[2023-11-19T09:45:08.596+0000] {taskinstance.py:1159} INFO - Dependencies all met for dep_context=non-requeueable deps ti=<TaskInstance: outcomes_dag.transform manual__2023-11-19T09:34:16.050509+00:00 [queued]>
[2023-11-19T09:45:08.599+0000] {taskinstance.py:1159} INFO - Dependencies all met for dep_context=requeueable deps ti=<TaskInstance: outcomes_dag.transform manual__2023-11-19T09:34:16.050509+00:00 [queued]>
[2023-11-19T09:45:08.600+0000] {taskinstance.py:1361} INFO - Starting attempt 2 of 2
[2023-11-19T09:45:08.604+0000] {taskinstance.py:1382} INFO - Executing <Task(PythonOperator): transform> on 2023-11-19 09:34:16.050509+00:00
[2023-11-19T09:45:08.609+0000] {standard_task_runner.py:57} INFO - Started process 345 to run task
[2023-11-19T09:45:08.611+0000] {standard_task_runner.py:84} INFO - Running: ['***', 'tasks', 'run', 'outcomes_dag', 'transform', 'manual__2023-11-19T09:34:16.050509+00:00', '--job-id', '26', '--raw', '--subdir', 'DAGS_FOLDER/outcomes_dag.py', '--cfg-path', '/tmp/tmpa5ap9jjz']
[2023-11-19T09:45:08.613+0000] {standard_task_runner.py:85} INFO - Job 26: Subtask transform
[2023-11-19T09:45:08.641+0000] {task_command.py:416} INFO - Running <TaskInstance: outcomes_dag.transform manual__2023-11-19T09:34:16.050509+00:00 [running]> on host 696613a1ef55
[2023-11-19T09:45:08.679+0000] {taskinstance.py:1662} INFO - Exporting env vars: AIRFLOW_CTX_DAG_OWNER='***' AIRFLOW_CTX_DAG_ID='outcomes_dag' AIRFLOW_CTX_TASK_ID='transform' AIRFLOW_CTX_EXECUTION_DATE='2023-11-19T09:34:16.050509+00:00' AIRFLOW_CTX_TRY_NUMBER='2' AIRFLOW_CTX_DAG_RUN_ID='manual__2023-11-19T09:34:16.050509+00:00'
[2023-11-19T09:45:08.679+0000] {taskinstance.py:1937} ERROR - Task failed with exception
Traceback (most recent call last):
  File "/home/airflow/.local/lib/python3.8/site-packages/airflow/operators/python.py", line 192, in execute
    return_value = self.execute_callable()
  File "/home/airflow/.local/lib/python3.8/site-packages/airflow/operators/python.py", line 209, in execute_callable
    return self.python_callable(*self.op_args, **self.op_kwargs)
TypeError: transform_data() missing 1 required positional argument: 'filename'
[2023-11-19T09:45:08.685+0000] {taskinstance.py:1400} INFO - Marking task as FAILED. dag_id=outcomes_dag, task_id=transform, execution_date=20231119T093416, start_date=20231119T094508, end_date=20231119T094508
[2023-11-19T09:45:08.690+0000] {standard_task_runner.py:104} ERROR - Failed to execute job 26 for task transform (transform_data() missing 1 required positional argument: 'filename'; 345)
[2023-11-19T09:45:08.703+0000] {local_task_job_runner.py:228} INFO - Task exited with return code 1
[2023-11-19T09:45:08.713+0000] {taskinstance.py:2778} INFO - 0 downstream tasks scheduled from follow-on schedule check
