[2023-11-19T09:34:18.700+0000] {taskinstance.py:1159} INFO - Dependencies all met for dep_context=non-requeueable deps ti=<TaskInstance: outcomes_dag.load_outcomes_fct manual__2023-11-19T09:34:16.050509+00:00 [queued]>
[2023-11-19T09:34:18.706+0000] {taskinstance.py:1159} INFO - Dependencies all met for dep_context=requeueable deps ti=<TaskInstance: outcomes_dag.load_outcomes_fct manual__2023-11-19T09:34:16.050509+00:00 [queued]>
[2023-11-19T09:34:18.707+0000] {taskinstance.py:1361} INFO - Starting attempt 1 of 1
[2023-11-19T09:34:18.720+0000] {taskinstance.py:1382} INFO - Executing <Task(PythonOperator): load_outcomes_fct> on 2023-11-19 09:34:16.050509+00:00
[2023-11-19T09:34:18.724+0000] {standard_task_runner.py:57} INFO - Started process 154 to run task
[2023-11-19T09:34:18.735+0000] {standard_task_runner.py:84} INFO - Running: ['***', 'tasks', 'run', 'outcomes_dag', 'load_outcomes_fct', 'manual__2023-11-19T09:34:16.050509+00:00', '--job-id', '22', '--raw', '--subdir', 'DAGS_FOLDER/outcomes_dag.py', '--cfg-path', '/tmp/tmpz7544xe2']
[2023-11-19T09:34:18.738+0000] {standard_task_runner.py:85} INFO - Job 22: Subtask load_outcomes_fct
[2023-11-19T09:34:18.786+0000] {task_command.py:416} INFO - Running <TaskInstance: outcomes_dag.load_outcomes_fct manual__2023-11-19T09:34:16.050509+00:00 [running]> on host 696613a1ef55
[2023-11-19T09:34:18.870+0000] {taskinstance.py:1662} INFO - Exporting env vars: AIRFLOW_CTX_DAG_OWNER='***' AIRFLOW_CTX_DAG_ID='outcomes_dag' AIRFLOW_CTX_TASK_ID='load_outcomes_fct' AIRFLOW_CTX_EXECUTION_DATE='2023-11-19T09:34:16.050509+00:00' AIRFLOW_CTX_TRY_NUMBER='1' AIRFLOW_CTX_DAG_RUN_ID='manual__2023-11-19T09:34:16.050509+00:00'
[2023-11-19T09:34:18.880+0000] {taskinstance.py:1937} ERROR - Task failed with exception
Traceback (most recent call last):
  File "/home/airflow/.local/lib/python3.8/site-packages/airflow/operators/python.py", line 192, in execute
    return_value = self.execute_callable()
  File "/home/airflow/.local/lib/python3.8/site-packages/airflow/operators/python.py", line 209, in execute_callable
    return self.python_callable(*self.op_args, **self.op_kwargs)
  File "/opt/airflow/dags/etl_scripts/load.py", line 32, in load_fact_data
    pd.read_parquet(table_file).to_sql(table_name, conn, if_exists="replace", index=False,)
  File "/home/airflow/.local/lib/python3.8/site-packages/pandas/io/parquet.py", line 509, in read_parquet
    return impl.read(
  File "/home/airflow/.local/lib/python3.8/site-packages/pandas/io/parquet.py", line 220, in read
    path_or_handle, handles, kwargs["filesystem"] = _get_path_or_handle(
  File "/home/airflow/.local/lib/python3.8/site-packages/pandas/io/parquet.py", line 110, in _get_path_or_handle
    handles = get_handle(
  File "/home/airflow/.local/lib/python3.8/site-packages/pandas/io/common.py", line 868, in get_handle
    handle = open(handle, ioargs.mode)
FileNotFoundError: [Errno 2] No such file or directory: '/opt/airflow/data/2023-11-19/processed/fct_outcomes.parquet'
[2023-11-19T09:34:18.887+0000] {taskinstance.py:1400} INFO - Marking task as FAILED. dag_id=outcomes_dag, task_id=load_outcomes_fct, execution_date=20231119T093416, start_date=20231119T093418, end_date=20231119T093418
[2023-11-19T09:34:18.897+0000] {standard_task_runner.py:104} ERROR - Failed to execute job 22 for task load_outcomes_fct ([Errno 2] No such file or directory: '/opt/airflow/data/2023-11-19/processed/fct_outcomes.parquet'; 154)
[2023-11-19T09:34:18.940+0000] {local_task_job_runner.py:228} INFO - Task exited with return code 1
[2023-11-19T09:34:18.956+0000] {taskinstance.py:2778} INFO - 0 downstream tasks scheduled from follow-on schedule check
