[2023-11-19T09:47:08.872+0000] {taskinstance.py:1159} INFO - Dependencies all met for dep_context=non-requeueable deps ti=<TaskInstance: outcomes_dag.transform manual__2023-11-19T09:47:04.120856+00:00 [queued]>
[2023-11-19T09:47:08.875+0000] {taskinstance.py:1159} INFO - Dependencies all met for dep_context=requeueable deps ti=<TaskInstance: outcomes_dag.transform manual__2023-11-19T09:47:04.120856+00:00 [queued]>
[2023-11-19T09:47:08.876+0000] {taskinstance.py:1361} INFO - Starting attempt 1 of 1
[2023-11-19T09:47:08.881+0000] {taskinstance.py:1382} INFO - Executing <Task(PythonOperator): transform> on 2023-11-19 09:47:04.120856+00:00
[2023-11-19T09:47:08.884+0000] {standard_task_runner.py:57} INFO - Started process 475 to run task
[2023-11-19T09:47:08.887+0000] {standard_task_runner.py:84} INFO - Running: ['***', 'tasks', 'run', 'outcomes_dag', 'transform', 'manual__2023-11-19T09:47:04.120856+00:00', '--job-id', '40', '--raw', '--subdir', 'DAGS_FOLDER/outcomes_dag.py', '--cfg-path', '/tmp/tmpri1nqfaq']
[2023-11-19T09:47:08.889+0000] {standard_task_runner.py:85} INFO - Job 40: Subtask transform
[2023-11-19T09:47:08.917+0000] {task_command.py:416} INFO - Running <TaskInstance: outcomes_dag.transform manual__2023-11-19T09:47:04.120856+00:00 [running]> on host 696613a1ef55
[2023-11-19T09:47:08.954+0000] {taskinstance.py:1662} INFO - Exporting env vars: AIRFLOW_CTX_DAG_OWNER='***' AIRFLOW_CTX_DAG_ID='outcomes_dag' AIRFLOW_CTX_TASK_ID='transform' AIRFLOW_CTX_EXECUTION_DATE='2023-11-19T09:47:04.120856+00:00' AIRFLOW_CTX_TRY_NUMBER='1' AIRFLOW_CTX_DAG_RUN_ID='manual__2023-11-19T09:47:04.120856+00:00'
[2023-11-19T09:47:09.404+0000] {taskinstance.py:1937} ERROR - Task failed with exception
Traceback (most recent call last):
  File "/home/airflow/.local/lib/python3.8/site-packages/pandas/core/indexes/base.py", line 3653, in get_loc
    return self._engine.get_loc(casted_key)
  File "pandas/_libs/index.pyx", line 147, in pandas._libs.index.IndexEngine.get_loc
  File "pandas/_libs/index.pyx", line 176, in pandas._libs.index.IndexEngine.get_loc
  File "pandas/_libs/hashtable_class_helper.pxi", line 7080, in pandas._libs.hashtable.PyObjectHashTable.get_item
  File "pandas/_libs/hashtable_class_helper.pxi", line 7088, in pandas._libs.hashtable.PyObjectHashTable.get_item
KeyError: 'Name'

The above exception was the direct cause of the following exception:

Traceback (most recent call last):
  File "/home/airflow/.local/lib/python3.8/site-packages/airflow/operators/python.py", line 192, in execute
    return_value = self.execute_callable()
  File "/home/airflow/.local/lib/python3.8/site-packages/airflow/operators/python.py", line 209, in execute_callable
    return self.python_callable(*self.op_args, **self.op_kwargs)
  File "/opt/airflow/dags/etl_scripts/transform.py", line 25, in transform_data
    new_data = prep_data(new_data)
  File "/opt/airflow/dags/etl_scripts/transform.py", line 47, in prep_data
    data['name'] = data['Name'].str.replace("*", "", regex=False)
  File "/home/airflow/.local/lib/python3.8/site-packages/pandas/core/frame.py", line 3761, in __getitem__
    indexer = self.columns.get_loc(key)
  File "/home/airflow/.local/lib/python3.8/site-packages/pandas/core/indexes/base.py", line 3655, in get_loc
    raise KeyError(key) from err
KeyError: 'Name'
[2023-11-19T09:47:09.413+0000] {taskinstance.py:1400} INFO - Marking task as FAILED. dag_id=outcomes_dag, task_id=transform, execution_date=20231119T094704, start_date=20231119T094708, end_date=20231119T094709
[2023-11-19T09:47:09.419+0000] {standard_task_runner.py:104} ERROR - Failed to execute job 40 for task transform ('Name'; 475)
[2023-11-19T09:47:09.463+0000] {local_task_job_runner.py:228} INFO - Task exited with return code 1
[2023-11-19T09:47:09.474+0000] {taskinstance.py:2778} INFO - 0 downstream tasks scheduled from follow-on schedule check
