[2023-11-19T06:28:24.671+0000] {taskinstance.py:1159} INFO - Dependencies all met for dep_context=non-requeueable deps ti=<TaskInstance: outcomes_dag.load_dates_dim scheduled__2023-11-18T00:00:00+00:00 [queued]>
[2023-11-19T06:28:24.675+0000] {taskinstance.py:1159} INFO - Dependencies all met for dep_context=requeueable deps ti=<TaskInstance: outcomes_dag.load_dates_dim scheduled__2023-11-18T00:00:00+00:00 [queued]>
[2023-11-19T06:28:24.676+0000] {taskinstance.py:1361} INFO - Starting attempt 1 of 1
[2023-11-19T06:28:24.689+0000] {taskinstance.py:1382} INFO - Executing <Task(PythonOperator): load_dates_dim> on 2023-11-18 00:00:00+00:00
[2023-11-19T06:28:24.696+0000] {standard_task_runner.py:57} INFO - Started process 103 to run task
[2023-11-19T06:28:24.700+0000] {standard_task_runner.py:84} INFO - Running: ['***', 'tasks', 'run', 'outcomes_dag', 'load_dates_dim', 'scheduled__2023-11-18T00:00:00+00:00', '--job-id', '11', '--raw', '--subdir', 'DAGS_FOLDER/outcomes_dag.py', '--cfg-path', '/tmp/tmpu9sdfxeo']
[2023-11-19T06:28:24.703+0000] {standard_task_runner.py:85} INFO - Job 11: Subtask load_dates_dim
[2023-11-19T06:28:24.752+0000] {task_command.py:416} INFO - Running <TaskInstance: outcomes_dag.load_dates_dim scheduled__2023-11-18T00:00:00+00:00 [running]> on host 8c758415f3b2
[2023-11-19T06:28:25.208+0000] {taskinstance.py:1662} INFO - Exporting env vars: AIRFLOW_CTX_DAG_OWNER='***' AIRFLOW_CTX_DAG_ID='outcomes_dag' AIRFLOW_CTX_TASK_ID='load_dates_dim' AIRFLOW_CTX_EXECUTION_DATE='2023-11-18T00:00:00+00:00' AIRFLOW_CTX_TRY_NUMBER='1' AIRFLOW_CTX_DAG_RUN_ID='scheduled__2023-11-18T00:00:00+00:00'
[2023-11-19T06:28:25.517+0000] {logging_mixin.py:154} INFO - dim_dates loaded
[2023-11-19T06:28:25.517+0000] {python.py:194} INFO - Done. Returned value was: None
[2023-11-19T06:28:25.524+0000] {taskinstance.py:1400} INFO - Marking task as SUCCESS. dag_id=outcomes_dag, task_id=load_dates_dim, execution_date=20231118T000000, start_date=20231119T062824, end_date=20231119T062825
[2023-11-19T06:28:25.562+0000] {local_task_job_runner.py:228} INFO - Task exited with return code 0
[2023-11-19T06:28:25.577+0000] {taskinstance.py:2778} INFO - 0 downstream tasks scheduled from follow-on schedule check
[2023-11-19T07:33:04.994+0000] {taskinstance.py:1159} INFO - Dependencies all met for dep_context=non-requeueable deps ti=<TaskInstance: outcomes_dag.load_dates_dim scheduled__2023-11-18T00:00:00+00:00 [queued]>
[2023-11-19T07:33:05.003+0000] {taskinstance.py:1159} INFO - Dependencies all met for dep_context=requeueable deps ti=<TaskInstance: outcomes_dag.load_dates_dim scheduled__2023-11-18T00:00:00+00:00 [queued]>
[2023-11-19T07:33:05.004+0000] {taskinstance.py:1361} INFO - Starting attempt 1 of 1
[2023-11-19T07:33:05.014+0000] {taskinstance.py:1382} INFO - Executing <Task(PythonOperator): load_dates_dim> on 2023-11-18 00:00:00+00:00
[2023-11-19T07:33:05.021+0000] {standard_task_runner.py:57} INFO - Started process 125 to run task
[2023-11-19T07:33:05.030+0000] {standard_task_runner.py:84} INFO - Running: ['***', 'tasks', 'run', 'outcomes_dag', 'load_dates_dim', 'scheduled__2023-11-18T00:00:00+00:00', '--job-id', '11', '--raw', '--subdir', 'DAGS_FOLDER/outcomes_dag.py', '--cfg-path', '/tmp/tmpw4lk6alv']
[2023-11-19T07:33:05.034+0000] {standard_task_runner.py:85} INFO - Job 11: Subtask load_dates_dim
[2023-11-19T07:33:05.094+0000] {task_command.py:416} INFO - Running <TaskInstance: outcomes_dag.load_dates_dim scheduled__2023-11-18T00:00:00+00:00 [running]> on host 13403f191858
[2023-11-19T07:33:05.416+0000] {taskinstance.py:1662} INFO - Exporting env vars: AIRFLOW_CTX_DAG_OWNER='***' AIRFLOW_CTX_DAG_ID='outcomes_dag' AIRFLOW_CTX_TASK_ID='load_dates_dim' AIRFLOW_CTX_EXECUTION_DATE='2023-11-18T00:00:00+00:00' AIRFLOW_CTX_TRY_NUMBER='1' AIRFLOW_CTX_DAG_RUN_ID='scheduled__2023-11-18T00:00:00+00:00'
[2023-11-19T07:33:05.913+0000] {logging_mixin.py:154} INFO - dim_dates loaded
[2023-11-19T07:33:05.914+0000] {python.py:194} INFO - Done. Returned value was: None
[2023-11-19T07:33:05.921+0000] {taskinstance.py:1400} INFO - Marking task as SUCCESS. dag_id=outcomes_dag, task_id=load_dates_dim, execution_date=20231118T000000, start_date=20231119T073304, end_date=20231119T073305
[2023-11-19T07:33:05.960+0000] {local_task_job_runner.py:228} INFO - Task exited with return code 0
[2023-11-19T07:33:05.975+0000] {taskinstance.py:2778} INFO - 0 downstream tasks scheduled from follow-on schedule check
[2023-11-19T09:32:54.040+0000] {taskinstance.py:1159} INFO - Dependencies all met for dep_context=non-requeueable deps ti=<TaskInstance: outcomes_dag.load_dates_dim scheduled__2023-11-18T00:00:00+00:00 [queued]>
[2023-11-19T09:32:54.082+0000] {taskinstance.py:1159} INFO - Dependencies all met for dep_context=requeueable deps ti=<TaskInstance: outcomes_dag.load_dates_dim scheduled__2023-11-18T00:00:00+00:00 [queued]>
[2023-11-19T09:32:54.082+0000] {taskinstance.py:1361} INFO - Starting attempt 1 of 1
[2023-11-19T09:32:54.110+0000] {taskinstance.py:1382} INFO - Executing <Task(PythonOperator): load_dates_dim> on 2023-11-18 00:00:00+00:00
[2023-11-19T09:32:54.158+0000] {standard_task_runner.py:57} INFO - Started process 102 to run task
[2023-11-19T09:32:54.189+0000] {standard_task_runner.py:84} INFO - Running: ['***', 'tasks', 'run', 'outcomes_dag', 'load_dates_dim', 'scheduled__2023-11-18T00:00:00+00:00', '--job-id', '14', '--raw', '--subdir', 'DAGS_FOLDER/outcomes_dag.py', '--cfg-path', '/tmp/tmp9i6zcs68']
[2023-11-19T09:32:54.201+0000] {standard_task_runner.py:85} INFO - Job 14: Subtask load_dates_dim
[2023-11-19T09:32:54.383+0000] {task_command.py:416} INFO - Running <TaskInstance: outcomes_dag.load_dates_dim scheduled__2023-11-18T00:00:00+00:00 [running]> on host 696613a1ef55
[2023-11-19T09:32:54.526+0000] {taskinstance.py:1662} INFO - Exporting env vars: AIRFLOW_CTX_DAG_OWNER='***' AIRFLOW_CTX_DAG_ID='outcomes_dag' AIRFLOW_CTX_TASK_ID='load_dates_dim' AIRFLOW_CTX_EXECUTION_DATE='2023-11-18T00:00:00+00:00' AIRFLOW_CTX_TRY_NUMBER='1' AIRFLOW_CTX_DAG_RUN_ID='scheduled__2023-11-18T00:00:00+00:00'
[2023-11-19T09:32:54.548+0000] {taskinstance.py:1937} ERROR - Task failed with exception
Traceback (most recent call last):
  File "/home/airflow/.local/lib/python3.8/site-packages/airflow/operators/python.py", line 192, in execute
    return_value = self.execute_callable()
  File "/home/airflow/.local/lib/python3.8/site-packages/airflow/operators/python.py", line 209, in execute_callable
    return self.python_callable(*self.op_args, **self.op_kwargs)
  File "/opt/airflow/dags/etl_scripts/load.py", line 25, in load_data
    pd.read_parquet(table_file).to_sql(table_name, conn, if_exists="append", index=False, method=insert_on_conflict_nothing)
  File "/home/airflow/.local/lib/python3.8/site-packages/pandas/io/parquet.py", line 509, in read_parquet
    return impl.read(
  File "/home/airflow/.local/lib/python3.8/site-packages/pandas/io/parquet.py", line 220, in read
    path_or_handle, handles, kwargs["filesystem"] = _get_path_or_handle(
  File "/home/airflow/.local/lib/python3.8/site-packages/pandas/io/parquet.py", line 110, in _get_path_or_handle
    handles = get_handle(
  File "/home/airflow/.local/lib/python3.8/site-packages/pandas/io/common.py", line 868, in get_handle
    handle = open(handle, ioargs.mode)
FileNotFoundError: [Errno 2] No such file or directory: '/opt/airflow/data/2023-11-18/processed/dim_dates.parquet'
[2023-11-19T09:32:54.562+0000] {taskinstance.py:1400} INFO - Marking task as FAILED. dag_id=outcomes_dag, task_id=load_dates_dim, execution_date=20231118T000000, start_date=20231119T093254, end_date=20231119T093254
[2023-11-19T09:32:54.573+0000] {standard_task_runner.py:104} ERROR - Failed to execute job 14 for task load_dates_dim ([Errno 2] No such file or directory: '/opt/airflow/data/2023-11-18/processed/dim_dates.parquet'; 102)
[2023-11-19T09:32:54.604+0000] {local_task_job_runner.py:228} INFO - Task exited with return code 1
[2023-11-19T09:32:54.616+0000] {taskinstance.py:2778} INFO - 0 downstream tasks scheduled from follow-on schedule check
[2023-11-19T20:43:40.158+0000] {taskinstance.py:1159} INFO - Dependencies all met for dep_context=non-requeueable deps ti=<TaskInstance: outcomes_dag.load_dates_dim scheduled__2023-11-18T00:00:00+00:00 [queued]>
[2023-11-19T20:43:40.162+0000] {taskinstance.py:1159} INFO - Dependencies all met for dep_context=requeueable deps ti=<TaskInstance: outcomes_dag.load_dates_dim scheduled__2023-11-18T00:00:00+00:00 [queued]>
[2023-11-19T20:43:40.163+0000] {taskinstance.py:1361} INFO - Starting attempt 1 of 1
[2023-11-19T20:43:40.168+0000] {taskinstance.py:1382} INFO - Executing <Task(PythonOperator): load_dates_dim> on 2023-11-18 00:00:00+00:00
[2023-11-19T20:43:40.172+0000] {standard_task_runner.py:57} INFO - Started process 102 to run task
[2023-11-19T20:43:40.175+0000] {standard_task_runner.py:84} INFO - Running: ['***', 'tasks', 'run', 'outcomes_dag', 'load_dates_dim', 'scheduled__2023-11-18T00:00:00+00:00', '--job-id', '8', '--raw', '--subdir', 'DAGS_FOLDER/outcomes_dag.py', '--cfg-path', '/tmp/tmpr5adwids']
[2023-11-19T20:43:40.177+0000] {standard_task_runner.py:85} INFO - Job 8: Subtask load_dates_dim
[2023-11-19T20:43:40.217+0000] {task_command.py:416} INFO - Running <TaskInstance: outcomes_dag.load_dates_dim scheduled__2023-11-18T00:00:00+00:00 [running]> on host 549ad0bd2371
[2023-11-19T20:43:40.272+0000] {taskinstance.py:1662} INFO - Exporting env vars: AIRFLOW_CTX_DAG_OWNER='***' AIRFLOW_CTX_DAG_ID='outcomes_dag' AIRFLOW_CTX_TASK_ID='load_dates_dim' AIRFLOW_CTX_EXECUTION_DATE='2023-11-18T00:00:00+00:00' AIRFLOW_CTX_TRY_NUMBER='1' AIRFLOW_CTX_DAG_RUN_ID='scheduled__2023-11-18T00:00:00+00:00'
[2023-11-19T20:43:56.356+0000] {taskinstance.py:1937} ERROR - Task failed with exception
Traceback (most recent call last):
  File "/home/airflow/.local/lib/python3.8/site-packages/sqlalchemy/engine/base.py", line 3371, in _wrap_pool_connect
    return fn()
  File "/home/airflow/.local/lib/python3.8/site-packages/sqlalchemy/pool/base.py", line 327, in connect
    return _ConnectionFairy._checkout(self)
  File "/home/airflow/.local/lib/python3.8/site-packages/sqlalchemy/pool/base.py", line 894, in _checkout
    fairy = _ConnectionRecord.checkout(pool)
  File "/home/airflow/.local/lib/python3.8/site-packages/sqlalchemy/pool/base.py", line 493, in checkout
    rec = pool._do_get()
  File "/home/airflow/.local/lib/python3.8/site-packages/sqlalchemy/pool/impl.py", line 146, in _do_get
    self._dec_overflow()
  File "/home/airflow/.local/lib/python3.8/site-packages/sqlalchemy/util/langhelpers.py", line 70, in __exit__
    compat.raise_(
  File "/home/airflow/.local/lib/python3.8/site-packages/sqlalchemy/util/compat.py", line 211, in raise_
    raise exception
  File "/home/airflow/.local/lib/python3.8/site-packages/sqlalchemy/pool/impl.py", line 143, in _do_get
    return self._create_connection()
  File "/home/airflow/.local/lib/python3.8/site-packages/sqlalchemy/pool/base.py", line 273, in _create_connection
    return _ConnectionRecord(self)
  File "/home/airflow/.local/lib/python3.8/site-packages/sqlalchemy/pool/base.py", line 388, in __init__
    self.__connect()
  File "/home/airflow/.local/lib/python3.8/site-packages/sqlalchemy/pool/base.py", line 691, in __connect
    pool.logger.debug("Error on connect(): %s", e)
  File "/home/airflow/.local/lib/python3.8/site-packages/sqlalchemy/util/langhelpers.py", line 70, in __exit__
    compat.raise_(
  File "/home/airflow/.local/lib/python3.8/site-packages/sqlalchemy/util/compat.py", line 211, in raise_
    raise exception
  File "/home/airflow/.local/lib/python3.8/site-packages/sqlalchemy/pool/base.py", line 686, in __connect
    self.dbapi_connection = connection = pool._invoke_creator(self)
  File "/home/airflow/.local/lib/python3.8/site-packages/sqlalchemy/engine/create.py", line 574, in connect
    return dialect.connect(*cargs, **cparams)
  File "/home/airflow/.local/lib/python3.8/site-packages/sqlalchemy/engine/default.py", line 598, in connect
    return self.dbapi.connect(*cargs, **cparams)
  File "/home/airflow/.local/lib/python3.8/site-packages/psycopg2/__init__.py", line 122, in connect
    conn = _connect(dsn, connection_factory=connection_factory, **kwasync)
psycopg2.OperationalError: connection to server at "database-1.cvwmlpdligxr.us-east-2.rds.amazonaws.com" (13.58.230.201), port 5432 failed: server closed the connection unexpectedly
	This probably means the server terminated abnormally
	before or while processing the request.


The above exception was the direct cause of the following exception:

Traceback (most recent call last):
  File "/home/airflow/.local/lib/python3.8/site-packages/airflow/operators/python.py", line 192, in execute
    return_value = self.execute_callable()
  File "/home/airflow/.local/lib/python3.8/site-packages/airflow/operators/python.py", line 209, in execute_callable
    return self.python_callable(*self.op_args, **self.op_kwargs)
  File "/opt/airflow/dags/etl_scripts/load.py", line 26, in load_data
    pd.read_csv(obj['Body'], index_col=0).to_sql(table_name, conn, if_exists="append", index=False, method=insert_on_conflict_nothing)
  File "/home/airflow/.local/lib/python3.8/site-packages/pandas/core/generic.py", line 2878, in to_sql
    return sql.to_sql(
  File "/home/airflow/.local/lib/python3.8/site-packages/pandas/io/sql.py", line 768, in to_sql
    with pandasSQL_builder(con, schema=schema, need_transaction=True) as pandas_sql:
  File "/home/airflow/.local/lib/python3.8/site-packages/pandas/io/sql.py", line 832, in pandasSQL_builder
    return SQLDatabase(con, schema, need_transaction)
  File "/home/airflow/.local/lib/python3.8/site-packages/pandas/io/sql.py", line 1539, in __init__
    con = self.exit_stack.enter_context(con.connect())
  File "/home/airflow/.local/lib/python3.8/site-packages/sqlalchemy/engine/base.py", line 3325, in connect
    return self._connection_cls(self, close_with_result=close_with_result)
  File "/home/airflow/.local/lib/python3.8/site-packages/sqlalchemy/engine/base.py", line 96, in __init__
    else engine.raw_connection()
  File "/home/airflow/.local/lib/python3.8/site-packages/sqlalchemy/engine/base.py", line 3404, in raw_connection
    return self._wrap_pool_connect(self.pool.connect, _connection)
  File "/home/airflow/.local/lib/python3.8/site-packages/sqlalchemy/engine/base.py", line 3374, in _wrap_pool_connect
    Connection._handle_dbapi_exception_noconnection(
  File "/home/airflow/.local/lib/python3.8/site-packages/sqlalchemy/engine/base.py", line 2208, in _handle_dbapi_exception_noconnection
    util.raise_(
  File "/home/airflow/.local/lib/python3.8/site-packages/sqlalchemy/util/compat.py", line 211, in raise_
    raise exception
  File "/home/airflow/.local/lib/python3.8/site-packages/sqlalchemy/engine/base.py", line 3371, in _wrap_pool_connect
    return fn()
  File "/home/airflow/.local/lib/python3.8/site-packages/sqlalchemy/pool/base.py", line 327, in connect
    return _ConnectionFairy._checkout(self)
  File "/home/airflow/.local/lib/python3.8/site-packages/sqlalchemy/pool/base.py", line 894, in _checkout
    fairy = _ConnectionRecord.checkout(pool)
  File "/home/airflow/.local/lib/python3.8/site-packages/sqlalchemy/pool/base.py", line 493, in checkout
    rec = pool._do_get()
  File "/home/airflow/.local/lib/python3.8/site-packages/sqlalchemy/pool/impl.py", line 146, in _do_get
    self._dec_overflow()
  File "/home/airflow/.local/lib/python3.8/site-packages/sqlalchemy/util/langhelpers.py", line 70, in __exit__
    compat.raise_(
  File "/home/airflow/.local/lib/python3.8/site-packages/sqlalchemy/util/compat.py", line 211, in raise_
    raise exception
  File "/home/airflow/.local/lib/python3.8/site-packages/sqlalchemy/pool/impl.py", line 143, in _do_get
    return self._create_connection()
  File "/home/airflow/.local/lib/python3.8/site-packages/sqlalchemy/pool/base.py", line 273, in _create_connection
    return _ConnectionRecord(self)
  File "/home/airflow/.local/lib/python3.8/site-packages/sqlalchemy/pool/base.py", line 388, in __init__
    self.__connect()
  File "/home/airflow/.local/lib/python3.8/site-packages/sqlalchemy/pool/base.py", line 691, in __connect
    pool.logger.debug("Error on connect(): %s", e)
  File "/home/airflow/.local/lib/python3.8/site-packages/sqlalchemy/util/langhelpers.py", line 70, in __exit__
    compat.raise_(
  File "/home/airflow/.local/lib/python3.8/site-packages/sqlalchemy/util/compat.py", line 211, in raise_
    raise exception
  File "/home/airflow/.local/lib/python3.8/site-packages/sqlalchemy/pool/base.py", line 686, in __connect
    self.dbapi_connection = connection = pool._invoke_creator(self)
  File "/home/airflow/.local/lib/python3.8/site-packages/sqlalchemy/engine/create.py", line 574, in connect
    return dialect.connect(*cargs, **cparams)
  File "/home/airflow/.local/lib/python3.8/site-packages/sqlalchemy/engine/default.py", line 598, in connect
    return self.dbapi.connect(*cargs, **cparams)
  File "/home/airflow/.local/lib/python3.8/site-packages/psycopg2/__init__.py", line 122, in connect
    conn = _connect(dsn, connection_factory=connection_factory, **kwasync)
sqlalchemy.exc.OperationalError: (psycopg2.OperationalError) connection to server at "database-1.cvwmlpdligxr.us-east-2.rds.amazonaws.com" (13.58.230.201), port 5432 failed: server closed the connection unexpectedly
	This probably means the server terminated abnormally
	before or while processing the request.

(Background on this error at: https://sqlalche.me/e/14/e3q8)
[2023-11-19T20:43:56.385+0000] {taskinstance.py:1400} INFO - Marking task as FAILED. dag_id=outcomes_dag, task_id=load_dates_dim, execution_date=20231118T000000, start_date=20231119T204340, end_date=20231119T204356
[2023-11-19T20:43:56.396+0000] {standard_task_runner.py:104} ERROR - Failed to execute job 8 for task load_dates_dim ((psycopg2.OperationalError) connection to server at "database-1.cvwmlpdligxr.us-east-2.rds.amazonaws.com" (13.58.230.201), port 5432 failed: server closed the connection unexpectedly
	This probably means the server terminated abnormally
	before or while processing the request.

(Background on this error at: https://sqlalche.me/e/14/e3q8); 102)
[2023-11-19T20:43:56.423+0000] {local_task_job_runner.py:228} INFO - Task exited with return code 1
[2023-11-19T20:47:20.410+0000] {taskinstance.py:1159} INFO - Dependencies all met for dep_context=non-requeueable deps ti=<TaskInstance: outcomes_dag.load_dates_dim scheduled__2023-11-18T00:00:00+00:00 [queued]>
[2023-11-19T20:47:20.415+0000] {taskinstance.py:1159} INFO - Dependencies all met for dep_context=requeueable deps ti=<TaskInstance: outcomes_dag.load_dates_dim scheduled__2023-11-18T00:00:00+00:00 [queued]>
[2023-11-19T20:47:20.416+0000] {taskinstance.py:1361} INFO - Starting attempt 1 of 1
[2023-11-19T20:47:20.421+0000] {taskinstance.py:1382} INFO - Executing <Task(PythonOperator): load_dates_dim> on 2023-11-18 00:00:00+00:00
[2023-11-19T20:47:20.425+0000] {standard_task_runner.py:57} INFO - Started process 108 to run task
[2023-11-19T20:47:20.428+0000] {standard_task_runner.py:84} INFO - Running: ['***', 'tasks', 'run', 'outcomes_dag', 'load_dates_dim', 'scheduled__2023-11-18T00:00:00+00:00', '--job-id', '10', '--raw', '--subdir', 'DAGS_FOLDER/outcomes_dag.py', '--cfg-path', '/tmp/tmp0nsoqbhk']
[2023-11-19T20:47:20.431+0000] {standard_task_runner.py:85} INFO - Job 10: Subtask load_dates_dim
[2023-11-19T20:47:20.464+0000] {task_command.py:416} INFO - Running <TaskInstance: outcomes_dag.load_dates_dim scheduled__2023-11-18T00:00:00+00:00 [running]> on host 9cdfa5fb3a71
[2023-11-19T20:47:20.513+0000] {taskinstance.py:1662} INFO - Exporting env vars: AIRFLOW_CTX_DAG_OWNER='***' AIRFLOW_CTX_DAG_ID='outcomes_dag' AIRFLOW_CTX_TASK_ID='load_dates_dim' AIRFLOW_CTX_EXECUTION_DATE='2023-11-18T00:00:00+00:00' AIRFLOW_CTX_TRY_NUMBER='1' AIRFLOW_CTX_DAG_RUN_ID='scheduled__2023-11-18T00:00:00+00:00'
[2023-11-19T20:47:36.516+0000] {taskinstance.py:1937} ERROR - Task failed with exception
Traceback (most recent call last):
  File "/home/airflow/.local/lib/python3.8/site-packages/sqlalchemy/engine/base.py", line 3371, in _wrap_pool_connect
    return fn()
  File "/home/airflow/.local/lib/python3.8/site-packages/sqlalchemy/pool/base.py", line 327, in connect
    return _ConnectionFairy._checkout(self)
  File "/home/airflow/.local/lib/python3.8/site-packages/sqlalchemy/pool/base.py", line 894, in _checkout
    fairy = _ConnectionRecord.checkout(pool)
  File "/home/airflow/.local/lib/python3.8/site-packages/sqlalchemy/pool/base.py", line 493, in checkout
    rec = pool._do_get()
  File "/home/airflow/.local/lib/python3.8/site-packages/sqlalchemy/pool/impl.py", line 146, in _do_get
    self._dec_overflow()
  File "/home/airflow/.local/lib/python3.8/site-packages/sqlalchemy/util/langhelpers.py", line 70, in __exit__
    compat.raise_(
  File "/home/airflow/.local/lib/python3.8/site-packages/sqlalchemy/util/compat.py", line 211, in raise_
    raise exception
  File "/home/airflow/.local/lib/python3.8/site-packages/sqlalchemy/pool/impl.py", line 143, in _do_get
    return self._create_connection()
  File "/home/airflow/.local/lib/python3.8/site-packages/sqlalchemy/pool/base.py", line 273, in _create_connection
    return _ConnectionRecord(self)
  File "/home/airflow/.local/lib/python3.8/site-packages/sqlalchemy/pool/base.py", line 388, in __init__
    self.__connect()
  File "/home/airflow/.local/lib/python3.8/site-packages/sqlalchemy/pool/base.py", line 691, in __connect
    pool.logger.debug("Error on connect(): %s", e)
  File "/home/airflow/.local/lib/python3.8/site-packages/sqlalchemy/util/langhelpers.py", line 70, in __exit__
    compat.raise_(
  File "/home/airflow/.local/lib/python3.8/site-packages/sqlalchemy/util/compat.py", line 211, in raise_
    raise exception
  File "/home/airflow/.local/lib/python3.8/site-packages/sqlalchemy/pool/base.py", line 686, in __connect
    self.dbapi_connection = connection = pool._invoke_creator(self)
  File "/home/airflow/.local/lib/python3.8/site-packages/sqlalchemy/engine/create.py", line 574, in connect
    return dialect.connect(*cargs, **cparams)
  File "/home/airflow/.local/lib/python3.8/site-packages/sqlalchemy/engine/default.py", line 598, in connect
    return self.dbapi.connect(*cargs, **cparams)
  File "/home/airflow/.local/lib/python3.8/site-packages/psycopg2/__init__.py", line 122, in connect
    conn = _connect(dsn, connection_factory=connection_factory, **kwasync)
psycopg2.OperationalError: connection to server at "database-1.cvwmlpdligxr.us-east-2.rds.amazonaws.com" (13.58.230.201), port 5432 failed: server closed the connection unexpectedly
	This probably means the server terminated abnormally
	before or while processing the request.


The above exception was the direct cause of the following exception:

Traceback (most recent call last):
  File "/home/airflow/.local/lib/python3.8/site-packages/airflow/operators/python.py", line 192, in execute
    return_value = self.execute_callable()
  File "/home/airflow/.local/lib/python3.8/site-packages/airflow/operators/python.py", line 209, in execute_callable
    return self.python_callable(*self.op_args, **self.op_kwargs)
  File "/opt/airflow/dags/etl_scripts/load.py", line 26, in load_data
    pd.read_csv(obj['Body'], index_col=0).to_sql(table_name, conn, if_exists="append", index=False, method=insert_on_conflict_nothing)
  File "/home/airflow/.local/lib/python3.8/site-packages/pandas/core/generic.py", line 2878, in to_sql
    return sql.to_sql(
  File "/home/airflow/.local/lib/python3.8/site-packages/pandas/io/sql.py", line 768, in to_sql
    with pandasSQL_builder(con, schema=schema, need_transaction=True) as pandas_sql:
  File "/home/airflow/.local/lib/python3.8/site-packages/pandas/io/sql.py", line 832, in pandasSQL_builder
    return SQLDatabase(con, schema, need_transaction)
  File "/home/airflow/.local/lib/python3.8/site-packages/pandas/io/sql.py", line 1539, in __init__
    con = self.exit_stack.enter_context(con.connect())
  File "/home/airflow/.local/lib/python3.8/site-packages/sqlalchemy/engine/base.py", line 3325, in connect
    return self._connection_cls(self, close_with_result=close_with_result)
  File "/home/airflow/.local/lib/python3.8/site-packages/sqlalchemy/engine/base.py", line 96, in __init__
    else engine.raw_connection()
  File "/home/airflow/.local/lib/python3.8/site-packages/sqlalchemy/engine/base.py", line 3404, in raw_connection
    return self._wrap_pool_connect(self.pool.connect, _connection)
  File "/home/airflow/.local/lib/python3.8/site-packages/sqlalchemy/engine/base.py", line 3374, in _wrap_pool_connect
    Connection._handle_dbapi_exception_noconnection(
  File "/home/airflow/.local/lib/python3.8/site-packages/sqlalchemy/engine/base.py", line 2208, in _handle_dbapi_exception_noconnection
    util.raise_(
  File "/home/airflow/.local/lib/python3.8/site-packages/sqlalchemy/util/compat.py", line 211, in raise_
    raise exception
  File "/home/airflow/.local/lib/python3.8/site-packages/sqlalchemy/engine/base.py", line 3371, in _wrap_pool_connect
    return fn()
  File "/home/airflow/.local/lib/python3.8/site-packages/sqlalchemy/pool/base.py", line 327, in connect
    return _ConnectionFairy._checkout(self)
  File "/home/airflow/.local/lib/python3.8/site-packages/sqlalchemy/pool/base.py", line 894, in _checkout
    fairy = _ConnectionRecord.checkout(pool)
  File "/home/airflow/.local/lib/python3.8/site-packages/sqlalchemy/pool/base.py", line 493, in checkout
    rec = pool._do_get()
  File "/home/airflow/.local/lib/python3.8/site-packages/sqlalchemy/pool/impl.py", line 146, in _do_get
    self._dec_overflow()
  File "/home/airflow/.local/lib/python3.8/site-packages/sqlalchemy/util/langhelpers.py", line 70, in __exit__
    compat.raise_(
  File "/home/airflow/.local/lib/python3.8/site-packages/sqlalchemy/util/compat.py", line 211, in raise_
    raise exception
  File "/home/airflow/.local/lib/python3.8/site-packages/sqlalchemy/pool/impl.py", line 143, in _do_get
    return self._create_connection()
  File "/home/airflow/.local/lib/python3.8/site-packages/sqlalchemy/pool/base.py", line 273, in _create_connection
    return _ConnectionRecord(self)
  File "/home/airflow/.local/lib/python3.8/site-packages/sqlalchemy/pool/base.py", line 388, in __init__
    self.__connect()
  File "/home/airflow/.local/lib/python3.8/site-packages/sqlalchemy/pool/base.py", line 691, in __connect
    pool.logger.debug("Error on connect(): %s", e)
  File "/home/airflow/.local/lib/python3.8/site-packages/sqlalchemy/util/langhelpers.py", line 70, in __exit__
    compat.raise_(
  File "/home/airflow/.local/lib/python3.8/site-packages/sqlalchemy/util/compat.py", line 211, in raise_
    raise exception
  File "/home/airflow/.local/lib/python3.8/site-packages/sqlalchemy/pool/base.py", line 686, in __connect
    self.dbapi_connection = connection = pool._invoke_creator(self)
  File "/home/airflow/.local/lib/python3.8/site-packages/sqlalchemy/engine/create.py", line 574, in connect
    return dialect.connect(*cargs, **cparams)
  File "/home/airflow/.local/lib/python3.8/site-packages/sqlalchemy/engine/default.py", line 598, in connect
    return self.dbapi.connect(*cargs, **cparams)
  File "/home/airflow/.local/lib/python3.8/site-packages/psycopg2/__init__.py", line 122, in connect
    conn = _connect(dsn, connection_factory=connection_factory, **kwasync)
sqlalchemy.exc.OperationalError: (psycopg2.OperationalError) connection to server at "database-1.cvwmlpdligxr.us-east-2.rds.amazonaws.com" (13.58.230.201), port 5432 failed: server closed the connection unexpectedly
	This probably means the server terminated abnormally
	before or while processing the request.

(Background on this error at: https://sqlalche.me/e/14/e3q8)
[2023-11-19T20:47:36.553+0000] {taskinstance.py:1400} INFO - Marking task as FAILED. dag_id=outcomes_dag, task_id=load_dates_dim, execution_date=20231118T000000, start_date=20231119T204720, end_date=20231119T204736
[2023-11-19T20:47:36.571+0000] {standard_task_runner.py:104} ERROR - Failed to execute job 10 for task load_dates_dim ((psycopg2.OperationalError) connection to server at "database-1.cvwmlpdligxr.us-east-2.rds.amazonaws.com" (13.58.230.201), port 5432 failed: server closed the connection unexpectedly
	This probably means the server terminated abnormally
	before or while processing the request.

(Background on this error at: https://sqlalche.me/e/14/e3q8); 108)
[2023-11-19T20:47:36.585+0000] {local_task_job_runner.py:228} INFO - Task exited with return code 1
[2023-11-19T21:07:56.041+0000] {taskinstance.py:1159} INFO - Dependencies all met for dep_context=non-requeueable deps ti=<TaskInstance: outcomes_dag.load_dates_dim scheduled__2023-11-18T00:00:00+00:00 [queued]>
[2023-11-19T21:07:56.045+0000] {taskinstance.py:1159} INFO - Dependencies all met for dep_context=requeueable deps ti=<TaskInstance: outcomes_dag.load_dates_dim scheduled__2023-11-18T00:00:00+00:00 [queued]>
[2023-11-19T21:07:56.045+0000] {taskinstance.py:1361} INFO - Starting attempt 1 of 1
[2023-11-19T21:07:56.051+0000] {taskinstance.py:1382} INFO - Executing <Task(PythonOperator): load_dates_dim> on 2023-11-18 00:00:00+00:00
[2023-11-19T21:07:56.056+0000] {standard_task_runner.py:57} INFO - Started process 98 to run task
[2023-11-19T21:07:56.060+0000] {standard_task_runner.py:84} INFO - Running: ['***', 'tasks', 'run', 'outcomes_dag', 'load_dates_dim', 'scheduled__2023-11-18T00:00:00+00:00', '--job-id', '9', '--raw', '--subdir', 'DAGS_FOLDER/outcomes_dag.py', '--cfg-path', '/tmp/tmp7e291wjd']
[2023-11-19T21:07:56.062+0000] {standard_task_runner.py:85} INFO - Job 9: Subtask load_dates_dim
[2023-11-19T21:07:56.110+0000] {task_command.py:416} INFO - Running <TaskInstance: outcomes_dag.load_dates_dim scheduled__2023-11-18T00:00:00+00:00 [running]> on host 39e21f8b1ec3
[2023-11-19T21:07:56.158+0000] {taskinstance.py:1662} INFO - Exporting env vars: AIRFLOW_CTX_DAG_OWNER='***' AIRFLOW_CTX_DAG_ID='outcomes_dag' AIRFLOW_CTX_TASK_ID='load_dates_dim' AIRFLOW_CTX_EXECUTION_DATE='2023-11-18T00:00:00+00:00' AIRFLOW_CTX_TRY_NUMBER='1' AIRFLOW_CTX_DAG_RUN_ID='scheduled__2023-11-18T00:00:00+00:00'
[2023-11-19T21:07:56.769+0000] {logging_mixin.py:154} INFO - dim_dates loaded
[2023-11-19T21:07:56.769+0000] {python.py:194} INFO - Done. Returned value was: None
[2023-11-19T21:07:56.779+0000] {taskinstance.py:1400} INFO - Marking task as SUCCESS. dag_id=outcomes_dag, task_id=load_dates_dim, execution_date=20231118T000000, start_date=20231119T210756, end_date=20231119T210756
[2023-11-19T21:07:56.799+0000] {local_task_job_runner.py:228} INFO - Task exited with return code 0
[2023-11-19T21:11:48.511+0000] {taskinstance.py:1159} INFO - Dependencies all met for dep_context=non-requeueable deps ti=<TaskInstance: outcomes_dag.load_dates_dim scheduled__2023-11-18T00:00:00+00:00 [queued]>
[2023-11-19T21:11:48.518+0000] {taskinstance.py:1159} INFO - Dependencies all met for dep_context=requeueable deps ti=<TaskInstance: outcomes_dag.load_dates_dim scheduled__2023-11-18T00:00:00+00:00 [queued]>
[2023-11-19T21:11:48.518+0000] {taskinstance.py:1361} INFO - Starting attempt 1 of 1
[2023-11-19T21:11:48.527+0000] {taskinstance.py:1382} INFO - Executing <Task(PythonOperator): load_dates_dim> on 2023-11-18 00:00:00+00:00
[2023-11-19T21:11:48.533+0000] {standard_task_runner.py:57} INFO - Started process 124 to run task
[2023-11-19T21:11:48.537+0000] {standard_task_runner.py:84} INFO - Running: ['***', 'tasks', 'run', 'outcomes_dag', 'load_dates_dim', 'scheduled__2023-11-18T00:00:00+00:00', '--job-id', '12', '--raw', '--subdir', 'DAGS_FOLDER/outcomes_dag.py', '--cfg-path', '/tmp/tmp8lkz8r56']
[2023-11-19T21:11:48.541+0000] {standard_task_runner.py:85} INFO - Job 12: Subtask load_dates_dim
[2023-11-19T21:11:48.589+0000] {task_command.py:416} INFO - Running <TaskInstance: outcomes_dag.load_dates_dim scheduled__2023-11-18T00:00:00+00:00 [running]> on host 0aa87954f8d2
[2023-11-19T21:11:48.657+0000] {taskinstance.py:1662} INFO - Exporting env vars: AIRFLOW_CTX_DAG_OWNER='***' AIRFLOW_CTX_DAG_ID='outcomes_dag' AIRFLOW_CTX_TASK_ID='load_dates_dim' AIRFLOW_CTX_EXECUTION_DATE='2023-11-18T00:00:00+00:00' AIRFLOW_CTX_TRY_NUMBER='1' AIRFLOW_CTX_DAG_RUN_ID='scheduled__2023-11-18T00:00:00+00:00'
[2023-11-19T21:11:49.199+0000] {logging_mixin.py:154} INFO - dim_dates loaded
[2023-11-19T21:11:49.199+0000] {python.py:194} INFO - Done. Returned value was: None
[2023-11-19T21:11:49.211+0000] {taskinstance.py:1400} INFO - Marking task as SUCCESS. dag_id=outcomes_dag, task_id=load_dates_dim, execution_date=20231118T000000, start_date=20231119T211148, end_date=20231119T211149
[2023-11-19T21:11:49.275+0000] {local_task_job_runner.py:228} INFO - Task exited with return code 0
[2023-11-19T21:15:30.569+0000] {taskinstance.py:1159} INFO - Dependencies all met for dep_context=non-requeueable deps ti=<TaskInstance: outcomes_dag.load_dates_dim scheduled__2023-11-18T00:00:00+00:00 [queued]>
[2023-11-19T21:15:30.587+0000] {taskinstance.py:1159} INFO - Dependencies all met for dep_context=requeueable deps ti=<TaskInstance: outcomes_dag.load_dates_dim scheduled__2023-11-18T00:00:00+00:00 [queued]>
[2023-11-19T21:15:30.588+0000] {taskinstance.py:1361} INFO - Starting attempt 1 of 1
[2023-11-19T21:15:30.599+0000] {taskinstance.py:1382} INFO - Executing <Task(PythonOperator): load_dates_dim> on 2023-11-18 00:00:00+00:00
[2023-11-19T21:15:30.614+0000] {standard_task_runner.py:57} INFO - Started process 113 to run task
[2023-11-19T21:15:30.614+0000] {standard_task_runner.py:84} INFO - Running: ['***', 'tasks', 'run', 'outcomes_dag', 'load_dates_dim', 'scheduled__2023-11-18T00:00:00+00:00', '--job-id', '10', '--raw', '--subdir', 'DAGS_FOLDER/outcomes_dag.py', '--cfg-path', '/tmp/tmp4qcjcqmw']
[2023-11-19T21:15:30.618+0000] {standard_task_runner.py:85} INFO - Job 10: Subtask load_dates_dim
[2023-11-19T21:15:30.691+0000] {task_command.py:416} INFO - Running <TaskInstance: outcomes_dag.load_dates_dim scheduled__2023-11-18T00:00:00+00:00 [running]> on host 5d17f892a68d
[2023-11-19T21:15:30.792+0000] {taskinstance.py:1662} INFO - Exporting env vars: AIRFLOW_CTX_DAG_OWNER='***' AIRFLOW_CTX_DAG_ID='outcomes_dag' AIRFLOW_CTX_TASK_ID='load_dates_dim' AIRFLOW_CTX_EXECUTION_DATE='2023-11-18T00:00:00+00:00' AIRFLOW_CTX_TRY_NUMBER='1' AIRFLOW_CTX_DAG_RUN_ID='scheduled__2023-11-18T00:00:00+00:00'
[2023-11-19T21:15:31.374+0000] {logging_mixin.py:154} INFO - dim_dates loaded
[2023-11-19T21:15:31.375+0000] {python.py:194} INFO - Done. Returned value was: None
[2023-11-19T21:15:31.390+0000] {taskinstance.py:1400} INFO - Marking task as SUCCESS. dag_id=outcomes_dag, task_id=load_dates_dim, execution_date=20231118T000000, start_date=20231119T211530, end_date=20231119T211531
[2023-11-19T21:15:31.434+0000] {local_task_job_runner.py:228} INFO - Task exited with return code 0
[2023-11-19T21:20:53.989+0000] {taskinstance.py:1159} INFO - Dependencies all met for dep_context=non-requeueable deps ti=<TaskInstance: outcomes_dag.load_dates_dim scheduled__2023-11-18T00:00:00+00:00 [queued]>
[2023-11-19T21:20:53.993+0000] {taskinstance.py:1159} INFO - Dependencies all met for dep_context=requeueable deps ti=<TaskInstance: outcomes_dag.load_dates_dim scheduled__2023-11-18T00:00:00+00:00 [queued]>
[2023-11-19T21:20:53.993+0000] {taskinstance.py:1361} INFO - Starting attempt 1 of 1
[2023-11-19T21:20:53.999+0000] {taskinstance.py:1382} INFO - Executing <Task(PythonOperator): load_dates_dim> on 2023-11-18 00:00:00+00:00
[2023-11-19T21:20:54.003+0000] {standard_task_runner.py:57} INFO - Started process 114 to run task
[2023-11-19T21:20:54.007+0000] {standard_task_runner.py:84} INFO - Running: ['***', 'tasks', 'run', 'outcomes_dag', 'load_dates_dim', 'scheduled__2023-11-18T00:00:00+00:00', '--job-id', '12', '--raw', '--subdir', 'DAGS_FOLDER/outcomes_dag.py', '--cfg-path', '/tmp/tmpqi8je1gj']
[2023-11-19T21:20:54.009+0000] {standard_task_runner.py:85} INFO - Job 12: Subtask load_dates_dim
[2023-11-19T21:20:54.051+0000] {task_command.py:416} INFO - Running <TaskInstance: outcomes_dag.load_dates_dim scheduled__2023-11-18T00:00:00+00:00 [running]> on host 33e2059faeb6
[2023-11-19T21:20:54.100+0000] {taskinstance.py:1662} INFO - Exporting env vars: AIRFLOW_CTX_DAG_OWNER='***' AIRFLOW_CTX_DAG_ID='outcomes_dag' AIRFLOW_CTX_TASK_ID='load_dates_dim' AIRFLOW_CTX_EXECUTION_DATE='2023-11-18T00:00:00+00:00' AIRFLOW_CTX_TRY_NUMBER='1' AIRFLOW_CTX_DAG_RUN_ID='scheduled__2023-11-18T00:00:00+00:00'
[2023-11-19T21:20:54.684+0000] {logging_mixin.py:154} INFO - dim_dates loaded
[2023-11-19T21:20:54.684+0000] {python.py:194} INFO - Done. Returned value was: None
[2023-11-19T21:20:54.691+0000] {taskinstance.py:1400} INFO - Marking task as SUCCESS. dag_id=outcomes_dag, task_id=load_dates_dim, execution_date=20231118T000000, start_date=20231119T212053, end_date=20231119T212054
[2023-11-19T21:20:54.720+0000] {local_task_job_runner.py:228} INFO - Task exited with return code 0
[2023-11-19T21:31:18.857+0000] {taskinstance.py:1159} INFO - Dependencies all met for dep_context=non-requeueable deps ti=<TaskInstance: outcomes_dag.load_dates_dim scheduled__2023-11-18T00:00:00+00:00 [queued]>
[2023-11-19T21:31:18.864+0000] {taskinstance.py:1159} INFO - Dependencies all met for dep_context=requeueable deps ti=<TaskInstance: outcomes_dag.load_dates_dim scheduled__2023-11-18T00:00:00+00:00 [queued]>
[2023-11-19T21:31:18.864+0000] {taskinstance.py:1361} INFO - Starting attempt 1 of 1
[2023-11-19T21:31:18.875+0000] {taskinstance.py:1382} INFO - Executing <Task(PythonOperator): load_dates_dim> on 2023-11-18 00:00:00+00:00
[2023-11-19T21:31:18.881+0000] {standard_task_runner.py:57} INFO - Started process 114 to run task
[2023-11-19T21:31:18.890+0000] {standard_task_runner.py:84} INFO - Running: ['***', 'tasks', 'run', 'outcomes_dag', 'load_dates_dim', 'scheduled__2023-11-18T00:00:00+00:00', '--job-id', '13', '--raw', '--subdir', 'DAGS_FOLDER/outcomes_dag.py', '--cfg-path', '/tmp/tmpp48ld17q']
[2023-11-19T21:31:18.894+0000] {standard_task_runner.py:85} INFO - Job 13: Subtask load_dates_dim
[2023-11-19T21:31:18.968+0000] {task_command.py:416} INFO - Running <TaskInstance: outcomes_dag.load_dates_dim scheduled__2023-11-18T00:00:00+00:00 [running]> on host bceb2bfddd0e
[2023-11-19T21:31:19.044+0000] {taskinstance.py:1662} INFO - Exporting env vars: AIRFLOW_CTX_DAG_OWNER='***' AIRFLOW_CTX_DAG_ID='outcomes_dag' AIRFLOW_CTX_TASK_ID='load_dates_dim' AIRFLOW_CTX_EXECUTION_DATE='2023-11-18T00:00:00+00:00' AIRFLOW_CTX_TRY_NUMBER='1' AIRFLOW_CTX_DAG_RUN_ID='scheduled__2023-11-18T00:00:00+00:00'
[2023-11-19T21:31:19.657+0000] {logging_mixin.py:154} INFO - dim_dates loaded
[2023-11-19T21:31:19.657+0000] {python.py:194} INFO - Done. Returned value was: None
[2023-11-19T21:31:19.671+0000] {taskinstance.py:1400} INFO - Marking task as SUCCESS. dag_id=outcomes_dag, task_id=load_dates_dim, execution_date=20231118T000000, start_date=20231119T213118, end_date=20231119T213119
[2023-11-19T21:31:19.710+0000] {local_task_job_runner.py:228} INFO - Task exited with return code 0
[2023-11-20T17:17:50.400+0000] {taskinstance.py:1159} INFO - Dependencies all met for dep_context=non-requeueable deps ti=<TaskInstance: outcomes_dag.load_dates_dim scheduled__2023-11-18T00:00:00+00:00 [queued]>
[2023-11-20T17:17:50.423+0000] {taskinstance.py:1159} INFO - Dependencies all met for dep_context=requeueable deps ti=<TaskInstance: outcomes_dag.load_dates_dim scheduled__2023-11-18T00:00:00+00:00 [queued]>
[2023-11-20T17:17:50.424+0000] {taskinstance.py:1361} INFO - Starting attempt 1 of 1
[2023-11-20T17:17:50.458+0000] {taskinstance.py:1382} INFO - Executing <Task(PythonOperator): load_dates_dim> on 2023-11-18 00:00:00+00:00
[2023-11-20T17:17:50.592+0000] {standard_task_runner.py:57} INFO - Started process 153 to run task
[2023-11-20T17:17:50.613+0000] {standard_task_runner.py:84} INFO - Running: ['***', 'tasks', 'run', 'outcomes_dag', 'load_dates_dim', 'scheduled__2023-11-18T00:00:00+00:00', '--job-id', '12', '--raw', '--subdir', 'DAGS_FOLDER/outcomes_dag.py', '--cfg-path', '/tmp/tmp9l2gr9e_']
[2023-11-20T17:17:50.652+0000] {standard_task_runner.py:85} INFO - Job 12: Subtask load_dates_dim
[2023-11-20T17:17:50.825+0000] {task_command.py:416} INFO - Running <TaskInstance: outcomes_dag.load_dates_dim scheduled__2023-11-18T00:00:00+00:00 [running]> on host c82b86fb091d
[2023-11-20T17:17:50.991+0000] {taskinstance.py:1662} INFO - Exporting env vars: AIRFLOW_CTX_DAG_OWNER='***' AIRFLOW_CTX_DAG_ID='outcomes_dag' AIRFLOW_CTX_TASK_ID='load_dates_dim' AIRFLOW_CTX_EXECUTION_DATE='2023-11-18T00:00:00+00:00' AIRFLOW_CTX_TRY_NUMBER='1' AIRFLOW_CTX_DAG_RUN_ID='scheduled__2023-11-18T00:00:00+00:00'
[2023-11-20T17:18:07.178+0000] {taskinstance.py:1937} ERROR - Task failed with exception
Traceback (most recent call last):
  File "/home/airflow/.local/lib/python3.8/site-packages/sqlalchemy/engine/base.py", line 3371, in _wrap_pool_connect
    return fn()
  File "/home/airflow/.local/lib/python3.8/site-packages/sqlalchemy/pool/base.py", line 327, in connect
    return _ConnectionFairy._checkout(self)
  File "/home/airflow/.local/lib/python3.8/site-packages/sqlalchemy/pool/base.py", line 894, in _checkout
    fairy = _ConnectionRecord.checkout(pool)
  File "/home/airflow/.local/lib/python3.8/site-packages/sqlalchemy/pool/base.py", line 493, in checkout
    rec = pool._do_get()
  File "/home/airflow/.local/lib/python3.8/site-packages/sqlalchemy/pool/impl.py", line 146, in _do_get
    self._dec_overflow()
  File "/home/airflow/.local/lib/python3.8/site-packages/sqlalchemy/util/langhelpers.py", line 70, in __exit__
    compat.raise_(
  File "/home/airflow/.local/lib/python3.8/site-packages/sqlalchemy/util/compat.py", line 211, in raise_
    raise exception
  File "/home/airflow/.local/lib/python3.8/site-packages/sqlalchemy/pool/impl.py", line 143, in _do_get
    return self._create_connection()
  File "/home/airflow/.local/lib/python3.8/site-packages/sqlalchemy/pool/base.py", line 273, in _create_connection
    return _ConnectionRecord(self)
  File "/home/airflow/.local/lib/python3.8/site-packages/sqlalchemy/pool/base.py", line 388, in __init__
    self.__connect()
  File "/home/airflow/.local/lib/python3.8/site-packages/sqlalchemy/pool/base.py", line 691, in __connect
    pool.logger.debug("Error on connect(): %s", e)
  File "/home/airflow/.local/lib/python3.8/site-packages/sqlalchemy/util/langhelpers.py", line 70, in __exit__
    compat.raise_(
  File "/home/airflow/.local/lib/python3.8/site-packages/sqlalchemy/util/compat.py", line 211, in raise_
    raise exception
  File "/home/airflow/.local/lib/python3.8/site-packages/sqlalchemy/pool/base.py", line 686, in __connect
    self.dbapi_connection = connection = pool._invoke_creator(self)
  File "/home/airflow/.local/lib/python3.8/site-packages/sqlalchemy/engine/create.py", line 574, in connect
    return dialect.connect(*cargs, **cparams)
  File "/home/airflow/.local/lib/python3.8/site-packages/sqlalchemy/engine/default.py", line 598, in connect
    return self.dbapi.connect(*cargs, **cparams)
  File "/home/airflow/.local/lib/python3.8/site-packages/psycopg2/__init__.py", line 122, in connect
    conn = _connect(dsn, connection_factory=connection_factory, **kwasync)
psycopg2.OperationalError: connection to server at "dpg-cldp6jef27hc73fbu0rg-a.oregon-postgres.render.com" (35.227.164.209), port 5432 failed: server closed the connection unexpectedly
	This probably means the server terminated abnormally
	before or while processing the request.


The above exception was the direct cause of the following exception:

Traceback (most recent call last):
  File "/home/airflow/.local/lib/python3.8/site-packages/airflow/operators/python.py", line 192, in execute
    return_value = self.execute_callable()
  File "/home/airflow/.local/lib/python3.8/site-packages/airflow/operators/python.py", line 209, in execute_callable
    return self.python_callable(*self.op_args, **self.op_kwargs)
  File "/opt/airflow/dags/etl_scripts/load.py", line 23, in load_data
    pd.read_csv(obj['Body'], index_col=0).to_sql(table_name, conn, if_exists="append", index=False, method=insert_on_conflict_nothing)
  File "/home/airflow/.local/lib/python3.8/site-packages/pandas/core/generic.py", line 2878, in to_sql
    return sql.to_sql(
  File "/home/airflow/.local/lib/python3.8/site-packages/pandas/io/sql.py", line 768, in to_sql
    with pandasSQL_builder(con, schema=schema, need_transaction=True) as pandas_sql:
  File "/home/airflow/.local/lib/python3.8/site-packages/pandas/io/sql.py", line 832, in pandasSQL_builder
    return SQLDatabase(con, schema, need_transaction)
  File "/home/airflow/.local/lib/python3.8/site-packages/pandas/io/sql.py", line 1539, in __init__
    con = self.exit_stack.enter_context(con.connect())
  File "/home/airflow/.local/lib/python3.8/site-packages/sqlalchemy/engine/base.py", line 3325, in connect
    return self._connection_cls(self, close_with_result=close_with_result)
  File "/home/airflow/.local/lib/python3.8/site-packages/sqlalchemy/engine/base.py", line 96, in __init__
    else engine.raw_connection()
  File "/home/airflow/.local/lib/python3.8/site-packages/sqlalchemy/engine/base.py", line 3404, in raw_connection
    return self._wrap_pool_connect(self.pool.connect, _connection)
  File "/home/airflow/.local/lib/python3.8/site-packages/sqlalchemy/engine/base.py", line 3374, in _wrap_pool_connect
    Connection._handle_dbapi_exception_noconnection(
  File "/home/airflow/.local/lib/python3.8/site-packages/sqlalchemy/engine/base.py", line 2208, in _handle_dbapi_exception_noconnection
    util.raise_(
  File "/home/airflow/.local/lib/python3.8/site-packages/sqlalchemy/util/compat.py", line 211, in raise_
    raise exception
  File "/home/airflow/.local/lib/python3.8/site-packages/sqlalchemy/engine/base.py", line 3371, in _wrap_pool_connect
    return fn()
  File "/home/airflow/.local/lib/python3.8/site-packages/sqlalchemy/pool/base.py", line 327, in connect
    return _ConnectionFairy._checkout(self)
  File "/home/airflow/.local/lib/python3.8/site-packages/sqlalchemy/pool/base.py", line 894, in _checkout
    fairy = _ConnectionRecord.checkout(pool)
  File "/home/airflow/.local/lib/python3.8/site-packages/sqlalchemy/pool/base.py", line 493, in checkout
    rec = pool._do_get()
  File "/home/airflow/.local/lib/python3.8/site-packages/sqlalchemy/pool/impl.py", line 146, in _do_get
    self._dec_overflow()
  File "/home/airflow/.local/lib/python3.8/site-packages/sqlalchemy/util/langhelpers.py", line 70, in __exit__
    compat.raise_(
  File "/home/airflow/.local/lib/python3.8/site-packages/sqlalchemy/util/compat.py", line 211, in raise_
    raise exception
  File "/home/airflow/.local/lib/python3.8/site-packages/sqlalchemy/pool/impl.py", line 143, in _do_get
    return self._create_connection()
  File "/home/airflow/.local/lib/python3.8/site-packages/sqlalchemy/pool/base.py", line 273, in _create_connection
    return _ConnectionRecord(self)
  File "/home/airflow/.local/lib/python3.8/site-packages/sqlalchemy/pool/base.py", line 388, in __init__
    self.__connect()
  File "/home/airflow/.local/lib/python3.8/site-packages/sqlalchemy/pool/base.py", line 691, in __connect
    pool.logger.debug("Error on connect(): %s", e)
  File "/home/airflow/.local/lib/python3.8/site-packages/sqlalchemy/util/langhelpers.py", line 70, in __exit__
    compat.raise_(
  File "/home/airflow/.local/lib/python3.8/site-packages/sqlalchemy/util/compat.py", line 211, in raise_
    raise exception
  File "/home/airflow/.local/lib/python3.8/site-packages/sqlalchemy/pool/base.py", line 686, in __connect
    self.dbapi_connection = connection = pool._invoke_creator(self)
  File "/home/airflow/.local/lib/python3.8/site-packages/sqlalchemy/engine/create.py", line 574, in connect
    return dialect.connect(*cargs, **cparams)
  File "/home/airflow/.local/lib/python3.8/site-packages/sqlalchemy/engine/default.py", line 598, in connect
    return self.dbapi.connect(*cargs, **cparams)
  File "/home/airflow/.local/lib/python3.8/site-packages/psycopg2/__init__.py", line 122, in connect
    conn = _connect(dsn, connection_factory=connection_factory, **kwasync)
sqlalchemy.exc.OperationalError: (psycopg2.OperationalError) connection to server at "dpg-cldp6jef27hc73fbu0rg-a.oregon-postgres.render.com" (35.227.164.209), port 5432 failed: server closed the connection unexpectedly
	This probably means the server terminated abnormally
	before or while processing the request.

(Background on this error at: https://sqlalche.me/e/14/e3q8)
[2023-11-20T17:18:07.220+0000] {taskinstance.py:1400} INFO - Marking task as FAILED. dag_id=outcomes_dag, task_id=load_dates_dim, execution_date=20231118T000000, start_date=20231120T171750, end_date=20231120T171807
[2023-11-20T17:18:07.231+0000] {standard_task_runner.py:104} ERROR - Failed to execute job 12 for task load_dates_dim ((psycopg2.OperationalError) connection to server at "dpg-cldp6jef27hc73fbu0rg-a.oregon-postgres.render.com" (35.227.164.209), port 5432 failed: server closed the connection unexpectedly
	This probably means the server terminated abnormally
	before or while processing the request.

(Background on this error at: https://sqlalche.me/e/14/e3q8); 153)
[2023-11-20T17:18:07.248+0000] {local_task_job_runner.py:228} INFO - Task exited with return code 1
