[2023-11-19T07:33:21.000+0000] {taskinstance.py:1159} INFO - Dependencies all met for dep_context=non-requeueable deps ti=<TaskInstance: outcomes_dag.load_outcomes_fct manual__2023-11-19T07:32:44.273578+00:00 [queued]>
[2023-11-19T07:33:21.005+0000] {taskinstance.py:1159} INFO - Dependencies all met for dep_context=requeueable deps ti=<TaskInstance: outcomes_dag.load_outcomes_fct manual__2023-11-19T07:32:44.273578+00:00 [queued]>
[2023-11-19T07:33:21.005+0000] {taskinstance.py:1361} INFO - Starting attempt 1 of 1
[2023-11-19T07:33:21.010+0000] {taskinstance.py:1382} INFO - Executing <Task(PythonOperator): load_outcomes_fct> on 2023-11-19 07:32:44.273578+00:00
[2023-11-19T07:33:21.014+0000] {standard_task_runner.py:57} INFO - Started process 185 to run task
[2023-11-19T07:33:21.017+0000] {standard_task_runner.py:84} INFO - Running: ['***', 'tasks', 'run', 'outcomes_dag', 'load_outcomes_fct', 'manual__2023-11-19T07:32:44.273578+00:00', '--job-id', '18', '--raw', '--subdir', 'DAGS_FOLDER/outcomes_dag.py', '--cfg-path', '/tmp/tmpp9qsdx3d']
[2023-11-19T07:33:21.019+0000] {standard_task_runner.py:85} INFO - Job 18: Subtask load_outcomes_fct
[2023-11-19T07:33:21.048+0000] {task_command.py:416} INFO - Running <TaskInstance: outcomes_dag.load_outcomes_fct manual__2023-11-19T07:32:44.273578+00:00 [running]> on host 13403f191858
[2023-11-19T07:33:21.247+0000] {taskinstance.py:1662} INFO - Exporting env vars: AIRFLOW_CTX_DAG_OWNER='***' AIRFLOW_CTX_DAG_ID='outcomes_dag' AIRFLOW_CTX_TASK_ID='load_outcomes_fct' AIRFLOW_CTX_EXECUTION_DATE='2023-11-19T07:32:44.273578+00:00' AIRFLOW_CTX_TRY_NUMBER='1' AIRFLOW_CTX_DAG_RUN_ID='manual__2023-11-19T07:32:44.273578+00:00'
[2023-11-19T07:33:22.160+0000] {taskinstance.py:1937} ERROR - Task failed with exception
Traceback (most recent call last):
  File "/home/airflow/.local/lib/python3.8/site-packages/sqlalchemy/engine/base.py", line 1910, in _execute_context
    self.dialect.do_execute(
  File "/home/airflow/.local/lib/python3.8/site-packages/sqlalchemy/engine/default.py", line 736, in do_execute
    cursor.execute(statement, parameters)
psycopg2.errors.InternalError_: could not open relation with OID 16405


The above exception was the direct cause of the following exception:

Traceback (most recent call last):
  File "/home/airflow/.local/lib/python3.8/site-packages/airflow/operators/python.py", line 192, in execute
    return_value = self.execute_callable()
  File "/home/airflow/.local/lib/python3.8/site-packages/airflow/operators/python.py", line 209, in execute_callable
    return self.python_callable(*self.op_args, **self.op_kwargs)
  File "/opt/airflow/dags/etl_scripts/load.py", line 32, in load_fact_data
    pd.read_parquet(table_file).to_sql(table_name, conn, if_exists="replace", index=False,)
  File "/home/airflow/.local/lib/python3.8/site-packages/pandas/core/generic.py", line 2878, in to_sql
    return sql.to_sql(
  File "/home/airflow/.local/lib/python3.8/site-packages/pandas/io/sql.py", line 769, in to_sql
    return pandas_sql.to_sql(
  File "/home/airflow/.local/lib/python3.8/site-packages/pandas/io/sql.py", line 1910, in to_sql
    table = self.prep_table(
  File "/home/airflow/.local/lib/python3.8/site-packages/pandas/io/sql.py", line 1814, in prep_table
    table.create()
  File "/home/airflow/.local/lib/python3.8/site-packages/pandas/io/sql.py", line 907, in create
    self.pd_sql.drop_table(self.name, self.schema)
  File "/home/airflow/.local/lib/python3.8/site-packages/pandas/io/sql.py", line 1961, in drop_table
    self.meta.reflect(bind=self.con, only=[table_name], schema=schema)
  File "/home/airflow/.local/lib/python3.8/site-packages/sqlalchemy/sql/schema.py", line 4901, in reflect
    Table(name, self, **reflect_opts)
  File "<string>", line 2, in __new__
  File "/home/airflow/.local/lib/python3.8/site-packages/sqlalchemy/util/deprecations.py", line 375, in warned
    return fn(*args, **kwargs)
  File "/home/airflow/.local/lib/python3.8/site-packages/sqlalchemy/sql/schema.py", line 619, in __new__
    metadata._remove_table(name, schema)
  File "/home/airflow/.local/lib/python3.8/site-packages/sqlalchemy/util/langhelpers.py", line 70, in __exit__
    compat.raise_(
  File "/home/airflow/.local/lib/python3.8/site-packages/sqlalchemy/util/compat.py", line 211, in raise_
    raise exception
  File "/home/airflow/.local/lib/python3.8/site-packages/sqlalchemy/sql/schema.py", line 614, in __new__
    table._init(name, metadata, *args, **kw)
  File "/home/airflow/.local/lib/python3.8/site-packages/sqlalchemy/sql/schema.py", line 689, in _init
    self._autoload(
  File "/home/airflow/.local/lib/python3.8/site-packages/sqlalchemy/sql/schema.py", line 724, in _autoload
    conn_insp.reflect_table(
  File "/home/airflow/.local/lib/python3.8/site-packages/sqlalchemy/engine/reflection.py", line 774, in reflect_table
    for col_d in self.get_columns(
  File "/home/airflow/.local/lib/python3.8/site-packages/sqlalchemy/engine/reflection.py", line 497, in get_columns
    col_defs = self.dialect.get_columns(
  File "<string>", line 2, in get_columns
  File "/home/airflow/.local/lib/python3.8/site-packages/sqlalchemy/engine/reflection.py", line 55, in cache
    ret = fn(self, con, *args, **kw)
  File "/home/airflow/.local/lib/python3.8/site-packages/sqlalchemy/dialects/postgresql/base.py", line 3918, in get_columns
    c = connection.execute(s, dict(table_oid=table_oid))
  File "/home/airflow/.local/lib/python3.8/site-packages/sqlalchemy/engine/base.py", line 1385, in execute
    return meth(self, multiparams, params, _EMPTY_EXECUTION_OPTS)
  File "/home/airflow/.local/lib/python3.8/site-packages/sqlalchemy/sql/elements.py", line 334, in _execute_on_connection
    return connection._execute_clauseelement(
  File "/home/airflow/.local/lib/python3.8/site-packages/sqlalchemy/engine/base.py", line 1577, in _execute_clauseelement
    ret = self._execute_context(
  File "/home/airflow/.local/lib/python3.8/site-packages/sqlalchemy/engine/base.py", line 1953, in _execute_context
    self._handle_dbapi_exception(
  File "/home/airflow/.local/lib/python3.8/site-packages/sqlalchemy/engine/base.py", line 2134, in _handle_dbapi_exception
    util.raise_(
  File "/home/airflow/.local/lib/python3.8/site-packages/sqlalchemy/util/compat.py", line 211, in raise_
    raise exception
  File "/home/airflow/.local/lib/python3.8/site-packages/sqlalchemy/engine/base.py", line 1910, in _execute_context
    self.dialect.do_execute(
  File "/home/airflow/.local/lib/python3.8/site-packages/sqlalchemy/engine/default.py", line 736, in do_execute
    cursor.execute(statement, parameters)
sqlalchemy.exc.InternalError: (psycopg2.errors.InternalError_) could not open relation with OID 16405

[SQL: 
            SELECT a.attname,
              pg_catalog.format_type(a.atttypid, a.atttypmod),
              (
                SELECT pg_catalog.pg_get_expr(d.adbin, d.adrelid)
                FROM pg_catalog.pg_attrdef d
                WHERE d.adrelid = a.attrelid AND d.adnum = a.attnum
                AND a.atthasdef
              ) AS DEFAULT,
              a.attnotnull,
              a.attrelid as table_oid,
              pgd.description as comment,
              a.attgenerated as generated,
                              (SELECT json_build_object(
                    'always', a.attidentity = 'a',
                    'start', s.seqstart,
                    'increment', s.seqincrement,
                    'minvalue', s.seqmin,
                    'maxvalue', s.seqmax,
                    'cache', s.seqcache,
                    'cycle', s.seqcycle)
                FROM pg_catalog.pg_sequence s
                JOIN pg_catalog.pg_class c on s.seqrelid = c."oid"
                WHERE c.relkind = 'S'
                AND a.attidentity != ''
                AND s.seqrelid = pg_catalog.pg_get_serial_sequence(
                    a.attrelid::regclass::text, a.attname
                )::regclass::oid
                ) as identity_options                
            FROM pg_catalog.pg_attribute a
            LEFT JOIN pg_catalog.pg_description pgd ON (
                pgd.objoid = a.attrelid AND pgd.objsubid = a.attnum)
            WHERE a.attrelid = %(table_oid)s
            AND a.attnum > 0 AND NOT a.attisdropped
            ORDER BY a.attnum
        ]
[parameters: {'table_oid': 16405}]
(Background on this error at: https://sqlalche.me/e/14/2j85)
[2023-11-19T07:33:22.183+0000] {taskinstance.py:1400} INFO - Marking task as FAILED. dag_id=outcomes_dag, task_id=load_outcomes_fct, execution_date=20231119T073244, start_date=20231119T073321, end_date=20231119T073322
[2023-11-19T07:33:22.189+0000] {standard_task_runner.py:104} ERROR - Failed to execute job 18 for task load_outcomes_fct ((psycopg2.errors.InternalError_) could not open relation with OID 16405

[SQL: 
            SELECT a.attname,
              pg_catalog.format_type(a.atttypid, a.atttypmod),
              (
                SELECT pg_catalog.pg_get_expr(d.adbin, d.adrelid)
                FROM pg_catalog.pg_attrdef d
                WHERE d.adrelid = a.attrelid AND d.adnum = a.attnum
                AND a.atthasdef
              ) AS DEFAULT,
              a.attnotnull,
              a.attrelid as table_oid,
              pgd.description as comment,
              a.attgenerated as generated,
                              (SELECT json_build_object(
                    'always', a.attidentity = 'a',
                    'start', s.seqstart,
                    'increment', s.seqincrement,
                    'minvalue', s.seqmin,
                    'maxvalue', s.seqmax,
                    'cache', s.seqcache,
                    'cycle', s.seqcycle)
                FROM pg_catalog.pg_sequence s
                JOIN pg_catalog.pg_class c on s.seqrelid = c."oid"
                WHERE c.relkind = 'S'
                AND a.attidentity != ''
                AND s.seqrelid = pg_catalog.pg_get_serial_sequence(
                    a.attrelid::regclass::text, a.attname
                )::regclass::oid
                ) as identity_options                
            FROM pg_catalog.pg_attribute a
            LEFT JOIN pg_catalog.pg_description pgd ON (
                pgd.objoid = a.attrelid AND pgd.objsubid = a.attnum)
            WHERE a.attrelid = %(table_oid)s
            AND a.attnum > 0 AND NOT a.attisdropped
            ORDER BY a.attnum
        ]
[parameters: {'table_oid': 16405}]
(Background on this error at: https://sqlalche.me/e/14/2j85); 185)
[2023-11-19T07:33:22.203+0000] {local_task_job_runner.py:228} INFO - Task exited with return code 1
[2023-11-19T07:33:22.214+0000] {taskinstance.py:2778} INFO - 0 downstream tasks scheduled from follow-on schedule check
