[2023-11-19T21:07:50.584+0000] {taskinstance.py:1159} INFO - Dependencies all met for dep_context=non-requeueable deps ti=<TaskInstance: outcomes_dag.transform manual__2023-11-19T21:07:46.337213+00:00 [queued]>
[2023-11-19T21:07:50.587+0000] {taskinstance.py:1159} INFO - Dependencies all met for dep_context=requeueable deps ti=<TaskInstance: outcomes_dag.transform manual__2023-11-19T21:07:46.337213+00:00 [queued]>
[2023-11-19T21:07:50.587+0000] {taskinstance.py:1361} INFO - Starting attempt 1 of 1
[2023-11-19T21:07:50.592+0000] {taskinstance.py:1382} INFO - Executing <Task(PythonOperator): transform> on 2023-11-19 21:07:46.337213+00:00
[2023-11-19T21:07:50.598+0000] {standard_task_runner.py:57} INFO - Started process 80 to run task
[2023-11-19T21:07:50.601+0000] {standard_task_runner.py:84} INFO - Running: ['***', 'tasks', 'run', 'outcomes_dag', 'transform', 'manual__2023-11-19T21:07:46.337213+00:00', '--job-id', '7', '--raw', '--subdir', 'DAGS_FOLDER/outcomes_dag.py', '--cfg-path', '/tmp/tmps318d863']
[2023-11-19T21:07:50.603+0000] {standard_task_runner.py:85} INFO - Job 7: Subtask transform
[2023-11-19T21:07:50.636+0000] {task_command.py:416} INFO - Running <TaskInstance: outcomes_dag.transform manual__2023-11-19T21:07:46.337213+00:00 [running]> on host 39e21f8b1ec3
[2023-11-19T21:07:50.687+0000] {taskinstance.py:1662} INFO - Exporting env vars: AIRFLOW_CTX_DAG_OWNER='***' AIRFLOW_CTX_DAG_ID='outcomes_dag' AIRFLOW_CTX_TASK_ID='transform' AIRFLOW_CTX_EXECUTION_DATE='2023-11-19T21:07:46.337213+00:00' AIRFLOW_CTX_TRY_NUMBER='1' AIRFLOW_CTX_DAG_RUN_ID='manual__2023-11-19T21:07:46.337213+00:00'
[2023-11-19T21:07:51.101+0000] {taskinstance.py:1937} ERROR - Task failed with exception
Traceback (most recent call last):
  File "/home/airflow/.local/lib/python3.8/site-packages/airflow/operators/python.py", line 192, in execute
    return_value = self.execute_callable()
  File "/home/airflow/.local/lib/python3.8/site-packages/airflow/operators/python.py", line 209, in execute_callable
    return self.python_callable(*self.op_args, **self.op_kwargs)
  File "/opt/airflow/dags/etl_scripts/transform.py", line 23, in transform_data
    new_data = pd.read_csv(obj['Body'], index_col=0)
  File "/home/airflow/.local/lib/python3.8/site-packages/pandas/io/parsers/readers.py", line 912, in read_csv
    return _read(filepath_or_buffer, kwds)
  File "/home/airflow/.local/lib/python3.8/site-packages/pandas/io/parsers/readers.py", line 577, in _read
    parser = TextFileReader(filepath_or_buffer, **kwds)
  File "/home/airflow/.local/lib/python3.8/site-packages/pandas/io/parsers/readers.py", line 1407, in __init__
    self._engine = self._make_engine(f, self.engine)
  File "/home/airflow/.local/lib/python3.8/site-packages/pandas/io/parsers/readers.py", line 1679, in _make_engine
    return mapping[engine](f, **self.options)
  File "/home/airflow/.local/lib/python3.8/site-packages/pandas/io/parsers/c_parser_wrapper.py", line 93, in __init__
    self._reader = parsers.TextReader(src, **kwds)
  File "pandas/_libs/parsers.pyx", line 557, in pandas._libs.parsers.TextReader.__cinit__
pandas.errors.EmptyDataError: No columns to parse from file
[2023-11-19T21:07:51.113+0000] {taskinstance.py:1400} INFO - Marking task as FAILED. dag_id=outcomes_dag, task_id=transform, execution_date=20231119T210746, start_date=20231119T210750, end_date=20231119T210751
[2023-11-19T21:07:51.121+0000] {standard_task_runner.py:104} ERROR - Failed to execute job 7 for task transform (No columns to parse from file; 80)
[2023-11-19T21:07:51.145+0000] {local_task_job_runner.py:228} INFO - Task exited with return code 1
