[2023-11-19T09:45:37.097+0000] {taskinstance.py:1159} INFO - Dependencies all met for dep_context=non-requeueable deps ti=<TaskInstance: outcomes_dag.transform manual__2023-11-19T09:45:32.256155+00:00 [queued]>
[2023-11-19T09:45:37.103+0000] {taskinstance.py:1159} INFO - Dependencies all met for dep_context=requeueable deps ti=<TaskInstance: outcomes_dag.transform manual__2023-11-19T09:45:32.256155+00:00 [queued]>
[2023-11-19T09:45:37.104+0000] {taskinstance.py:1361} INFO - Starting attempt 1 of 1
[2023-11-19T09:45:37.129+0000] {taskinstance.py:1382} INFO - Executing <Task(PythonOperator): transform> on 2023-11-19 09:45:32.256155+00:00
[2023-11-19T09:45:37.134+0000] {standard_task_runner.py:57} INFO - Started process 402 to run task
[2023-11-19T09:45:37.143+0000] {standard_task_runner.py:84} INFO - Running: ['***', 'tasks', 'run', 'outcomes_dag', 'transform', 'manual__2023-11-19T09:45:32.256155+00:00', '--job-id', '33', '--raw', '--subdir', 'DAGS_FOLDER/outcomes_dag.py', '--cfg-path', '/tmp/tmp3d748x_u']
[2023-11-19T09:45:37.147+0000] {standard_task_runner.py:85} INFO - Job 33: Subtask transform
[2023-11-19T09:45:37.218+0000] {task_command.py:416} INFO - Running <TaskInstance: outcomes_dag.transform manual__2023-11-19T09:45:32.256155+00:00 [running]> on host 696613a1ef55
[2023-11-19T09:45:37.274+0000] {taskinstance.py:1662} INFO - Exporting env vars: AIRFLOW_CTX_DAG_OWNER='***' AIRFLOW_CTX_DAG_ID='outcomes_dag' AIRFLOW_CTX_TASK_ID='transform' AIRFLOW_CTX_EXECUTION_DATE='2023-11-19T09:45:32.256155+00:00' AIRFLOW_CTX_TRY_NUMBER='1' AIRFLOW_CTX_DAG_RUN_ID='manual__2023-11-19T09:45:32.256155+00:00'
[2023-11-19T09:45:37.275+0000] {taskinstance.py:1937} ERROR - Task failed with exception
Traceback (most recent call last):
  File "/home/airflow/.local/lib/python3.8/site-packages/airflow/operators/python.py", line 192, in execute
    return_value = self.execute_callable()
  File "/home/airflow/.local/lib/python3.8/site-packages/airflow/operators/python.py", line 209, in execute_callable
    return self.python_callable(*self.op_args, **self.op_kwargs)
TypeError: transform_data() missing 1 required positional argument: 'filename'
[2023-11-19T09:45:37.283+0000] {taskinstance.py:1400} INFO - Marking task as FAILED. dag_id=outcomes_dag, task_id=transform, execution_date=20231119T094532, start_date=20231119T094537, end_date=20231119T094537
[2023-11-19T09:45:37.290+0000] {standard_task_runner.py:104} ERROR - Failed to execute job 33 for task transform (transform_data() missing 1 required positional argument: 'filename'; 402)
[2023-11-19T09:45:37.317+0000] {local_task_job_runner.py:228} INFO - Task exited with return code 1
[2023-11-19T09:45:37.333+0000] {taskinstance.py:2778} INFO - 0 downstream tasks scheduled from follow-on schedule check
