[2023-11-19T06:28:24.682+0000] {taskinstance.py:1159} INFO - Dependencies all met for dep_context=non-requeueable deps ti=<TaskInstance: outcomes_dag.load_outcome_types_dim scheduled__2023-11-18T00:00:00+00:00 [queued]>
[2023-11-19T06:28:24.691+0000] {taskinstance.py:1159} INFO - Dependencies all met for dep_context=requeueable deps ti=<TaskInstance: outcomes_dag.load_outcome_types_dim scheduled__2023-11-18T00:00:00+00:00 [queued]>
[2023-11-19T06:28:24.691+0000] {taskinstance.py:1361} INFO - Starting attempt 1 of 1
[2023-11-19T06:28:24.706+0000] {taskinstance.py:1382} INFO - Executing <Task(PythonOperator): load_outcome_types_dim> on 2023-11-18 00:00:00+00:00
[2023-11-19T06:28:24.713+0000] {standard_task_runner.py:57} INFO - Started process 105 to run task
[2023-11-19T06:28:24.720+0000] {standard_task_runner.py:84} INFO - Running: ['***', 'tasks', 'run', 'outcomes_dag', 'load_outcome_types_dim', 'scheduled__2023-11-18T00:00:00+00:00', '--job-id', '12', '--raw', '--subdir', 'DAGS_FOLDER/outcomes_dag.py', '--cfg-path', '/tmp/tmpjor5wzw_']
[2023-11-19T06:28:24.722+0000] {standard_task_runner.py:85} INFO - Job 12: Subtask load_outcome_types_dim
[2023-11-19T06:28:24.789+0000] {task_command.py:416} INFO - Running <TaskInstance: outcomes_dag.load_outcome_types_dim scheduled__2023-11-18T00:00:00+00:00 [running]> on host 8c758415f3b2
[2023-11-19T06:28:25.340+0000] {taskinstance.py:1662} INFO - Exporting env vars: AIRFLOW_CTX_DAG_OWNER='***' AIRFLOW_CTX_DAG_ID='outcomes_dag' AIRFLOW_CTX_TASK_ID='load_outcome_types_dim' AIRFLOW_CTX_EXECUTION_DATE='2023-11-18T00:00:00+00:00' AIRFLOW_CTX_TRY_NUMBER='1' AIRFLOW_CTX_DAG_RUN_ID='scheduled__2023-11-18T00:00:00+00:00'
[2023-11-19T06:28:25.403+0000] {logging_mixin.py:154} INFO - dim_outcome_types loaded
[2023-11-19T06:28:25.403+0000] {python.py:194} INFO - Done. Returned value was: None
[2023-11-19T06:28:25.410+0000] {taskinstance.py:1400} INFO - Marking task as SUCCESS. dag_id=outcomes_dag, task_id=load_outcome_types_dim, execution_date=20231118T000000, start_date=20231119T062824, end_date=20231119T062825
[2023-11-19T06:28:25.464+0000] {local_task_job_runner.py:228} INFO - Task exited with return code 0
[2023-11-19T06:28:25.478+0000] {taskinstance.py:2778} INFO - 0 downstream tasks scheduled from follow-on schedule check
[2023-11-19T07:33:05.047+0000] {taskinstance.py:1159} INFO - Dependencies all met for dep_context=non-requeueable deps ti=<TaskInstance: outcomes_dag.load_outcome_types_dim scheduled__2023-11-18T00:00:00+00:00 [queued]>
[2023-11-19T07:33:05.059+0000] {taskinstance.py:1159} INFO - Dependencies all met for dep_context=requeueable deps ti=<TaskInstance: outcomes_dag.load_outcome_types_dim scheduled__2023-11-18T00:00:00+00:00 [queued]>
[2023-11-19T07:33:05.059+0000] {taskinstance.py:1361} INFO - Starting attempt 1 of 1
[2023-11-19T07:33:05.069+0000] {taskinstance.py:1382} INFO - Executing <Task(PythonOperator): load_outcome_types_dim> on 2023-11-18 00:00:00+00:00
[2023-11-19T07:33:05.074+0000] {standard_task_runner.py:57} INFO - Started process 126 to run task
[2023-11-19T07:33:05.079+0000] {standard_task_runner.py:84} INFO - Running: ['***', 'tasks', 'run', 'outcomes_dag', 'load_outcome_types_dim', 'scheduled__2023-11-18T00:00:00+00:00', '--job-id', '12', '--raw', '--subdir', 'DAGS_FOLDER/outcomes_dag.py', '--cfg-path', '/tmp/tmp9tgyit_h']
[2023-11-19T07:33:05.095+0000] {standard_task_runner.py:85} INFO - Job 12: Subtask load_outcome_types_dim
[2023-11-19T07:33:05.168+0000] {task_command.py:416} INFO - Running <TaskInstance: outcomes_dag.load_outcome_types_dim scheduled__2023-11-18T00:00:00+00:00 [running]> on host 13403f191858
[2023-11-19T07:33:05.586+0000] {taskinstance.py:1662} INFO - Exporting env vars: AIRFLOW_CTX_DAG_OWNER='***' AIRFLOW_CTX_DAG_ID='outcomes_dag' AIRFLOW_CTX_TASK_ID='load_outcome_types_dim' AIRFLOW_CTX_EXECUTION_DATE='2023-11-18T00:00:00+00:00' AIRFLOW_CTX_TRY_NUMBER='1' AIRFLOW_CTX_DAG_RUN_ID='scheduled__2023-11-18T00:00:00+00:00'
[2023-11-19T07:33:05.642+0000] {logging_mixin.py:154} INFO - dim_outcome_types loaded
[2023-11-19T07:33:05.643+0000] {python.py:194} INFO - Done. Returned value was: None
[2023-11-19T07:33:05.652+0000] {taskinstance.py:1400} INFO - Marking task as SUCCESS. dag_id=outcomes_dag, task_id=load_outcome_types_dim, execution_date=20231118T000000, start_date=20231119T073305, end_date=20231119T073305
[2023-11-19T07:33:05.698+0000] {local_task_job_runner.py:228} INFO - Task exited with return code 0
[2023-11-19T07:33:05.719+0000] {taskinstance.py:2778} INFO - 0 downstream tasks scheduled from follow-on schedule check
[2023-11-19T09:32:53.800+0000] {taskinstance.py:1159} INFO - Dependencies all met for dep_context=non-requeueable deps ti=<TaskInstance: outcomes_dag.load_outcome_types_dim scheduled__2023-11-18T00:00:00+00:00 [queued]>
[2023-11-19T09:32:53.838+0000] {taskinstance.py:1159} INFO - Dependencies all met for dep_context=requeueable deps ti=<TaskInstance: outcomes_dag.load_outcome_types_dim scheduled__2023-11-18T00:00:00+00:00 [queued]>
[2023-11-19T09:32:53.844+0000] {taskinstance.py:1361} INFO - Starting attempt 1 of 1
[2023-11-19T09:32:53.872+0000] {taskinstance.py:1382} INFO - Executing <Task(PythonOperator): load_outcome_types_dim> on 2023-11-18 00:00:00+00:00
[2023-11-19T09:32:53.893+0000] {standard_task_runner.py:57} INFO - Started process 98 to run task
[2023-11-19T09:32:53.921+0000] {standard_task_runner.py:84} INFO - Running: ['***', 'tasks', 'run', 'outcomes_dag', 'load_outcome_types_dim', 'scheduled__2023-11-18T00:00:00+00:00', '--job-id', '10', '--raw', '--subdir', 'DAGS_FOLDER/outcomes_dag.py', '--cfg-path', '/tmp/tmpa0t7upan']
[2023-11-19T09:32:53.929+0000] {standard_task_runner.py:85} INFO - Job 10: Subtask load_outcome_types_dim
[2023-11-19T09:32:54.206+0000] {task_command.py:416} INFO - Running <TaskInstance: outcomes_dag.load_outcome_types_dim scheduled__2023-11-18T00:00:00+00:00 [running]> on host 696613a1ef55
[2023-11-19T09:32:54.345+0000] {taskinstance.py:1662} INFO - Exporting env vars: AIRFLOW_CTX_DAG_OWNER='***' AIRFLOW_CTX_DAG_ID='outcomes_dag' AIRFLOW_CTX_TASK_ID='load_outcome_types_dim' AIRFLOW_CTX_EXECUTION_DATE='2023-11-18T00:00:00+00:00' AIRFLOW_CTX_TRY_NUMBER='1' AIRFLOW_CTX_DAG_RUN_ID='scheduled__2023-11-18T00:00:00+00:00'
[2023-11-19T09:32:54.368+0000] {taskinstance.py:1937} ERROR - Task failed with exception
Traceback (most recent call last):
  File "/home/airflow/.local/lib/python3.8/site-packages/airflow/operators/python.py", line 192, in execute
    return_value = self.execute_callable()
  File "/home/airflow/.local/lib/python3.8/site-packages/airflow/operators/python.py", line 209, in execute_callable
    return self.python_callable(*self.op_args, **self.op_kwargs)
  File "/opt/airflow/dags/etl_scripts/load.py", line 25, in load_data
    pd.read_parquet(table_file).to_sql(table_name, conn, if_exists="append", index=False, method=insert_on_conflict_nothing)
  File "/home/airflow/.local/lib/python3.8/site-packages/pandas/io/parquet.py", line 509, in read_parquet
    return impl.read(
  File "/home/airflow/.local/lib/python3.8/site-packages/pandas/io/parquet.py", line 220, in read
    path_or_handle, handles, kwargs["filesystem"] = _get_path_or_handle(
  File "/home/airflow/.local/lib/python3.8/site-packages/pandas/io/parquet.py", line 110, in _get_path_or_handle
    handles = get_handle(
  File "/home/airflow/.local/lib/python3.8/site-packages/pandas/io/common.py", line 868, in get_handle
    handle = open(handle, ioargs.mode)
FileNotFoundError: [Errno 2] No such file or directory: '/opt/airflow/data/2023-11-18/processed/dim_outcome_types.parquet'
[2023-11-19T09:32:54.394+0000] {taskinstance.py:1400} INFO - Marking task as FAILED. dag_id=outcomes_dag, task_id=load_outcome_types_dim, execution_date=20231118T000000, start_date=20231119T093253, end_date=20231119T093254
[2023-11-19T09:32:54.417+0000] {standard_task_runner.py:104} ERROR - Failed to execute job 10 for task load_outcome_types_dim ([Errno 2] No such file or directory: '/opt/airflow/data/2023-11-18/processed/dim_outcome_types.parquet'; 98)
[2023-11-19T09:32:54.448+0000] {local_task_job_runner.py:228} INFO - Task exited with return code 1
[2023-11-19T09:32:54.476+0000] {taskinstance.py:2778} INFO - 0 downstream tasks scheduled from follow-on schedule check
[2023-11-19T20:43:40.311+0000] {taskinstance.py:1159} INFO - Dependencies all met for dep_context=non-requeueable deps ti=<TaskInstance: outcomes_dag.load_outcome_types_dim scheduled__2023-11-18T00:00:00+00:00 [queued]>
[2023-11-19T20:43:40.315+0000] {taskinstance.py:1159} INFO - Dependencies all met for dep_context=requeueable deps ti=<TaskInstance: outcomes_dag.load_outcome_types_dim scheduled__2023-11-18T00:00:00+00:00 [queued]>
[2023-11-19T20:43:40.315+0000] {taskinstance.py:1361} INFO - Starting attempt 1 of 1
[2023-11-19T20:43:40.321+0000] {taskinstance.py:1382} INFO - Executing <Task(PythonOperator): load_outcome_types_dim> on 2023-11-18 00:00:00+00:00
[2023-11-19T20:43:40.324+0000] {standard_task_runner.py:57} INFO - Started process 104 to run task
[2023-11-19T20:43:40.328+0000] {standard_task_runner.py:84} INFO - Running: ['***', 'tasks', 'run', 'outcomes_dag', 'load_outcome_types_dim', 'scheduled__2023-11-18T00:00:00+00:00', '--job-id', '10', '--raw', '--subdir', 'DAGS_FOLDER/outcomes_dag.py', '--cfg-path', '/tmp/tmpse44uw2z']
[2023-11-19T20:43:40.331+0000] {standard_task_runner.py:85} INFO - Job 10: Subtask load_outcome_types_dim
[2023-11-19T20:43:40.367+0000] {task_command.py:416} INFO - Running <TaskInstance: outcomes_dag.load_outcome_types_dim scheduled__2023-11-18T00:00:00+00:00 [running]> on host 549ad0bd2371
[2023-11-19T20:43:40.426+0000] {taskinstance.py:1662} INFO - Exporting env vars: AIRFLOW_CTX_DAG_OWNER='***' AIRFLOW_CTX_DAG_ID='outcomes_dag' AIRFLOW_CTX_TASK_ID='load_outcome_types_dim' AIRFLOW_CTX_EXECUTION_DATE='2023-11-18T00:00:00+00:00' AIRFLOW_CTX_TRY_NUMBER='1' AIRFLOW_CTX_DAG_RUN_ID='scheduled__2023-11-18T00:00:00+00:00'
[2023-11-19T20:43:56.606+0000] {taskinstance.py:1937} ERROR - Task failed with exception
Traceback (most recent call last):
  File "/home/airflow/.local/lib/python3.8/site-packages/sqlalchemy/engine/base.py", line 3371, in _wrap_pool_connect
    return fn()
  File "/home/airflow/.local/lib/python3.8/site-packages/sqlalchemy/pool/base.py", line 327, in connect
    return _ConnectionFairy._checkout(self)
  File "/home/airflow/.local/lib/python3.8/site-packages/sqlalchemy/pool/base.py", line 894, in _checkout
    fairy = _ConnectionRecord.checkout(pool)
  File "/home/airflow/.local/lib/python3.8/site-packages/sqlalchemy/pool/base.py", line 493, in checkout
    rec = pool._do_get()
  File "/home/airflow/.local/lib/python3.8/site-packages/sqlalchemy/pool/impl.py", line 146, in _do_get
    self._dec_overflow()
  File "/home/airflow/.local/lib/python3.8/site-packages/sqlalchemy/util/langhelpers.py", line 70, in __exit__
    compat.raise_(
  File "/home/airflow/.local/lib/python3.8/site-packages/sqlalchemy/util/compat.py", line 211, in raise_
    raise exception
  File "/home/airflow/.local/lib/python3.8/site-packages/sqlalchemy/pool/impl.py", line 143, in _do_get
    return self._create_connection()
  File "/home/airflow/.local/lib/python3.8/site-packages/sqlalchemy/pool/base.py", line 273, in _create_connection
    return _ConnectionRecord(self)
  File "/home/airflow/.local/lib/python3.8/site-packages/sqlalchemy/pool/base.py", line 388, in __init__
    self.__connect()
  File "/home/airflow/.local/lib/python3.8/site-packages/sqlalchemy/pool/base.py", line 691, in __connect
    pool.logger.debug("Error on connect(): %s", e)
  File "/home/airflow/.local/lib/python3.8/site-packages/sqlalchemy/util/langhelpers.py", line 70, in __exit__
    compat.raise_(
  File "/home/airflow/.local/lib/python3.8/site-packages/sqlalchemy/util/compat.py", line 211, in raise_
    raise exception
  File "/home/airflow/.local/lib/python3.8/site-packages/sqlalchemy/pool/base.py", line 686, in __connect
    self.dbapi_connection = connection = pool._invoke_creator(self)
  File "/home/airflow/.local/lib/python3.8/site-packages/sqlalchemy/engine/create.py", line 574, in connect
    return dialect.connect(*cargs, **cparams)
  File "/home/airflow/.local/lib/python3.8/site-packages/sqlalchemy/engine/default.py", line 598, in connect
    return self.dbapi.connect(*cargs, **cparams)
  File "/home/airflow/.local/lib/python3.8/site-packages/psycopg2/__init__.py", line 122, in connect
    conn = _connect(dsn, connection_factory=connection_factory, **kwasync)
psycopg2.OperationalError: connection to server at "database-1.cvwmlpdligxr.us-east-2.rds.amazonaws.com" (13.58.230.201), port 5432 failed: server closed the connection unexpectedly
	This probably means the server terminated abnormally
	before or while processing the request.


The above exception was the direct cause of the following exception:

Traceback (most recent call last):
  File "/home/airflow/.local/lib/python3.8/site-packages/airflow/operators/python.py", line 192, in execute
    return_value = self.execute_callable()
  File "/home/airflow/.local/lib/python3.8/site-packages/airflow/operators/python.py", line 209, in execute_callable
    return self.python_callable(*self.op_args, **self.op_kwargs)
  File "/opt/airflow/dags/etl_scripts/load.py", line 26, in load_data
    pd.read_csv(obj['Body'], index_col=0).to_sql(table_name, conn, if_exists="append", index=False, method=insert_on_conflict_nothing)
  File "/home/airflow/.local/lib/python3.8/site-packages/pandas/core/generic.py", line 2878, in to_sql
    return sql.to_sql(
  File "/home/airflow/.local/lib/python3.8/site-packages/pandas/io/sql.py", line 768, in to_sql
    with pandasSQL_builder(con, schema=schema, need_transaction=True) as pandas_sql:
  File "/home/airflow/.local/lib/python3.8/site-packages/pandas/io/sql.py", line 832, in pandasSQL_builder
    return SQLDatabase(con, schema, need_transaction)
  File "/home/airflow/.local/lib/python3.8/site-packages/pandas/io/sql.py", line 1539, in __init__
    con = self.exit_stack.enter_context(con.connect())
  File "/home/airflow/.local/lib/python3.8/site-packages/sqlalchemy/engine/base.py", line 3325, in connect
    return self._connection_cls(self, close_with_result=close_with_result)
  File "/home/airflow/.local/lib/python3.8/site-packages/sqlalchemy/engine/base.py", line 96, in __init__
    else engine.raw_connection()
  File "/home/airflow/.local/lib/python3.8/site-packages/sqlalchemy/engine/base.py", line 3404, in raw_connection
    return self._wrap_pool_connect(self.pool.connect, _connection)
  File "/home/airflow/.local/lib/python3.8/site-packages/sqlalchemy/engine/base.py", line 3374, in _wrap_pool_connect
    Connection._handle_dbapi_exception_noconnection(
  File "/home/airflow/.local/lib/python3.8/site-packages/sqlalchemy/engine/base.py", line 2208, in _handle_dbapi_exception_noconnection
    util.raise_(
  File "/home/airflow/.local/lib/python3.8/site-packages/sqlalchemy/util/compat.py", line 211, in raise_
    raise exception
  File "/home/airflow/.local/lib/python3.8/site-packages/sqlalchemy/engine/base.py", line 3371, in _wrap_pool_connect
    return fn()
  File "/home/airflow/.local/lib/python3.8/site-packages/sqlalchemy/pool/base.py", line 327, in connect
    return _ConnectionFairy._checkout(self)
  File "/home/airflow/.local/lib/python3.8/site-packages/sqlalchemy/pool/base.py", line 894, in _checkout
    fairy = _ConnectionRecord.checkout(pool)
  File "/home/airflow/.local/lib/python3.8/site-packages/sqlalchemy/pool/base.py", line 493, in checkout
    rec = pool._do_get()
  File "/home/airflow/.local/lib/python3.8/site-packages/sqlalchemy/pool/impl.py", line 146, in _do_get
    self._dec_overflow()
  File "/home/airflow/.local/lib/python3.8/site-packages/sqlalchemy/util/langhelpers.py", line 70, in __exit__
    compat.raise_(
  File "/home/airflow/.local/lib/python3.8/site-packages/sqlalchemy/util/compat.py", line 211, in raise_
    raise exception
  File "/home/airflow/.local/lib/python3.8/site-packages/sqlalchemy/pool/impl.py", line 143, in _do_get
    return self._create_connection()
  File "/home/airflow/.local/lib/python3.8/site-packages/sqlalchemy/pool/base.py", line 273, in _create_connection
    return _ConnectionRecord(self)
  File "/home/airflow/.local/lib/python3.8/site-packages/sqlalchemy/pool/base.py", line 388, in __init__
    self.__connect()
  File "/home/airflow/.local/lib/python3.8/site-packages/sqlalchemy/pool/base.py", line 691, in __connect
    pool.logger.debug("Error on connect(): %s", e)
  File "/home/airflow/.local/lib/python3.8/site-packages/sqlalchemy/util/langhelpers.py", line 70, in __exit__
    compat.raise_(
  File "/home/airflow/.local/lib/python3.8/site-packages/sqlalchemy/util/compat.py", line 211, in raise_
    raise exception
  File "/home/airflow/.local/lib/python3.8/site-packages/sqlalchemy/pool/base.py", line 686, in __connect
    self.dbapi_connection = connection = pool._invoke_creator(self)
  File "/home/airflow/.local/lib/python3.8/site-packages/sqlalchemy/engine/create.py", line 574, in connect
    return dialect.connect(*cargs, **cparams)
  File "/home/airflow/.local/lib/python3.8/site-packages/sqlalchemy/engine/default.py", line 598, in connect
    return self.dbapi.connect(*cargs, **cparams)
  File "/home/airflow/.local/lib/python3.8/site-packages/psycopg2/__init__.py", line 122, in connect
    conn = _connect(dsn, connection_factory=connection_factory, **kwasync)
sqlalchemy.exc.OperationalError: (psycopg2.OperationalError) connection to server at "database-1.cvwmlpdligxr.us-east-2.rds.amazonaws.com" (13.58.230.201), port 5432 failed: server closed the connection unexpectedly
	This probably means the server terminated abnormally
	before or while processing the request.

(Background on this error at: https://sqlalche.me/e/14/e3q8)
[2023-11-19T20:43:56.617+0000] {taskinstance.py:1400} INFO - Marking task as FAILED. dag_id=outcomes_dag, task_id=load_outcome_types_dim, execution_date=20231118T000000, start_date=20231119T204340, end_date=20231119T204356
[2023-11-19T20:43:56.624+0000] {standard_task_runner.py:104} ERROR - Failed to execute job 10 for task load_outcome_types_dim ((psycopg2.OperationalError) connection to server at "database-1.cvwmlpdligxr.us-east-2.rds.amazonaws.com" (13.58.230.201), port 5432 failed: server closed the connection unexpectedly
	This probably means the server terminated abnormally
	before or while processing the request.

(Background on this error at: https://sqlalche.me/e/14/e3q8); 104)
[2023-11-19T20:43:56.669+0000] {local_task_job_runner.py:228} INFO - Task exited with return code 1
[2023-11-19T20:47:20.451+0000] {taskinstance.py:1159} INFO - Dependencies all met for dep_context=non-requeueable deps ti=<TaskInstance: outcomes_dag.load_outcome_types_dim scheduled__2023-11-18T00:00:00+00:00 [queued]>
[2023-11-19T20:47:20.456+0000] {taskinstance.py:1159} INFO - Dependencies all met for dep_context=requeueable deps ti=<TaskInstance: outcomes_dag.load_outcome_types_dim scheduled__2023-11-18T00:00:00+00:00 [queued]>
[2023-11-19T20:47:20.456+0000] {taskinstance.py:1361} INFO - Starting attempt 1 of 1
[2023-11-19T20:47:20.466+0000] {taskinstance.py:1382} INFO - Executing <Task(PythonOperator): load_outcome_types_dim> on 2023-11-18 00:00:00+00:00
[2023-11-19T20:47:20.470+0000] {standard_task_runner.py:57} INFO - Started process 109 to run task
[2023-11-19T20:47:20.473+0000] {standard_task_runner.py:84} INFO - Running: ['***', 'tasks', 'run', 'outcomes_dag', 'load_outcome_types_dim', 'scheduled__2023-11-18T00:00:00+00:00', '--job-id', '11', '--raw', '--subdir', 'DAGS_FOLDER/outcomes_dag.py', '--cfg-path', '/tmp/tmpp8udk3z6']
[2023-11-19T20:47:20.475+0000] {standard_task_runner.py:85} INFO - Job 11: Subtask load_outcome_types_dim
[2023-11-19T20:47:20.510+0000] {task_command.py:416} INFO - Running <TaskInstance: outcomes_dag.load_outcome_types_dim scheduled__2023-11-18T00:00:00+00:00 [running]> on host 9cdfa5fb3a71
[2023-11-19T20:47:20.552+0000] {taskinstance.py:1662} INFO - Exporting env vars: AIRFLOW_CTX_DAG_OWNER='***' AIRFLOW_CTX_DAG_ID='outcomes_dag' AIRFLOW_CTX_TASK_ID='load_outcome_types_dim' AIRFLOW_CTX_EXECUTION_DATE='2023-11-18T00:00:00+00:00' AIRFLOW_CTX_TRY_NUMBER='1' AIRFLOW_CTX_DAG_RUN_ID='scheduled__2023-11-18T00:00:00+00:00'
[2023-11-19T20:47:36.516+0000] {taskinstance.py:1937} ERROR - Task failed with exception
Traceback (most recent call last):
  File "/home/airflow/.local/lib/python3.8/site-packages/sqlalchemy/engine/base.py", line 3371, in _wrap_pool_connect
    return fn()
  File "/home/airflow/.local/lib/python3.8/site-packages/sqlalchemy/pool/base.py", line 327, in connect
    return _ConnectionFairy._checkout(self)
  File "/home/airflow/.local/lib/python3.8/site-packages/sqlalchemy/pool/base.py", line 894, in _checkout
    fairy = _ConnectionRecord.checkout(pool)
  File "/home/airflow/.local/lib/python3.8/site-packages/sqlalchemy/pool/base.py", line 493, in checkout
    rec = pool._do_get()
  File "/home/airflow/.local/lib/python3.8/site-packages/sqlalchemy/pool/impl.py", line 146, in _do_get
    self._dec_overflow()
  File "/home/airflow/.local/lib/python3.8/site-packages/sqlalchemy/util/langhelpers.py", line 70, in __exit__
    compat.raise_(
  File "/home/airflow/.local/lib/python3.8/site-packages/sqlalchemy/util/compat.py", line 211, in raise_
    raise exception
  File "/home/airflow/.local/lib/python3.8/site-packages/sqlalchemy/pool/impl.py", line 143, in _do_get
    return self._create_connection()
  File "/home/airflow/.local/lib/python3.8/site-packages/sqlalchemy/pool/base.py", line 273, in _create_connection
    return _ConnectionRecord(self)
  File "/home/airflow/.local/lib/python3.8/site-packages/sqlalchemy/pool/base.py", line 388, in __init__
    self.__connect()
  File "/home/airflow/.local/lib/python3.8/site-packages/sqlalchemy/pool/base.py", line 691, in __connect
    pool.logger.debug("Error on connect(): %s", e)
  File "/home/airflow/.local/lib/python3.8/site-packages/sqlalchemy/util/langhelpers.py", line 70, in __exit__
    compat.raise_(
  File "/home/airflow/.local/lib/python3.8/site-packages/sqlalchemy/util/compat.py", line 211, in raise_
    raise exception
  File "/home/airflow/.local/lib/python3.8/site-packages/sqlalchemy/pool/base.py", line 686, in __connect
    self.dbapi_connection = connection = pool._invoke_creator(self)
  File "/home/airflow/.local/lib/python3.8/site-packages/sqlalchemy/engine/create.py", line 574, in connect
    return dialect.connect(*cargs, **cparams)
  File "/home/airflow/.local/lib/python3.8/site-packages/sqlalchemy/engine/default.py", line 598, in connect
    return self.dbapi.connect(*cargs, **cparams)
  File "/home/airflow/.local/lib/python3.8/site-packages/psycopg2/__init__.py", line 122, in connect
    conn = _connect(dsn, connection_factory=connection_factory, **kwasync)
psycopg2.OperationalError: connection to server at "database-1.cvwmlpdligxr.us-east-2.rds.amazonaws.com" (13.58.230.201), port 5432 failed: server closed the connection unexpectedly
	This probably means the server terminated abnormally
	before or while processing the request.


The above exception was the direct cause of the following exception:

Traceback (most recent call last):
  File "/home/airflow/.local/lib/python3.8/site-packages/airflow/operators/python.py", line 192, in execute
    return_value = self.execute_callable()
  File "/home/airflow/.local/lib/python3.8/site-packages/airflow/operators/python.py", line 209, in execute_callable
    return self.python_callable(*self.op_args, **self.op_kwargs)
  File "/opt/airflow/dags/etl_scripts/load.py", line 26, in load_data
    pd.read_csv(obj['Body'], index_col=0).to_sql(table_name, conn, if_exists="append", index=False, method=insert_on_conflict_nothing)
  File "/home/airflow/.local/lib/python3.8/site-packages/pandas/core/generic.py", line 2878, in to_sql
    return sql.to_sql(
  File "/home/airflow/.local/lib/python3.8/site-packages/pandas/io/sql.py", line 768, in to_sql
    with pandasSQL_builder(con, schema=schema, need_transaction=True) as pandas_sql:
  File "/home/airflow/.local/lib/python3.8/site-packages/pandas/io/sql.py", line 832, in pandasSQL_builder
    return SQLDatabase(con, schema, need_transaction)
  File "/home/airflow/.local/lib/python3.8/site-packages/pandas/io/sql.py", line 1539, in __init__
    con = self.exit_stack.enter_context(con.connect())
  File "/home/airflow/.local/lib/python3.8/site-packages/sqlalchemy/engine/base.py", line 3325, in connect
    return self._connection_cls(self, close_with_result=close_with_result)
  File "/home/airflow/.local/lib/python3.8/site-packages/sqlalchemy/engine/base.py", line 96, in __init__
    else engine.raw_connection()
  File "/home/airflow/.local/lib/python3.8/site-packages/sqlalchemy/engine/base.py", line 3404, in raw_connection
    return self._wrap_pool_connect(self.pool.connect, _connection)
  File "/home/airflow/.local/lib/python3.8/site-packages/sqlalchemy/engine/base.py", line 3374, in _wrap_pool_connect
    Connection._handle_dbapi_exception_noconnection(
  File "/home/airflow/.local/lib/python3.8/site-packages/sqlalchemy/engine/base.py", line 2208, in _handle_dbapi_exception_noconnection
    util.raise_(
  File "/home/airflow/.local/lib/python3.8/site-packages/sqlalchemy/util/compat.py", line 211, in raise_
    raise exception
  File "/home/airflow/.local/lib/python3.8/site-packages/sqlalchemy/engine/base.py", line 3371, in _wrap_pool_connect
    return fn()
  File "/home/airflow/.local/lib/python3.8/site-packages/sqlalchemy/pool/base.py", line 327, in connect
    return _ConnectionFairy._checkout(self)
  File "/home/airflow/.local/lib/python3.8/site-packages/sqlalchemy/pool/base.py", line 894, in _checkout
    fairy = _ConnectionRecord.checkout(pool)
  File "/home/airflow/.local/lib/python3.8/site-packages/sqlalchemy/pool/base.py", line 493, in checkout
    rec = pool._do_get()
  File "/home/airflow/.local/lib/python3.8/site-packages/sqlalchemy/pool/impl.py", line 146, in _do_get
    self._dec_overflow()
  File "/home/airflow/.local/lib/python3.8/site-packages/sqlalchemy/util/langhelpers.py", line 70, in __exit__
    compat.raise_(
  File "/home/airflow/.local/lib/python3.8/site-packages/sqlalchemy/util/compat.py", line 211, in raise_
    raise exception
  File "/home/airflow/.local/lib/python3.8/site-packages/sqlalchemy/pool/impl.py", line 143, in _do_get
    return self._create_connection()
  File "/home/airflow/.local/lib/python3.8/site-packages/sqlalchemy/pool/base.py", line 273, in _create_connection
    return _ConnectionRecord(self)
  File "/home/airflow/.local/lib/python3.8/site-packages/sqlalchemy/pool/base.py", line 388, in __init__
    self.__connect()
  File "/home/airflow/.local/lib/python3.8/site-packages/sqlalchemy/pool/base.py", line 691, in __connect
    pool.logger.debug("Error on connect(): %s", e)
  File "/home/airflow/.local/lib/python3.8/site-packages/sqlalchemy/util/langhelpers.py", line 70, in __exit__
    compat.raise_(
  File "/home/airflow/.local/lib/python3.8/site-packages/sqlalchemy/util/compat.py", line 211, in raise_
    raise exception
  File "/home/airflow/.local/lib/python3.8/site-packages/sqlalchemy/pool/base.py", line 686, in __connect
    self.dbapi_connection = connection = pool._invoke_creator(self)
  File "/home/airflow/.local/lib/python3.8/site-packages/sqlalchemy/engine/create.py", line 574, in connect
    return dialect.connect(*cargs, **cparams)
  File "/home/airflow/.local/lib/python3.8/site-packages/sqlalchemy/engine/default.py", line 598, in connect
    return self.dbapi.connect(*cargs, **cparams)
  File "/home/airflow/.local/lib/python3.8/site-packages/psycopg2/__init__.py", line 122, in connect
    conn = _connect(dsn, connection_factory=connection_factory, **kwasync)
sqlalchemy.exc.OperationalError: (psycopg2.OperationalError) connection to server at "database-1.cvwmlpdligxr.us-east-2.rds.amazonaws.com" (13.58.230.201), port 5432 failed: server closed the connection unexpectedly
	This probably means the server terminated abnormally
	before or while processing the request.

(Background on this error at: https://sqlalche.me/e/14/e3q8)
[2023-11-19T20:47:36.552+0000] {taskinstance.py:1400} INFO - Marking task as FAILED. dag_id=outcomes_dag, task_id=load_outcome_types_dim, execution_date=20231118T000000, start_date=20231119T204720, end_date=20231119T204736
[2023-11-19T20:47:36.566+0000] {standard_task_runner.py:104} ERROR - Failed to execute job 11 for task load_outcome_types_dim ((psycopg2.OperationalError) connection to server at "database-1.cvwmlpdligxr.us-east-2.rds.amazonaws.com" (13.58.230.201), port 5432 failed: server closed the connection unexpectedly
	This probably means the server terminated abnormally
	before or while processing the request.

(Background on this error at: https://sqlalche.me/e/14/e3q8); 109)
[2023-11-19T20:47:36.586+0000] {local_task_job_runner.py:228} INFO - Task exited with return code 1
[2023-11-19T21:07:56.043+0000] {taskinstance.py:1159} INFO - Dependencies all met for dep_context=non-requeueable deps ti=<TaskInstance: outcomes_dag.load_outcome_types_dim scheduled__2023-11-18T00:00:00+00:00 [queued]>
[2023-11-19T21:07:56.047+0000] {taskinstance.py:1159} INFO - Dependencies all met for dep_context=requeueable deps ti=<TaskInstance: outcomes_dag.load_outcome_types_dim scheduled__2023-11-18T00:00:00+00:00 [queued]>
[2023-11-19T21:07:56.047+0000] {taskinstance.py:1361} INFO - Starting attempt 1 of 1
[2023-11-19T21:07:56.053+0000] {taskinstance.py:1382} INFO - Executing <Task(PythonOperator): load_outcome_types_dim> on 2023-11-18 00:00:00+00:00
[2023-11-19T21:07:56.059+0000] {standard_task_runner.py:57} INFO - Started process 100 to run task
[2023-11-19T21:07:56.065+0000] {standard_task_runner.py:84} INFO - Running: ['***', 'tasks', 'run', 'outcomes_dag', 'load_outcome_types_dim', 'scheduled__2023-11-18T00:00:00+00:00', '--job-id', '10', '--raw', '--subdir', 'DAGS_FOLDER/outcomes_dag.py', '--cfg-path', '/tmp/tmpf0qealp_']
[2023-11-19T21:07:56.068+0000] {standard_task_runner.py:85} INFO - Job 10: Subtask load_outcome_types_dim
[2023-11-19T21:07:56.114+0000] {task_command.py:416} INFO - Running <TaskInstance: outcomes_dag.load_outcome_types_dim scheduled__2023-11-18T00:00:00+00:00 [running]> on host 39e21f8b1ec3
[2023-11-19T21:07:56.171+0000] {taskinstance.py:1662} INFO - Exporting env vars: AIRFLOW_CTX_DAG_OWNER='***' AIRFLOW_CTX_DAG_ID='outcomes_dag' AIRFLOW_CTX_TASK_ID='load_outcome_types_dim' AIRFLOW_CTX_EXECUTION_DATE='2023-11-18T00:00:00+00:00' AIRFLOW_CTX_TRY_NUMBER='1' AIRFLOW_CTX_DAG_RUN_ID='scheduled__2023-11-18T00:00:00+00:00'
[2023-11-19T21:07:56.695+0000] {taskinstance.py:1937} ERROR - Task failed with exception
Traceback (most recent call last):
  File "/home/airflow/.local/lib/python3.8/site-packages/sqlalchemy/engine/base.py", line 1910, in _execute_context
    self.dialect.do_execute(
  File "/home/airflow/.local/lib/python3.8/site-packages/sqlalchemy/engine/default.py", line 736, in do_execute
    cursor.execute(statement, parameters)
psycopg2.errors.NotNullViolation: null value in column "outcome_type" of relation "dim_outcome_types" violates not-null constraint
DETAIL:  Failing row contains (10, null).


The above exception was the direct cause of the following exception:

Traceback (most recent call last):
  File "/home/airflow/.local/lib/python3.8/site-packages/airflow/operators/python.py", line 192, in execute
    return_value = self.execute_callable()
  File "/home/airflow/.local/lib/python3.8/site-packages/airflow/operators/python.py", line 209, in execute_callable
    return self.python_callable(*self.op_args, **self.op_kwargs)
  File "/opt/airflow/dags/etl_scripts/load.py", line 26, in load_data
    pd.read_csv(obj['Body'], index_col=0).to_sql(table_name, conn, if_exists="append", index=False, method=insert_on_conflict_nothing)
  File "/home/airflow/.local/lib/python3.8/site-packages/pandas/core/generic.py", line 2878, in to_sql
    return sql.to_sql(
  File "/home/airflow/.local/lib/python3.8/site-packages/pandas/io/sql.py", line 769, in to_sql
    return pandas_sql.to_sql(
  File "/home/airflow/.local/lib/python3.8/site-packages/pandas/io/sql.py", line 1920, in to_sql
    total_inserted = sql_engine.insert_records(
  File "/home/airflow/.local/lib/python3.8/site-packages/pandas/io/sql.py", line 1470, in insert_records
    raise err
  File "/home/airflow/.local/lib/python3.8/site-packages/pandas/io/sql.py", line 1461, in insert_records
    return table.insert(chunksize=chunksize, method=method)
  File "/home/airflow/.local/lib/python3.8/site-packages/pandas/io/sql.py", line 1023, in insert
    num_inserted = exec_insert(conn, keys, chunk_iter)
  File "/opt/airflow/dags/etl_scripts/load.py", line 20, in insert_on_conflict_nothing
    result = conn.execute(stmt)
  File "/home/airflow/.local/lib/python3.8/site-packages/sqlalchemy/engine/base.py", line 1385, in execute
    return meth(self, multiparams, params, _EMPTY_EXECUTION_OPTS)
  File "/home/airflow/.local/lib/python3.8/site-packages/sqlalchemy/sql/elements.py", line 334, in _execute_on_connection
    return connection._execute_clauseelement(
  File "/home/airflow/.local/lib/python3.8/site-packages/sqlalchemy/engine/base.py", line 1577, in _execute_clauseelement
    ret = self._execute_context(
  File "/home/airflow/.local/lib/python3.8/site-packages/sqlalchemy/engine/base.py", line 1953, in _execute_context
    self._handle_dbapi_exception(
  File "/home/airflow/.local/lib/python3.8/site-packages/sqlalchemy/engine/base.py", line 2134, in _handle_dbapi_exception
    util.raise_(
  File "/home/airflow/.local/lib/python3.8/site-packages/sqlalchemy/util/compat.py", line 211, in raise_
    raise exception
  File "/home/airflow/.local/lib/python3.8/site-packages/sqlalchemy/engine/base.py", line 1910, in _execute_context
    self.dialect.do_execute(
  File "/home/airflow/.local/lib/python3.8/site-packages/sqlalchemy/engine/default.py", line 736, in do_execute
    cursor.execute(statement, parameters)
sqlalchemy.exc.IntegrityError: (psycopg2.errors.NotNullViolation) null value in column "outcome_type" of relation "dim_outcome_types" violates not-null constraint
DETAIL:  Failing row contains (10, null).

[SQL: INSERT INTO dim_outcome_types (outcome_type, outcome_type_id) VALUES (%(outcome_type_m0)s, %(outcome_type_id_m0)s), (%(outcome_type_m1)s, %(outcome_type_id_m1)s), (%(outcome_type_m2)s, %(outcome_type_id_m2)s), (%(outcome_type_m3)s, %(outcome_type_id_m3)s), (%(outcome_type_m4)s, %(outcome_type_id_m4)s), (%(outcome_type_m5)s, %(outcome_type_id_m5)s), (%(outcome_type_m6)s, %(outcome_type_id_m6)s), (%(outcome_type_m7)s, %(outcome_type_id_m7)s), (%(outcome_type_m8)s, %(outcome_type_id_m8)s), (%(outcome_type_m9)s, %(outcome_type_id_m9)s), (%(outcome_type_m10)s, %(outcome_type_id_m10)s) ON CONFLICT (outcome_type_id) DO NOTHING]
[parameters: {'outcome_type_m0': 'Rto-Adopt', 'outcome_type_id_m0': 1, 'outcome_type_m1': 'Adoption', 'outcome_type_id_m1': 2, 'outcome_type_m2': 'Euthanasia', 'outcome_type_id_m2': 3, 'outcome_type_m3': 'Transfer', 'outcome_type_id_m3': 4, 'outcome_type_m4': 'Return to Owner', 'outcome_type_id_m4': 5, 'outcome_type_m5': 'Died', 'outcome_type_id_m5': 6, 'outcome_type_m6': 'Disposal', 'outcome_type_id_m6': 7, 'outcome_type_m7': 'Missing', 'outcome_type_id_m7': 8, 'outcome_type_m8': 'Relocate', 'outcome_type_id_m8': 9, 'outcome_type_m9': None, 'outcome_type_id_m9': 10, 'outcome_type_m10': 'Stolen', 'outcome_type_id_m10': 11}]
(Background on this error at: https://sqlalche.me/e/14/gkpj)
[2023-11-19T21:07:56.722+0000] {taskinstance.py:1400} INFO - Marking task as FAILED. dag_id=outcomes_dag, task_id=load_outcome_types_dim, execution_date=20231118T000000, start_date=20231119T210756, end_date=20231119T210756
[2023-11-19T21:07:56.729+0000] {standard_task_runner.py:104} ERROR - Failed to execute job 10 for task load_outcome_types_dim ((psycopg2.errors.NotNullViolation) null value in column "outcome_type" of relation "dim_outcome_types" violates not-null constraint
DETAIL:  Failing row contains (10, null).

[SQL: INSERT INTO dim_outcome_types (outcome_type, outcome_type_id) VALUES (%(outcome_type_m0)s, %(outcome_type_id_m0)s), (%(outcome_type_m1)s, %(outcome_type_id_m1)s), (%(outcome_type_m2)s, %(outcome_type_id_m2)s), (%(outcome_type_m3)s, %(outcome_type_id_m3)s), (%(outcome_type_m4)s, %(outcome_type_id_m4)s), (%(outcome_type_m5)s, %(outcome_type_id_m5)s), (%(outcome_type_m6)s, %(outcome_type_id_m6)s), (%(outcome_type_m7)s, %(outcome_type_id_m7)s), (%(outcome_type_m8)s, %(outcome_type_id_m8)s), (%(outcome_type_m9)s, %(outcome_type_id_m9)s), (%(outcome_type_m10)s, %(outcome_type_id_m10)s) ON CONFLICT (outcome_type_id) DO NOTHING]
[parameters: {'outcome_type_m0': 'Rto-Adopt', 'outcome_type_id_m0': 1, 'outcome_type_m1': 'Adoption', 'outcome_type_id_m1': 2, 'outcome_type_m2': 'Euthanasia', 'outcome_type_id_m2': 3, 'outcome_type_m3': 'Transfer', 'outcome_type_id_m3': 4, 'outcome_type_m4': 'Return to Owner', 'outcome_type_id_m4': 5, 'outcome_type_m5': 'Died', 'outcome_type_id_m5': 6, 'outcome_type_m6': 'Disposal', 'outcome_type_id_m6': 7, 'outcome_type_m7': 'Missing', 'outcome_type_id_m7': 8, 'outcome_type_m8': 'Relocate', 'outcome_type_id_m8': 9, 'outcome_type_m9': None, 'outcome_type_id_m9': 10, 'outcome_type_m10': 'Stolen', 'outcome_type_id_m10': 11}]
(Background on this error at: https://sqlalche.me/e/14/gkpj); 100)
[2023-11-19T21:07:56.762+0000] {local_task_job_runner.py:228} INFO - Task exited with return code 1
[2023-11-19T21:11:48.032+0000] {taskinstance.py:1159} INFO - Dependencies all met for dep_context=non-requeueable deps ti=<TaskInstance: outcomes_dag.load_outcome_types_dim scheduled__2023-11-18T00:00:00+00:00 [queued]>
[2023-11-19T21:11:48.046+0000] {taskinstance.py:1159} INFO - Dependencies all met for dep_context=requeueable deps ti=<TaskInstance: outcomes_dag.load_outcome_types_dim scheduled__2023-11-18T00:00:00+00:00 [queued]>
[2023-11-19T21:11:48.047+0000] {taskinstance.py:1361} INFO - Starting attempt 1 of 1
[2023-11-19T21:11:48.053+0000] {taskinstance.py:1382} INFO - Executing <Task(PythonOperator): load_outcome_types_dim> on 2023-11-18 00:00:00+00:00
[2023-11-19T21:11:48.058+0000] {standard_task_runner.py:57} INFO - Started process 120 to run task
[2023-11-19T21:11:48.070+0000] {standard_task_runner.py:84} INFO - Running: ['***', 'tasks', 'run', 'outcomes_dag', 'load_outcome_types_dim', 'scheduled__2023-11-18T00:00:00+00:00', '--job-id', '9', '--raw', '--subdir', 'DAGS_FOLDER/outcomes_dag.py', '--cfg-path', '/tmp/tmpzbgidlpq']
[2023-11-19T21:11:48.083+0000] {standard_task_runner.py:85} INFO - Job 9: Subtask load_outcome_types_dim
[2023-11-19T21:11:48.185+0000] {task_command.py:416} INFO - Running <TaskInstance: outcomes_dag.load_outcome_types_dim scheduled__2023-11-18T00:00:00+00:00 [running]> on host 0aa87954f8d2
[2023-11-19T21:11:48.312+0000] {taskinstance.py:1662} INFO - Exporting env vars: AIRFLOW_CTX_DAG_OWNER='***' AIRFLOW_CTX_DAG_ID='outcomes_dag' AIRFLOW_CTX_TASK_ID='load_outcome_types_dim' AIRFLOW_CTX_EXECUTION_DATE='2023-11-18T00:00:00+00:00' AIRFLOW_CTX_TRY_NUMBER='1' AIRFLOW_CTX_DAG_RUN_ID='scheduled__2023-11-18T00:00:00+00:00'
[2023-11-19T21:11:48.841+0000] {taskinstance.py:1937} ERROR - Task failed with exception
Traceback (most recent call last):
  File "/home/airflow/.local/lib/python3.8/site-packages/sqlalchemy/engine/base.py", line 1910, in _execute_context
    self.dialect.do_execute(
  File "/home/airflow/.local/lib/python3.8/site-packages/sqlalchemy/engine/default.py", line 736, in do_execute
    cursor.execute(statement, parameters)
psycopg2.errors.NotNullViolation: null value in column "outcome_type" of relation "dim_outcome_types" violates not-null constraint
DETAIL:  Failing row contains (10, null).


The above exception was the direct cause of the following exception:

Traceback (most recent call last):
  File "/home/airflow/.local/lib/python3.8/site-packages/airflow/operators/python.py", line 192, in execute
    return_value = self.execute_callable()
  File "/home/airflow/.local/lib/python3.8/site-packages/airflow/operators/python.py", line 209, in execute_callable
    return self.python_callable(*self.op_args, **self.op_kwargs)
  File "/opt/airflow/dags/etl_scripts/load.py", line 26, in load_data
    pd.read_csv(obj['Body'], index_col=0).to_sql(table_name, conn, if_exists="append", index=False, method=insert_on_conflict_nothing)
  File "/home/airflow/.local/lib/python3.8/site-packages/pandas/core/generic.py", line 2878, in to_sql
    return sql.to_sql(
  File "/home/airflow/.local/lib/python3.8/site-packages/pandas/io/sql.py", line 769, in to_sql
    return pandas_sql.to_sql(
  File "/home/airflow/.local/lib/python3.8/site-packages/pandas/io/sql.py", line 1920, in to_sql
    total_inserted = sql_engine.insert_records(
  File "/home/airflow/.local/lib/python3.8/site-packages/pandas/io/sql.py", line 1470, in insert_records
    raise err
  File "/home/airflow/.local/lib/python3.8/site-packages/pandas/io/sql.py", line 1461, in insert_records
    return table.insert(chunksize=chunksize, method=method)
  File "/home/airflow/.local/lib/python3.8/site-packages/pandas/io/sql.py", line 1023, in insert
    num_inserted = exec_insert(conn, keys, chunk_iter)
  File "/opt/airflow/dags/etl_scripts/load.py", line 20, in insert_on_conflict_nothing
    result = conn.execute(stmt)
  File "/home/airflow/.local/lib/python3.8/site-packages/sqlalchemy/engine/base.py", line 1385, in execute
    return meth(self, multiparams, params, _EMPTY_EXECUTION_OPTS)
  File "/home/airflow/.local/lib/python3.8/site-packages/sqlalchemy/sql/elements.py", line 334, in _execute_on_connection
    return connection._execute_clauseelement(
  File "/home/airflow/.local/lib/python3.8/site-packages/sqlalchemy/engine/base.py", line 1577, in _execute_clauseelement
    ret = self._execute_context(
  File "/home/airflow/.local/lib/python3.8/site-packages/sqlalchemy/engine/base.py", line 1953, in _execute_context
    self._handle_dbapi_exception(
  File "/home/airflow/.local/lib/python3.8/site-packages/sqlalchemy/engine/base.py", line 2134, in _handle_dbapi_exception
    util.raise_(
  File "/home/airflow/.local/lib/python3.8/site-packages/sqlalchemy/util/compat.py", line 211, in raise_
    raise exception
  File "/home/airflow/.local/lib/python3.8/site-packages/sqlalchemy/engine/base.py", line 1910, in _execute_context
    self.dialect.do_execute(
  File "/home/airflow/.local/lib/python3.8/site-packages/sqlalchemy/engine/default.py", line 736, in do_execute
    cursor.execute(statement, parameters)
sqlalchemy.exc.IntegrityError: (psycopg2.errors.NotNullViolation) null value in column "outcome_type" of relation "dim_outcome_types" violates not-null constraint
DETAIL:  Failing row contains (10, null).

[SQL: INSERT INTO dim_outcome_types (outcome_type, outcome_type_id) VALUES (%(outcome_type_m0)s, %(outcome_type_id_m0)s), (%(outcome_type_m1)s, %(outcome_type_id_m1)s), (%(outcome_type_m2)s, %(outcome_type_id_m2)s), (%(outcome_type_m3)s, %(outcome_type_id_m3)s), (%(outcome_type_m4)s, %(outcome_type_id_m4)s), (%(outcome_type_m5)s, %(outcome_type_id_m5)s), (%(outcome_type_m6)s, %(outcome_type_id_m6)s), (%(outcome_type_m7)s, %(outcome_type_id_m7)s), (%(outcome_type_m8)s, %(outcome_type_id_m8)s), (%(outcome_type_m9)s, %(outcome_type_id_m9)s), (%(outcome_type_m10)s, %(outcome_type_id_m10)s) ON CONFLICT (outcome_type_id) DO NOTHING]
[parameters: {'outcome_type_m0': 'Rto-Adopt', 'outcome_type_id_m0': 1, 'outcome_type_m1': 'Adoption', 'outcome_type_id_m1': 2, 'outcome_type_m2': 'Euthanasia', 'outcome_type_id_m2': 3, 'outcome_type_m3': 'Transfer', 'outcome_type_id_m3': 4, 'outcome_type_m4': 'Return to Owner', 'outcome_type_id_m4': 5, 'outcome_type_m5': 'Died', 'outcome_type_id_m5': 6, 'outcome_type_m6': 'Disposal', 'outcome_type_id_m6': 7, 'outcome_type_m7': 'Missing', 'outcome_type_id_m7': 8, 'outcome_type_m8': 'Relocate', 'outcome_type_id_m8': 9, 'outcome_type_m9': None, 'outcome_type_id_m9': 10, 'outcome_type_m10': 'Stolen', 'outcome_type_id_m10': 11}]
(Background on this error at: https://sqlalche.me/e/14/gkpj)
[2023-11-19T21:11:48.859+0000] {taskinstance.py:1400} INFO - Marking task as FAILED. dag_id=outcomes_dag, task_id=load_outcome_types_dim, execution_date=20231118T000000, start_date=20231119T211148, end_date=20231119T211148
[2023-11-19T21:11:48.865+0000] {standard_task_runner.py:104} ERROR - Failed to execute job 9 for task load_outcome_types_dim ((psycopg2.errors.NotNullViolation) null value in column "outcome_type" of relation "dim_outcome_types" violates not-null constraint
DETAIL:  Failing row contains (10, null).

[SQL: INSERT INTO dim_outcome_types (outcome_type, outcome_type_id) VALUES (%(outcome_type_m0)s, %(outcome_type_id_m0)s), (%(outcome_type_m1)s, %(outcome_type_id_m1)s), (%(outcome_type_m2)s, %(outcome_type_id_m2)s), (%(outcome_type_m3)s, %(outcome_type_id_m3)s), (%(outcome_type_m4)s, %(outcome_type_id_m4)s), (%(outcome_type_m5)s, %(outcome_type_id_m5)s), (%(outcome_type_m6)s, %(outcome_type_id_m6)s), (%(outcome_type_m7)s, %(outcome_type_id_m7)s), (%(outcome_type_m8)s, %(outcome_type_id_m8)s), (%(outcome_type_m9)s, %(outcome_type_id_m9)s), (%(outcome_type_m10)s, %(outcome_type_id_m10)s) ON CONFLICT (outcome_type_id) DO NOTHING]
[parameters: {'outcome_type_m0': 'Rto-Adopt', 'outcome_type_id_m0': 1, 'outcome_type_m1': 'Adoption', 'outcome_type_id_m1': 2, 'outcome_type_m2': 'Euthanasia', 'outcome_type_id_m2': 3, 'outcome_type_m3': 'Transfer', 'outcome_type_id_m3': 4, 'outcome_type_m4': 'Return to Owner', 'outcome_type_id_m4': 5, 'outcome_type_m5': 'Died', 'outcome_type_id_m5': 6, 'outcome_type_m6': 'Disposal', 'outcome_type_id_m6': 7, 'outcome_type_m7': 'Missing', 'outcome_type_id_m7': 8, 'outcome_type_m8': 'Relocate', 'outcome_type_id_m8': 9, 'outcome_type_m9': None, 'outcome_type_id_m9': 10, 'outcome_type_m10': 'Stolen', 'outcome_type_id_m10': 11}]
(Background on this error at: https://sqlalche.me/e/14/gkpj); 120)
[2023-11-19T21:11:48.892+0000] {local_task_job_runner.py:228} INFO - Task exited with return code 1
[2023-11-19T21:15:30.920+0000] {taskinstance.py:1159} INFO - Dependencies all met for dep_context=non-requeueable deps ti=<TaskInstance: outcomes_dag.load_outcome_types_dim scheduled__2023-11-18T00:00:00+00:00 [queued]>
[2023-11-19T21:15:30.926+0000] {taskinstance.py:1159} INFO - Dependencies all met for dep_context=requeueable deps ti=<TaskInstance: outcomes_dag.load_outcome_types_dim scheduled__2023-11-18T00:00:00+00:00 [queued]>
[2023-11-19T21:15:30.926+0000] {taskinstance.py:1361} INFO - Starting attempt 1 of 1
[2023-11-19T21:15:30.932+0000] {taskinstance.py:1382} INFO - Executing <Task(PythonOperator): load_outcome_types_dim> on 2023-11-18 00:00:00+00:00
[2023-11-19T21:15:30.935+0000] {standard_task_runner.py:57} INFO - Started process 117 to run task
[2023-11-19T21:15:30.939+0000] {standard_task_runner.py:84} INFO - Running: ['***', 'tasks', 'run', 'outcomes_dag', 'load_outcome_types_dim', 'scheduled__2023-11-18T00:00:00+00:00', '--job-id', '14', '--raw', '--subdir', 'DAGS_FOLDER/outcomes_dag.py', '--cfg-path', '/tmp/tmpkolszvy9']
[2023-11-19T21:15:30.941+0000] {standard_task_runner.py:85} INFO - Job 14: Subtask load_outcome_types_dim
[2023-11-19T21:15:30.984+0000] {task_command.py:416} INFO - Running <TaskInstance: outcomes_dag.load_outcome_types_dim scheduled__2023-11-18T00:00:00+00:00 [running]> on host 5d17f892a68d
[2023-11-19T21:15:31.028+0000] {taskinstance.py:1662} INFO - Exporting env vars: AIRFLOW_CTX_DAG_OWNER='***' AIRFLOW_CTX_DAG_ID='outcomes_dag' AIRFLOW_CTX_TASK_ID='load_outcome_types_dim' AIRFLOW_CTX_EXECUTION_DATE='2023-11-18T00:00:00+00:00' AIRFLOW_CTX_TRY_NUMBER='1' AIRFLOW_CTX_DAG_RUN_ID='scheduled__2023-11-18T00:00:00+00:00'
[2023-11-19T21:15:31.538+0000] {taskinstance.py:1937} ERROR - Task failed with exception
Traceback (most recent call last):
  File "/home/airflow/.local/lib/python3.8/site-packages/sqlalchemy/engine/base.py", line 1910, in _execute_context
    self.dialect.do_execute(
  File "/home/airflow/.local/lib/python3.8/site-packages/sqlalchemy/engine/default.py", line 736, in do_execute
    cursor.execute(statement, parameters)
psycopg2.errors.NotNullViolation: null value in column "outcome_type" of relation "dim_outcome_types" violates not-null constraint
DETAIL:  Failing row contains (10, null).


The above exception was the direct cause of the following exception:

Traceback (most recent call last):
  File "/home/airflow/.local/lib/python3.8/site-packages/airflow/operators/python.py", line 192, in execute
    return_value = self.execute_callable()
  File "/home/airflow/.local/lib/python3.8/site-packages/airflow/operators/python.py", line 209, in execute_callable
    return self.python_callable(*self.op_args, **self.op_kwargs)
  File "/opt/airflow/dags/etl_scripts/load.py", line 23, in load_data
    pd.read_csv(obj['Body'], index_col=0).to_sql(table_name, conn, if_exists="append", index=False, method=insert_on_conflict_nothing)
  File "/home/airflow/.local/lib/python3.8/site-packages/pandas/core/generic.py", line 2878, in to_sql
    return sql.to_sql(
  File "/home/airflow/.local/lib/python3.8/site-packages/pandas/io/sql.py", line 769, in to_sql
    return pandas_sql.to_sql(
  File "/home/airflow/.local/lib/python3.8/site-packages/pandas/io/sql.py", line 1920, in to_sql
    total_inserted = sql_engine.insert_records(
  File "/home/airflow/.local/lib/python3.8/site-packages/pandas/io/sql.py", line 1470, in insert_records
    raise err
  File "/home/airflow/.local/lib/python3.8/site-packages/pandas/io/sql.py", line 1461, in insert_records
    return table.insert(chunksize=chunksize, method=method)
  File "/home/airflow/.local/lib/python3.8/site-packages/pandas/io/sql.py", line 1023, in insert
    num_inserted = exec_insert(conn, keys, chunk_iter)
  File "/opt/airflow/dags/etl_scripts/load.py", line 17, in insert_on_conflict_nothing
    result = conn.execute(stmt)
  File "/home/airflow/.local/lib/python3.8/site-packages/sqlalchemy/engine/base.py", line 1385, in execute
    return meth(self, multiparams, params, _EMPTY_EXECUTION_OPTS)
  File "/home/airflow/.local/lib/python3.8/site-packages/sqlalchemy/sql/elements.py", line 334, in _execute_on_connection
    return connection._execute_clauseelement(
  File "/home/airflow/.local/lib/python3.8/site-packages/sqlalchemy/engine/base.py", line 1577, in _execute_clauseelement
    ret = self._execute_context(
  File "/home/airflow/.local/lib/python3.8/site-packages/sqlalchemy/engine/base.py", line 1953, in _execute_context
    self._handle_dbapi_exception(
  File "/home/airflow/.local/lib/python3.8/site-packages/sqlalchemy/engine/base.py", line 2134, in _handle_dbapi_exception
    util.raise_(
  File "/home/airflow/.local/lib/python3.8/site-packages/sqlalchemy/util/compat.py", line 211, in raise_
    raise exception
  File "/home/airflow/.local/lib/python3.8/site-packages/sqlalchemy/engine/base.py", line 1910, in _execute_context
    self.dialect.do_execute(
  File "/home/airflow/.local/lib/python3.8/site-packages/sqlalchemy/engine/default.py", line 736, in do_execute
    cursor.execute(statement, parameters)
sqlalchemy.exc.IntegrityError: (psycopg2.errors.NotNullViolation) null value in column "outcome_type" of relation "dim_outcome_types" violates not-null constraint
DETAIL:  Failing row contains (10, null).

[SQL: INSERT INTO dim_outcome_types (outcome_type, outcome_type_id) VALUES (%(outcome_type_m0)s, %(outcome_type_id_m0)s), (%(outcome_type_m1)s, %(outcome_type_id_m1)s), (%(outcome_type_m2)s, %(outcome_type_id_m2)s), (%(outcome_type_m3)s, %(outcome_type_id_m3)s), (%(outcome_type_m4)s, %(outcome_type_id_m4)s), (%(outcome_type_m5)s, %(outcome_type_id_m5)s), (%(outcome_type_m6)s, %(outcome_type_id_m6)s), (%(outcome_type_m7)s, %(outcome_type_id_m7)s), (%(outcome_type_m8)s, %(outcome_type_id_m8)s), (%(outcome_type_m9)s, %(outcome_type_id_m9)s), (%(outcome_type_m10)s, %(outcome_type_id_m10)s) ON CONFLICT (outcome_type_id) DO NOTHING]
[parameters: {'outcome_type_m0': 'Rto-Adopt', 'outcome_type_id_m0': 1, 'outcome_type_m1': 'Adoption', 'outcome_type_id_m1': 2, 'outcome_type_m2': 'Euthanasia', 'outcome_type_id_m2': 3, 'outcome_type_m3': 'Transfer', 'outcome_type_id_m3': 4, 'outcome_type_m4': 'Return to Owner', 'outcome_type_id_m4': 5, 'outcome_type_m5': 'Died', 'outcome_type_id_m5': 6, 'outcome_type_m6': 'Disposal', 'outcome_type_id_m6': 7, 'outcome_type_m7': 'Missing', 'outcome_type_id_m7': 8, 'outcome_type_m8': 'Relocate', 'outcome_type_id_m8': 9, 'outcome_type_m9': None, 'outcome_type_id_m9': 10, 'outcome_type_m10': 'Stolen', 'outcome_type_id_m10': 11}]
(Background on this error at: https://sqlalche.me/e/14/gkpj)
[2023-11-19T21:15:31.553+0000] {taskinstance.py:1400} INFO - Marking task as FAILED. dag_id=outcomes_dag, task_id=load_outcome_types_dim, execution_date=20231118T000000, start_date=20231119T211530, end_date=20231119T211531
[2023-11-19T21:15:31.565+0000] {standard_task_runner.py:104} ERROR - Failed to execute job 14 for task load_outcome_types_dim ((psycopg2.errors.NotNullViolation) null value in column "outcome_type" of relation "dim_outcome_types" violates not-null constraint
DETAIL:  Failing row contains (10, null).

[SQL: INSERT INTO dim_outcome_types (outcome_type, outcome_type_id) VALUES (%(outcome_type_m0)s, %(outcome_type_id_m0)s), (%(outcome_type_m1)s, %(outcome_type_id_m1)s), (%(outcome_type_m2)s, %(outcome_type_id_m2)s), (%(outcome_type_m3)s, %(outcome_type_id_m3)s), (%(outcome_type_m4)s, %(outcome_type_id_m4)s), (%(outcome_type_m5)s, %(outcome_type_id_m5)s), (%(outcome_type_m6)s, %(outcome_type_id_m6)s), (%(outcome_type_m7)s, %(outcome_type_id_m7)s), (%(outcome_type_m8)s, %(outcome_type_id_m8)s), (%(outcome_type_m9)s, %(outcome_type_id_m9)s), (%(outcome_type_m10)s, %(outcome_type_id_m10)s) ON CONFLICT (outcome_type_id) DO NOTHING]
[parameters: {'outcome_type_m0': 'Rto-Adopt', 'outcome_type_id_m0': 1, 'outcome_type_m1': 'Adoption', 'outcome_type_id_m1': 2, 'outcome_type_m2': 'Euthanasia', 'outcome_type_id_m2': 3, 'outcome_type_m3': 'Transfer', 'outcome_type_id_m3': 4, 'outcome_type_m4': 'Return to Owner', 'outcome_type_id_m4': 5, 'outcome_type_m5': 'Died', 'outcome_type_id_m5': 6, 'outcome_type_m6': 'Disposal', 'outcome_type_id_m6': 7, 'outcome_type_m7': 'Missing', 'outcome_type_id_m7': 8, 'outcome_type_m8': 'Relocate', 'outcome_type_id_m8': 9, 'outcome_type_m9': None, 'outcome_type_id_m9': 10, 'outcome_type_m10': 'Stolen', 'outcome_type_id_m10': 11}]
(Background on this error at: https://sqlalche.me/e/14/gkpj); 117)
[2023-11-19T21:15:31.596+0000] {local_task_job_runner.py:228} INFO - Task exited with return code 1
[2023-11-19T21:20:54.076+0000] {taskinstance.py:1159} INFO - Dependencies all met for dep_context=non-requeueable deps ti=<TaskInstance: outcomes_dag.load_outcome_types_dim scheduled__2023-11-18T00:00:00+00:00 [queued]>
[2023-11-19T21:20:54.084+0000] {taskinstance.py:1159} INFO - Dependencies all met for dep_context=requeueable deps ti=<TaskInstance: outcomes_dag.load_outcome_types_dim scheduled__2023-11-18T00:00:00+00:00 [queued]>
[2023-11-19T21:20:54.085+0000] {taskinstance.py:1361} INFO - Starting attempt 1 of 1
[2023-11-19T21:20:54.092+0000] {taskinstance.py:1382} INFO - Executing <Task(PythonOperator): load_outcome_types_dim> on 2023-11-18 00:00:00+00:00
[2023-11-19T21:20:54.098+0000] {standard_task_runner.py:57} INFO - Started process 116 to run task
[2023-11-19T21:20:54.102+0000] {standard_task_runner.py:84} INFO - Running: ['***', 'tasks', 'run', 'outcomes_dag', 'load_outcome_types_dim', 'scheduled__2023-11-18T00:00:00+00:00', '--job-id', '14', '--raw', '--subdir', 'DAGS_FOLDER/outcomes_dag.py', '--cfg-path', '/tmp/tmpc2leps7x']
[2023-11-19T21:20:54.105+0000] {standard_task_runner.py:85} INFO - Job 14: Subtask load_outcome_types_dim
[2023-11-19T21:20:54.136+0000] {task_command.py:416} INFO - Running <TaskInstance: outcomes_dag.load_outcome_types_dim scheduled__2023-11-18T00:00:00+00:00 [running]> on host 33e2059faeb6
[2023-11-19T21:20:54.176+0000] {taskinstance.py:1662} INFO - Exporting env vars: AIRFLOW_CTX_DAG_OWNER='***' AIRFLOW_CTX_DAG_ID='outcomes_dag' AIRFLOW_CTX_TASK_ID='load_outcome_types_dim' AIRFLOW_CTX_EXECUTION_DATE='2023-11-18T00:00:00+00:00' AIRFLOW_CTX_TRY_NUMBER='1' AIRFLOW_CTX_DAG_RUN_ID='scheduled__2023-11-18T00:00:00+00:00'
[2023-11-19T21:20:54.638+0000] {taskinstance.py:1937} ERROR - Task failed with exception
Traceback (most recent call last):
  File "/home/airflow/.local/lib/python3.8/site-packages/sqlalchemy/engine/base.py", line 1910, in _execute_context
    self.dialect.do_execute(
  File "/home/airflow/.local/lib/python3.8/site-packages/sqlalchemy/engine/default.py", line 736, in do_execute
    cursor.execute(statement, parameters)
psycopg2.errors.NotNullViolation: null value in column "outcome_type" of relation "dim_outcome_types" violates not-null constraint
DETAIL:  Failing row contains (10, null).


The above exception was the direct cause of the following exception:

Traceback (most recent call last):
  File "/home/airflow/.local/lib/python3.8/site-packages/airflow/operators/python.py", line 192, in execute
    return_value = self.execute_callable()
  File "/home/airflow/.local/lib/python3.8/site-packages/airflow/operators/python.py", line 209, in execute_callable
    return self.python_callable(*self.op_args, **self.op_kwargs)
  File "/opt/airflow/dags/etl_scripts/load.py", line 23, in load_data
    pd.read_csv(obj['Body'], index_col=0).to_sql(table_name, conn, if_exists="append", index=False, method=insert_on_conflict_nothing)
  File "/home/airflow/.local/lib/python3.8/site-packages/pandas/core/generic.py", line 2878, in to_sql
    return sql.to_sql(
  File "/home/airflow/.local/lib/python3.8/site-packages/pandas/io/sql.py", line 769, in to_sql
    return pandas_sql.to_sql(
  File "/home/airflow/.local/lib/python3.8/site-packages/pandas/io/sql.py", line 1920, in to_sql
    total_inserted = sql_engine.insert_records(
  File "/home/airflow/.local/lib/python3.8/site-packages/pandas/io/sql.py", line 1470, in insert_records
    raise err
  File "/home/airflow/.local/lib/python3.8/site-packages/pandas/io/sql.py", line 1461, in insert_records
    return table.insert(chunksize=chunksize, method=method)
  File "/home/airflow/.local/lib/python3.8/site-packages/pandas/io/sql.py", line 1023, in insert
    num_inserted = exec_insert(conn, keys, chunk_iter)
  File "/opt/airflow/dags/etl_scripts/load.py", line 17, in insert_on_conflict_nothing
    result = conn.execute(stmt)
  File "/home/airflow/.local/lib/python3.8/site-packages/sqlalchemy/engine/base.py", line 1385, in execute
    return meth(self, multiparams, params, _EMPTY_EXECUTION_OPTS)
  File "/home/airflow/.local/lib/python3.8/site-packages/sqlalchemy/sql/elements.py", line 334, in _execute_on_connection
    return connection._execute_clauseelement(
  File "/home/airflow/.local/lib/python3.8/site-packages/sqlalchemy/engine/base.py", line 1577, in _execute_clauseelement
    ret = self._execute_context(
  File "/home/airflow/.local/lib/python3.8/site-packages/sqlalchemy/engine/base.py", line 1953, in _execute_context
    self._handle_dbapi_exception(
  File "/home/airflow/.local/lib/python3.8/site-packages/sqlalchemy/engine/base.py", line 2134, in _handle_dbapi_exception
    util.raise_(
  File "/home/airflow/.local/lib/python3.8/site-packages/sqlalchemy/util/compat.py", line 211, in raise_
    raise exception
  File "/home/airflow/.local/lib/python3.8/site-packages/sqlalchemy/engine/base.py", line 1910, in _execute_context
    self.dialect.do_execute(
  File "/home/airflow/.local/lib/python3.8/site-packages/sqlalchemy/engine/default.py", line 736, in do_execute
    cursor.execute(statement, parameters)
sqlalchemy.exc.IntegrityError: (psycopg2.errors.NotNullViolation) null value in column "outcome_type" of relation "dim_outcome_types" violates not-null constraint
DETAIL:  Failing row contains (10, null).

[SQL: INSERT INTO dim_outcome_types (outcome_type, outcome_type_id) VALUES (%(outcome_type_m0)s, %(outcome_type_id_m0)s), (%(outcome_type_m1)s, %(outcome_type_id_m1)s), (%(outcome_type_m2)s, %(outcome_type_id_m2)s), (%(outcome_type_m3)s, %(outcome_type_id_m3)s), (%(outcome_type_m4)s, %(outcome_type_id_m4)s), (%(outcome_type_m5)s, %(outcome_type_id_m5)s), (%(outcome_type_m6)s, %(outcome_type_id_m6)s), (%(outcome_type_m7)s, %(outcome_type_id_m7)s), (%(outcome_type_m8)s, %(outcome_type_id_m8)s), (%(outcome_type_m9)s, %(outcome_type_id_m9)s), (%(outcome_type_m10)s, %(outcome_type_id_m10)s) ON CONFLICT (outcome_type_id) DO NOTHING]
[parameters: {'outcome_type_m0': 'Rto-Adopt', 'outcome_type_id_m0': 1, 'outcome_type_m1': 'Adoption', 'outcome_type_id_m1': 2, 'outcome_type_m2': 'Euthanasia', 'outcome_type_id_m2': 3, 'outcome_type_m3': 'Transfer', 'outcome_type_id_m3': 4, 'outcome_type_m4': 'Return to Owner', 'outcome_type_id_m4': 5, 'outcome_type_m5': 'Died', 'outcome_type_id_m5': 6, 'outcome_type_m6': 'Disposal', 'outcome_type_id_m6': 7, 'outcome_type_m7': 'Missing', 'outcome_type_id_m7': 8, 'outcome_type_m8': 'Relocate', 'outcome_type_id_m8': 9, 'outcome_type_m9': None, 'outcome_type_id_m9': 10, 'outcome_type_m10': 'Stolen', 'outcome_type_id_m10': 11}]
(Background on this error at: https://sqlalche.me/e/14/gkpj)
[2023-11-19T21:20:54.650+0000] {taskinstance.py:1400} INFO - Marking task as FAILED. dag_id=outcomes_dag, task_id=load_outcome_types_dim, execution_date=20231118T000000, start_date=20231119T212054, end_date=20231119T212054
[2023-11-19T21:20:54.659+0000] {standard_task_runner.py:104} ERROR - Failed to execute job 14 for task load_outcome_types_dim ((psycopg2.errors.NotNullViolation) null value in column "outcome_type" of relation "dim_outcome_types" violates not-null constraint
DETAIL:  Failing row contains (10, null).

[SQL: INSERT INTO dim_outcome_types (outcome_type, outcome_type_id) VALUES (%(outcome_type_m0)s, %(outcome_type_id_m0)s), (%(outcome_type_m1)s, %(outcome_type_id_m1)s), (%(outcome_type_m2)s, %(outcome_type_id_m2)s), (%(outcome_type_m3)s, %(outcome_type_id_m3)s), (%(outcome_type_m4)s, %(outcome_type_id_m4)s), (%(outcome_type_m5)s, %(outcome_type_id_m5)s), (%(outcome_type_m6)s, %(outcome_type_id_m6)s), (%(outcome_type_m7)s, %(outcome_type_id_m7)s), (%(outcome_type_m8)s, %(outcome_type_id_m8)s), (%(outcome_type_m9)s, %(outcome_type_id_m9)s), (%(outcome_type_m10)s, %(outcome_type_id_m10)s) ON CONFLICT (outcome_type_id) DO NOTHING]
[parameters: {'outcome_type_m0': 'Rto-Adopt', 'outcome_type_id_m0': 1, 'outcome_type_m1': 'Adoption', 'outcome_type_id_m1': 2, 'outcome_type_m2': 'Euthanasia', 'outcome_type_id_m2': 3, 'outcome_type_m3': 'Transfer', 'outcome_type_id_m3': 4, 'outcome_type_m4': 'Return to Owner', 'outcome_type_id_m4': 5, 'outcome_type_m5': 'Died', 'outcome_type_id_m5': 6, 'outcome_type_m6': 'Disposal', 'outcome_type_id_m6': 7, 'outcome_type_m7': 'Missing', 'outcome_type_id_m7': 8, 'outcome_type_m8': 'Relocate', 'outcome_type_id_m8': 9, 'outcome_type_m9': None, 'outcome_type_id_m9': 10, 'outcome_type_m10': 'Stolen', 'outcome_type_id_m10': 11}]
(Background on this error at: https://sqlalche.me/e/14/gkpj); 116)
[2023-11-19T21:20:54.687+0000] {local_task_job_runner.py:228} INFO - Task exited with return code 1
[2023-11-19T21:31:18.857+0000] {taskinstance.py:1159} INFO - Dependencies all met for dep_context=non-requeueable deps ti=<TaskInstance: outcomes_dag.load_outcome_types_dim scheduled__2023-11-18T00:00:00+00:00 [queued]>
[2023-11-19T21:31:18.863+0000] {taskinstance.py:1159} INFO - Dependencies all met for dep_context=requeueable deps ti=<TaskInstance: outcomes_dag.load_outcome_types_dim scheduled__2023-11-18T00:00:00+00:00 [queued]>
[2023-11-19T21:31:18.865+0000] {taskinstance.py:1361} INFO - Starting attempt 1 of 1
[2023-11-19T21:31:18.878+0000] {taskinstance.py:1382} INFO - Executing <Task(PythonOperator): load_outcome_types_dim> on 2023-11-18 00:00:00+00:00
[2023-11-19T21:31:18.883+0000] {standard_task_runner.py:57} INFO - Started process 115 to run task
[2023-11-19T21:31:18.892+0000] {standard_task_runner.py:84} INFO - Running: ['***', 'tasks', 'run', 'outcomes_dag', 'load_outcome_types_dim', 'scheduled__2023-11-18T00:00:00+00:00', '--job-id', '12', '--raw', '--subdir', 'DAGS_FOLDER/outcomes_dag.py', '--cfg-path', '/tmp/tmpct9p_rxe']
[2023-11-19T21:31:18.897+0000] {standard_task_runner.py:85} INFO - Job 12: Subtask load_outcome_types_dim
[2023-11-19T21:31:18.980+0000] {task_command.py:416} INFO - Running <TaskInstance: outcomes_dag.load_outcome_types_dim scheduled__2023-11-18T00:00:00+00:00 [running]> on host bceb2bfddd0e
[2023-11-19T21:31:19.052+0000] {taskinstance.py:1662} INFO - Exporting env vars: AIRFLOW_CTX_DAG_OWNER='***' AIRFLOW_CTX_DAG_ID='outcomes_dag' AIRFLOW_CTX_TASK_ID='load_outcome_types_dim' AIRFLOW_CTX_EXECUTION_DATE='2023-11-18T00:00:00+00:00' AIRFLOW_CTX_TRY_NUMBER='1' AIRFLOW_CTX_DAG_RUN_ID='scheduled__2023-11-18T00:00:00+00:00'
[2023-11-19T21:31:19.436+0000] {logging_mixin.py:154} INFO - dim_outcome_types loaded
[2023-11-19T21:31:19.436+0000] {python.py:194} INFO - Done. Returned value was: None
[2023-11-19T21:31:19.443+0000] {taskinstance.py:1400} INFO - Marking task as SUCCESS. dag_id=outcomes_dag, task_id=load_outcome_types_dim, execution_date=20231118T000000, start_date=20231119T213118, end_date=20231119T213119
[2023-11-19T21:31:19.469+0000] {local_task_job_runner.py:228} INFO - Task exited with return code 0
[2023-11-20T17:17:51.310+0000] {taskinstance.py:1159} INFO - Dependencies all met for dep_context=non-requeueable deps ti=<TaskInstance: outcomes_dag.load_outcome_types_dim scheduled__2023-11-18T00:00:00+00:00 [queued]>
[2023-11-20T17:17:51.326+0000] {taskinstance.py:1159} INFO - Dependencies all met for dep_context=requeueable deps ti=<TaskInstance: outcomes_dag.load_outcome_types_dim scheduled__2023-11-18T00:00:00+00:00 [queued]>
[2023-11-20T17:17:51.326+0000] {taskinstance.py:1361} INFO - Starting attempt 1 of 1
[2023-11-20T17:17:51.340+0000] {taskinstance.py:1382} INFO - Executing <Task(PythonOperator): load_outcome_types_dim> on 2023-11-18 00:00:00+00:00
[2023-11-20T17:17:51.347+0000] {standard_task_runner.py:57} INFO - Started process 157 to run task
[2023-11-20T17:17:51.351+0000] {standard_task_runner.py:84} INFO - Running: ['***', 'tasks', 'run', 'outcomes_dag', 'load_outcome_types_dim', 'scheduled__2023-11-18T00:00:00+00:00', '--job-id', '17', '--raw', '--subdir', 'DAGS_FOLDER/outcomes_dag.py', '--cfg-path', '/tmp/tmp4d50ir9s']
[2023-11-20T17:17:51.359+0000] {standard_task_runner.py:85} INFO - Job 17: Subtask load_outcome_types_dim
[2023-11-20T17:17:51.454+0000] {task_command.py:416} INFO - Running <TaskInstance: outcomes_dag.load_outcome_types_dim scheduled__2023-11-18T00:00:00+00:00 [running]> on host c82b86fb091d
[2023-11-20T17:17:51.536+0000] {taskinstance.py:1662} INFO - Exporting env vars: AIRFLOW_CTX_DAG_OWNER='***' AIRFLOW_CTX_DAG_ID='outcomes_dag' AIRFLOW_CTX_TASK_ID='load_outcome_types_dim' AIRFLOW_CTX_EXECUTION_DATE='2023-11-18T00:00:00+00:00' AIRFLOW_CTX_TRY_NUMBER='1' AIRFLOW_CTX_DAG_RUN_ID='scheduled__2023-11-18T00:00:00+00:00'
[2023-11-20T17:18:07.692+0000] {taskinstance.py:1937} ERROR - Task failed with exception
Traceback (most recent call last):
  File "/home/airflow/.local/lib/python3.8/site-packages/sqlalchemy/engine/base.py", line 3371, in _wrap_pool_connect
    return fn()
  File "/home/airflow/.local/lib/python3.8/site-packages/sqlalchemy/pool/base.py", line 327, in connect
    return _ConnectionFairy._checkout(self)
  File "/home/airflow/.local/lib/python3.8/site-packages/sqlalchemy/pool/base.py", line 894, in _checkout
    fairy = _ConnectionRecord.checkout(pool)
  File "/home/airflow/.local/lib/python3.8/site-packages/sqlalchemy/pool/base.py", line 493, in checkout
    rec = pool._do_get()
  File "/home/airflow/.local/lib/python3.8/site-packages/sqlalchemy/pool/impl.py", line 146, in _do_get
    self._dec_overflow()
  File "/home/airflow/.local/lib/python3.8/site-packages/sqlalchemy/util/langhelpers.py", line 70, in __exit__
    compat.raise_(
  File "/home/airflow/.local/lib/python3.8/site-packages/sqlalchemy/util/compat.py", line 211, in raise_
    raise exception
  File "/home/airflow/.local/lib/python3.8/site-packages/sqlalchemy/pool/impl.py", line 143, in _do_get
    return self._create_connection()
  File "/home/airflow/.local/lib/python3.8/site-packages/sqlalchemy/pool/base.py", line 273, in _create_connection
    return _ConnectionRecord(self)
  File "/home/airflow/.local/lib/python3.8/site-packages/sqlalchemy/pool/base.py", line 388, in __init__
    self.__connect()
  File "/home/airflow/.local/lib/python3.8/site-packages/sqlalchemy/pool/base.py", line 691, in __connect
    pool.logger.debug("Error on connect(): %s", e)
  File "/home/airflow/.local/lib/python3.8/site-packages/sqlalchemy/util/langhelpers.py", line 70, in __exit__
    compat.raise_(
  File "/home/airflow/.local/lib/python3.8/site-packages/sqlalchemy/util/compat.py", line 211, in raise_
    raise exception
  File "/home/airflow/.local/lib/python3.8/site-packages/sqlalchemy/pool/base.py", line 686, in __connect
    self.dbapi_connection = connection = pool._invoke_creator(self)
  File "/home/airflow/.local/lib/python3.8/site-packages/sqlalchemy/engine/create.py", line 574, in connect
    return dialect.connect(*cargs, **cparams)
  File "/home/airflow/.local/lib/python3.8/site-packages/sqlalchemy/engine/default.py", line 598, in connect
    return self.dbapi.connect(*cargs, **cparams)
  File "/home/airflow/.local/lib/python3.8/site-packages/psycopg2/__init__.py", line 122, in connect
    conn = _connect(dsn, connection_factory=connection_factory, **kwasync)
psycopg2.OperationalError: connection to server at "dpg-cldp6jef27hc73fbu0rg-a.oregon-postgres.render.com" (35.227.164.209), port 5432 failed: server closed the connection unexpectedly
	This probably means the server terminated abnormally
	before or while processing the request.


The above exception was the direct cause of the following exception:

Traceback (most recent call last):
  File "/home/airflow/.local/lib/python3.8/site-packages/airflow/operators/python.py", line 192, in execute
    return_value = self.execute_callable()
  File "/home/airflow/.local/lib/python3.8/site-packages/airflow/operators/python.py", line 209, in execute_callable
    return self.python_callable(*self.op_args, **self.op_kwargs)
  File "/opt/airflow/dags/etl_scripts/load.py", line 23, in load_data
    pd.read_csv(obj['Body'], index_col=0).to_sql(table_name, conn, if_exists="append", index=False, method=insert_on_conflict_nothing)
  File "/home/airflow/.local/lib/python3.8/site-packages/pandas/core/generic.py", line 2878, in to_sql
    return sql.to_sql(
  File "/home/airflow/.local/lib/python3.8/site-packages/pandas/io/sql.py", line 768, in to_sql
    with pandasSQL_builder(con, schema=schema, need_transaction=True) as pandas_sql:
  File "/home/airflow/.local/lib/python3.8/site-packages/pandas/io/sql.py", line 832, in pandasSQL_builder
    return SQLDatabase(con, schema, need_transaction)
  File "/home/airflow/.local/lib/python3.8/site-packages/pandas/io/sql.py", line 1539, in __init__
    con = self.exit_stack.enter_context(con.connect())
  File "/home/airflow/.local/lib/python3.8/site-packages/sqlalchemy/engine/base.py", line 3325, in connect
    return self._connection_cls(self, close_with_result=close_with_result)
  File "/home/airflow/.local/lib/python3.8/site-packages/sqlalchemy/engine/base.py", line 96, in __init__
    else engine.raw_connection()
  File "/home/airflow/.local/lib/python3.8/site-packages/sqlalchemy/engine/base.py", line 3404, in raw_connection
    return self._wrap_pool_connect(self.pool.connect, _connection)
  File "/home/airflow/.local/lib/python3.8/site-packages/sqlalchemy/engine/base.py", line 3374, in _wrap_pool_connect
    Connection._handle_dbapi_exception_noconnection(
  File "/home/airflow/.local/lib/python3.8/site-packages/sqlalchemy/engine/base.py", line 2208, in _handle_dbapi_exception_noconnection
    util.raise_(
  File "/home/airflow/.local/lib/python3.8/site-packages/sqlalchemy/util/compat.py", line 211, in raise_
    raise exception
  File "/home/airflow/.local/lib/python3.8/site-packages/sqlalchemy/engine/base.py", line 3371, in _wrap_pool_connect
    return fn()
  File "/home/airflow/.local/lib/python3.8/site-packages/sqlalchemy/pool/base.py", line 327, in connect
    return _ConnectionFairy._checkout(self)
  File "/home/airflow/.local/lib/python3.8/site-packages/sqlalchemy/pool/base.py", line 894, in _checkout
    fairy = _ConnectionRecord.checkout(pool)
  File "/home/airflow/.local/lib/python3.8/site-packages/sqlalchemy/pool/base.py", line 493, in checkout
    rec = pool._do_get()
  File "/home/airflow/.local/lib/python3.8/site-packages/sqlalchemy/pool/impl.py", line 146, in _do_get
    self._dec_overflow()
  File "/home/airflow/.local/lib/python3.8/site-packages/sqlalchemy/util/langhelpers.py", line 70, in __exit__
    compat.raise_(
  File "/home/airflow/.local/lib/python3.8/site-packages/sqlalchemy/util/compat.py", line 211, in raise_
    raise exception
  File "/home/airflow/.local/lib/python3.8/site-packages/sqlalchemy/pool/impl.py", line 143, in _do_get
    return self._create_connection()
  File "/home/airflow/.local/lib/python3.8/site-packages/sqlalchemy/pool/base.py", line 273, in _create_connection
    return _ConnectionRecord(self)
  File "/home/airflow/.local/lib/python3.8/site-packages/sqlalchemy/pool/base.py", line 388, in __init__
    self.__connect()
  File "/home/airflow/.local/lib/python3.8/site-packages/sqlalchemy/pool/base.py", line 691, in __connect
    pool.logger.debug("Error on connect(): %s", e)
  File "/home/airflow/.local/lib/python3.8/site-packages/sqlalchemy/util/langhelpers.py", line 70, in __exit__
    compat.raise_(
  File "/home/airflow/.local/lib/python3.8/site-packages/sqlalchemy/util/compat.py", line 211, in raise_
    raise exception
  File "/home/airflow/.local/lib/python3.8/site-packages/sqlalchemy/pool/base.py", line 686, in __connect
    self.dbapi_connection = connection = pool._invoke_creator(self)
  File "/home/airflow/.local/lib/python3.8/site-packages/sqlalchemy/engine/create.py", line 574, in connect
    return dialect.connect(*cargs, **cparams)
  File "/home/airflow/.local/lib/python3.8/site-packages/sqlalchemy/engine/default.py", line 598, in connect
    return self.dbapi.connect(*cargs, **cparams)
  File "/home/airflow/.local/lib/python3.8/site-packages/psycopg2/__init__.py", line 122, in connect
    conn = _connect(dsn, connection_factory=connection_factory, **kwasync)
sqlalchemy.exc.OperationalError: (psycopg2.OperationalError) connection to server at "dpg-cldp6jef27hc73fbu0rg-a.oregon-postgres.render.com" (35.227.164.209), port 5432 failed: server closed the connection unexpectedly
	This probably means the server terminated abnormally
	before or while processing the request.

(Background on this error at: https://sqlalche.me/e/14/e3q8)
[2023-11-20T17:18:07.712+0000] {taskinstance.py:1400} INFO - Marking task as FAILED. dag_id=outcomes_dag, task_id=load_outcome_types_dim, execution_date=20231118T000000, start_date=20231120T171751, end_date=20231120T171807
[2023-11-20T17:18:07.738+0000] {standard_task_runner.py:104} ERROR - Failed to execute job 17 for task load_outcome_types_dim ((psycopg2.OperationalError) connection to server at "dpg-cldp6jef27hc73fbu0rg-a.oregon-postgres.render.com" (35.227.164.209), port 5432 failed: server closed the connection unexpectedly
	This probably means the server terminated abnormally
	before or while processing the request.

(Background on this error at: https://sqlalche.me/e/14/e3q8); 157)
[2023-11-20T17:18:07.770+0000] {local_task_job_runner.py:228} INFO - Task exited with return code 1
