[2023-11-25T04:56:04.238+0000] {taskinstance.py:1159} INFO - Dependencies all met for dep_context=non-requeueable deps ti=<TaskInstance: outcomes_dag.extract manual__2023-11-25T04:56:02.494040+00:00 [queued]>
[2023-11-25T04:56:04.242+0000] {taskinstance.py:1159} INFO - Dependencies all met for dep_context=requeueable deps ti=<TaskInstance: outcomes_dag.extract manual__2023-11-25T04:56:02.494040+00:00 [queued]>
[2023-11-25T04:56:04.242+0000] {taskinstance.py:1361} INFO - Starting attempt 1 of 1
[2023-11-25T04:56:04.248+0000] {taskinstance.py:1382} INFO - Executing <Task(PythonOperator): extract> on 2023-11-25 04:56:02.494040+00:00
[2023-11-25T04:56:04.253+0000] {standard_task_runner.py:57} INFO - Started process 76 to run task
[2023-11-25T04:56:04.256+0000] {standard_task_runner.py:84} INFO - Running: ['***', 'tasks', 'run', 'outcomes_dag', 'extract', 'manual__2023-11-25T04:56:02.494040+00:00', '--job-id', '3', '--raw', '--subdir', 'DAGS_FOLDER/outcomes_dag.py', '--cfg-path', '/tmp/tmpqhi14ojo']
[2023-11-25T04:56:04.258+0000] {standard_task_runner.py:85} INFO - Job 3: Subtask extract
[2023-11-25T04:56:04.338+0000] {task_command.py:416} INFO - Running <TaskInstance: outcomes_dag.extract manual__2023-11-25T04:56:02.494040+00:00 [running]> on host 9c18922f4e6b
[2023-11-25T04:56:04.385+0000] {taskinstance.py:1662} INFO - Exporting env vars: AIRFLOW_CTX_DAG_OWNER='***' AIRFLOW_CTX_DAG_ID='outcomes_dag' AIRFLOW_CTX_TASK_ID='extract' AIRFLOW_CTX_EXECUTION_DATE='2023-11-25T04:56:02.494040+00:00' AIRFLOW_CTX_TRY_NUMBER='1' AIRFLOW_CTX_DAG_RUN_ID='manual__2023-11-25T04:56:02.494040+00:00'
[2023-11-25T04:56:22.040+0000] {taskinstance.py:1937} ERROR - Task failed with exception
Traceback (most recent call last):
  File "/home/airflow/.local/lib/python3.8/site-packages/boto3/s3/transfer.py", line 292, in upload_file
    future.result()
  File "/home/airflow/.local/lib/python3.8/site-packages/s3transfer/futures.py", line 103, in result
    return self._coordinator.result()
  File "/home/airflow/.local/lib/python3.8/site-packages/s3transfer/futures.py", line 266, in result
    raise self._exception
  File "/home/airflow/.local/lib/python3.8/site-packages/s3transfer/tasks.py", line 139, in __call__
    return self._execute_main(kwargs)
  File "/home/airflow/.local/lib/python3.8/site-packages/s3transfer/tasks.py", line 162, in _execute_main
    return_value = self._main(**kwargs)
  File "/home/airflow/.local/lib/python3.8/site-packages/s3transfer/upload.py", line 764, in _main
    client.put_object(Bucket=bucket, Key=key, Body=body, **extra_args)
  File "/home/airflow/.local/lib/python3.8/site-packages/botocore/client.py", line 535, in _api_call
    return self._make_api_call(operation_name, kwargs)
  File "/home/airflow/.local/lib/python3.8/site-packages/botocore/client.py", line 980, in _make_api_call
    raise error_class(parsed_response, operation_name)
botocore.exceptions.ClientError: An error occurred (BadDigest) when calling the PutObject operation (reached max retries: 4): The Content-MD5 you specified did not match what we received.

During handling of the above exception, another exception occurred:

Traceback (most recent call last):
  File "/home/airflow/.local/lib/python3.8/site-packages/airflow/operators/python.py", line 192, in execute
    return_value = self.execute_callable()
  File "/home/airflow/.local/lib/python3.8/site-packages/airflow/operators/python.py", line 209, in execute_callable
    return self.python_callable(*self.op_args, **self.op_kwargs)
  File "/opt/airflow/dags/etl_scripts/extract.py", line 15, in extract_data
    s3.Bucket('animalshelter').upload_file(Filename='shelter.csv',Key='shelter.csv')
  File "/home/airflow/.local/lib/python3.8/site-packages/boto3/s3/inject.py", line 233, in bucket_upload_file
    return self.meta.client.upload_file(
  File "/home/airflow/.local/lib/python3.8/site-packages/boto3/s3/inject.py", line 143, in upload_file
    return transfer.upload_file(
  File "/home/airflow/.local/lib/python3.8/site-packages/boto3/s3/transfer.py", line 298, in upload_file
    raise S3UploadFailedError(
boto3.exceptions.S3UploadFailedError: Failed to upload shelter.csv to animalshelter/shelter.csv: An error occurred (BadDigest) when calling the PutObject operation (reached max retries: 4): The Content-MD5 you specified did not match what we received.
[2023-11-25T04:56:22.064+0000] {taskinstance.py:1400} INFO - Marking task as FAILED. dag_id=outcomes_dag, task_id=extract, execution_date=20231125T045602, start_date=20231125T045604, end_date=20231125T045622
[2023-11-25T04:56:22.073+0000] {standard_task_runner.py:104} ERROR - Failed to execute job 3 for task extract (Failed to upload shelter.csv to animalshelter/shelter.csv: An error occurred (BadDigest) when calling the PutObject operation (reached max retries: 4): The Content-MD5 you specified did not match what we received.; 76)
[2023-11-25T04:56:22.110+0000] {local_task_job_runner.py:228} INFO - Task exited with return code 1
