[2023-11-19T20:36:09.288+0000] {taskinstance.py:1159} INFO - Dependencies all met for dep_context=non-requeueable deps ti=<TaskInstance: outcomes_dag.load_animals_dim manual__2023-11-19T20:36:02.566797+00:00 [queued]>
[2023-11-19T20:36:09.294+0000] {taskinstance.py:1159} INFO - Dependencies all met for dep_context=requeueable deps ti=<TaskInstance: outcomes_dag.load_animals_dim manual__2023-11-19T20:36:02.566797+00:00 [queued]>
[2023-11-19T20:36:09.294+0000] {taskinstance.py:1361} INFO - Starting attempt 1 of 1
[2023-11-19T20:36:09.307+0000] {taskinstance.py:1382} INFO - Executing <Task(PythonOperator): load_animals_dim> on 2023-11-19 20:36:02.566797+00:00
[2023-11-19T20:36:09.313+0000] {standard_task_runner.py:57} INFO - Started process 187 to run task
[2023-11-19T20:36:09.316+0000] {standard_task_runner.py:84} INFO - Running: ['***', 'tasks', 'run', 'outcomes_dag', 'load_animals_dim', 'manual__2023-11-19T20:36:02.566797+00:00', '--job-id', '75', '--raw', '--subdir', 'DAGS_FOLDER/outcomes_dag.py', '--cfg-path', '/tmp/tmp5kldh9lp']
[2023-11-19T20:36:09.320+0000] {standard_task_runner.py:85} INFO - Job 75: Subtask load_animals_dim
[2023-11-19T20:36:09.365+0000] {task_command.py:416} INFO - Running <TaskInstance: outcomes_dag.load_animals_dim manual__2023-11-19T20:36:02.566797+00:00 [running]> on host dcd2747ca857
[2023-11-19T20:36:09.439+0000] {taskinstance.py:1662} INFO - Exporting env vars: AIRFLOW_CTX_DAG_OWNER='***' AIRFLOW_CTX_DAG_ID='outcomes_dag' AIRFLOW_CTX_TASK_ID='load_animals_dim' AIRFLOW_CTX_EXECUTION_DATE='2023-11-19T20:36:02.566797+00:00' AIRFLOW_CTX_TRY_NUMBER='1' AIRFLOW_CTX_DAG_RUN_ID='manual__2023-11-19T20:36:02.566797+00:00'
[2023-11-19T20:36:09.442+0000] {taskinstance.py:1937} ERROR - Task failed with exception
Traceback (most recent call last):
  File "/home/airflow/.local/lib/python3.8/site-packages/airflow/operators/python.py", line 192, in execute
    return_value = self.execute_callable()
  File "/home/airflow/.local/lib/python3.8/site-packages/airflow/operators/python.py", line 209, in execute_callable
    return self.python_callable(*self.op_args, **self.op_kwargs)
  File "/opt/airflow/dags/etl_scripts/load.py", line 26, in load_data
    pd.read_csv(table_file).to_sql(table_name, conn, if_exists="append", index=False, method=insert_on_conflict_nothing)
  File "/home/airflow/.local/lib/python3.8/site-packages/pandas/io/parsers/readers.py", line 912, in read_csv
    return _read(filepath_or_buffer, kwds)
  File "/home/airflow/.local/lib/python3.8/site-packages/pandas/io/parsers/readers.py", line 577, in _read
    parser = TextFileReader(filepath_or_buffer, **kwds)
  File "/home/airflow/.local/lib/python3.8/site-packages/pandas/io/parsers/readers.py", line 1407, in __init__
    self._engine = self._make_engine(f, self.engine)
  File "/home/airflow/.local/lib/python3.8/site-packages/pandas/io/parsers/readers.py", line 1661, in _make_engine
    self.handles = get_handle(
  File "/home/airflow/.local/lib/python3.8/site-packages/pandas/io/common.py", line 859, in get_handle
    handle = open(
FileNotFoundError: [Errno 2] No such file or directory: '/opt/airflow/data/2023-11-19/processed/dim_animals.parquet'
[2023-11-19T20:36:09.452+0000] {taskinstance.py:1400} INFO - Marking task as FAILED. dag_id=outcomes_dag, task_id=load_animals_dim, execution_date=20231119T203602, start_date=20231119T203609, end_date=20231119T203609
[2023-11-19T20:36:09.461+0000] {standard_task_runner.py:104} ERROR - Failed to execute job 75 for task load_animals_dim ([Errno 2] No such file or directory: '/opt/airflow/data/2023-11-19/processed/dim_animals.parquet'; 187)
[2023-11-19T20:36:09.490+0000] {local_task_job_runner.py:228} INFO - Task exited with return code 1
[2023-11-19T20:36:09.503+0000] {taskinstance.py:2778} INFO - 0 downstream tasks scheduled from follow-on schedule check
