[2023-11-20T00:24:21.227+0000] {taskinstance.py:1159} INFO - Dependencies all met for dep_context=non-requeueable deps ti=<TaskInstance: outcomes_dag.extract2 scheduled__2023-11-19T00:00:00+00:00 [queued]>
[2023-11-20T00:24:21.230+0000] {taskinstance.py:1159} INFO - Dependencies all met for dep_context=requeueable deps ti=<TaskInstance: outcomes_dag.extract2 scheduled__2023-11-19T00:00:00+00:00 [queued]>
[2023-11-20T00:24:21.231+0000] {taskinstance.py:1361} INFO - Starting attempt 1 of 1
[2023-11-20T00:24:21.236+0000] {taskinstance.py:1382} INFO - Executing <Task(PythonOperator): extract2> on 2023-11-19 00:00:00+00:00
[2023-11-20T00:24:21.240+0000] {standard_task_runner.py:57} INFO - Started process 647 to run task
[2023-11-20T00:24:21.242+0000] {standard_task_runner.py:84} INFO - Running: ['***', 'tasks', 'run', 'outcomes_dag', 'extract2', 'scheduled__2023-11-19T00:00:00+00:00', '--job-id', '19', '--raw', '--subdir', 'DAGS_FOLDER/outcomes_dag.py', '--cfg-path', '/tmp/tmpxoxgy6ax']
[2023-11-20T00:24:21.244+0000] {standard_task_runner.py:85} INFO - Job 19: Subtask extract2
[2023-11-20T00:24:21.272+0000] {task_command.py:416} INFO - Running <TaskInstance: outcomes_dag.extract2 scheduled__2023-11-19T00:00:00+00:00 [running]> on host bceb2bfddd0e
[2023-11-20T00:24:21.315+0000] {taskinstance.py:1662} INFO - Exporting env vars: AIRFLOW_CTX_DAG_OWNER='***' AIRFLOW_CTX_DAG_ID='outcomes_dag' AIRFLOW_CTX_TASK_ID='extract2' AIRFLOW_CTX_EXECUTION_DATE='2023-11-19T00:00:00+00:00' AIRFLOW_CTX_TRY_NUMBER='1' AIRFLOW_CTX_DAG_RUN_ID='scheduled__2023-11-19T00:00:00+00:00'
[2023-11-20T00:24:21.446+0000] {taskinstance.py:1937} ERROR - Task failed with exception
Traceback (most recent call last):
  File "/home/airflow/.local/lib/python3.8/site-packages/urllib3/connection.py", line 174, in _new_conn
    conn = connection.create_connection(
  File "/home/airflow/.local/lib/python3.8/site-packages/urllib3/util/connection.py", line 72, in create_connection
    for res in socket.getaddrinfo(host, port, family, socket.SOCK_STREAM):
  File "/usr/local/lib/python3.8/socket.py", line 918, in getaddrinfo
    for res in _socket.getaddrinfo(host, port, family, type, proto, flags):
socket.gaierror: [Errno -2] Name or service not known

During handling of the above exception, another exception occurred:

Traceback (most recent call last):
  File "/home/airflow/.local/lib/python3.8/site-packages/urllib3/connectionpool.py", line 715, in urlopen
    httplib_response = self._make_request(
  File "/home/airflow/.local/lib/python3.8/site-packages/urllib3/connectionpool.py", line 404, in _make_request
    self._validate_conn(conn)
  File "/home/airflow/.local/lib/python3.8/site-packages/urllib3/connectionpool.py", line 1058, in _validate_conn
    conn.connect()
  File "/home/airflow/.local/lib/python3.8/site-packages/urllib3/connection.py", line 363, in connect
    self.sock = conn = self._new_conn()
  File "/home/airflow/.local/lib/python3.8/site-packages/urllib3/connection.py", line 186, in _new_conn
    raise NewConnectionError(
urllib3.exceptions.NewConnectionError: <urllib3.connection.HTTPSConnection object at 0xffff746effd0>: Failed to establish a new connection: [Errno -2] Name or service not known

During handling of the above exception, another exception occurred:

Traceback (most recent call last):
  File "/home/airflow/.local/lib/python3.8/site-packages/requests/adapters.py", line 486, in send
    resp = conn.urlopen(
  File "/home/airflow/.local/lib/python3.8/site-packages/urllib3/connectionpool.py", line 799, in urlopen
    retries = retries.increment(
  File "/home/airflow/.local/lib/python3.8/site-packages/urllib3/util/retry.py", line 592, in increment
    raise MaxRetryError(_pool, url, error or ResponseError(cause))
urllib3.exceptions.MaxRetryError: HTTPSConnectionPool(host='data.austintexas.gov', port=443): Max retries exceeded with url: /resource/9t4d-g238.json (Caused by NewConnectionError('<urllib3.connection.HTTPSConnection object at 0xffff746effd0>: Failed to establish a new connection: [Errno -2] Name or service not known'))

During handling of the above exception, another exception occurred:

Traceback (most recent call last):
  File "/home/airflow/.local/lib/python3.8/site-packages/airflow/operators/python.py", line 192, in execute
    return_value = self.execute_callable()
  File "/home/airflow/.local/lib/python3.8/site-packages/airflow/operators/python.py", line 209, in execute_callable
    return self.python_callable(*self.op_args, **self.op_kwargs)
  File "/opt/airflow/dags/etl_scripts/extract.py", line 9, in extract_data
    response_API = requests.get(source_csv)
  File "/home/airflow/.local/lib/python3.8/site-packages/requests/api.py", line 73, in get
    return request("get", url, params=params, **kwargs)
  File "/home/airflow/.local/lib/python3.8/site-packages/requests/api.py", line 59, in request
    return session.request(method=method, url=url, **kwargs)
  File "/home/airflow/.local/lib/python3.8/site-packages/requests/sessions.py", line 589, in request
    resp = self.send(prep, **send_kwargs)
  File "/home/airflow/.local/lib/python3.8/site-packages/requests/sessions.py", line 703, in send
    r = adapter.send(request, **kwargs)
  File "/home/airflow/.local/lib/python3.8/site-packages/requests/adapters.py", line 519, in send
    raise ConnectionError(e, request=request)
requests.exceptions.ConnectionError: HTTPSConnectionPool(host='data.austintexas.gov', port=443): Max retries exceeded with url: /resource/9t4d-g238.json (Caused by NewConnectionError('<urllib3.connection.HTTPSConnection object at 0xffff746effd0>: Failed to establish a new connection: [Errno -2] Name or service not known'))
[2023-11-20T00:24:21.460+0000] {taskinstance.py:1400} INFO - Marking task as FAILED. dag_id=outcomes_dag, task_id=extract2, execution_date=20231119T000000, start_date=20231120T002421, end_date=20231120T002421
[2023-11-20T00:24:21.467+0000] {standard_task_runner.py:104} ERROR - Failed to execute job 19 for task extract2 (HTTPSConnectionPool(host='data.austintexas.gov', port=443): Max retries exceeded with url: /resource/9t4d-g238.json (Caused by NewConnectionError('<urllib3.connection.HTTPSConnection object at 0xffff746effd0>: Failed to establish a new connection: [Errno -2] Name or service not known')); 647)
[2023-11-20T00:24:21.495+0000] {local_task_job_runner.py:228} INFO - Task exited with return code 1
[2023-11-20T17:17:43.600+0000] {taskinstance.py:1159} INFO - Dependencies all met for dep_context=non-requeueable deps ti=<TaskInstance: outcomes_dag.extract2 scheduled__2023-11-19T00:00:00+00:00 [queued]>
[2023-11-20T17:17:43.608+0000] {taskinstance.py:1159} INFO - Dependencies all met for dep_context=requeueable deps ti=<TaskInstance: outcomes_dag.extract2 scheduled__2023-11-19T00:00:00+00:00 [queued]>
[2023-11-20T17:17:43.608+0000] {taskinstance.py:1361} INFO - Starting attempt 1 of 1
[2023-11-20T17:17:43.628+0000] {taskinstance.py:1382} INFO - Executing <Task(PythonOperator): extract2> on 2023-11-19 00:00:00+00:00
[2023-11-20T17:17:43.635+0000] {standard_task_runner.py:57} INFO - Started process 86 to run task
[2023-11-20T17:17:43.639+0000] {standard_task_runner.py:84} INFO - Running: ['***', 'tasks', 'run', 'outcomes_dag', 'extract2', 'scheduled__2023-11-19T00:00:00+00:00', '--job-id', '3', '--raw', '--subdir', 'DAGS_FOLDER/outcomes_dag.py', '--cfg-path', '/tmp/tmpgrionna7']
[2023-11-20T17:17:43.644+0000] {standard_task_runner.py:85} INFO - Job 3: Subtask extract2
[2023-11-20T17:17:43.718+0000] {task_command.py:416} INFO - Running <TaskInstance: outcomes_dag.extract2 scheduled__2023-11-19T00:00:00+00:00 [running]> on host c82b86fb091d
[2023-11-20T17:17:43.824+0000] {taskinstance.py:1662} INFO - Exporting env vars: AIRFLOW_CTX_DAG_OWNER='***' AIRFLOW_CTX_DAG_ID='outcomes_dag' AIRFLOW_CTX_TASK_ID='extract2' AIRFLOW_CTX_EXECUTION_DATE='2023-11-19T00:00:00+00:00' AIRFLOW_CTX_TRY_NUMBER='1' AIRFLOW_CTX_DAG_RUN_ID='scheduled__2023-11-19T00:00:00+00:00'
[2023-11-20T17:17:45.549+0000] {python.py:194} INFO - Done. Returned value was: None
[2023-11-20T17:17:45.565+0000] {taskinstance.py:1400} INFO - Marking task as SUCCESS. dag_id=outcomes_dag, task_id=extract2, execution_date=20231119T000000, start_date=20231120T171743, end_date=20231120T171745
[2023-11-20T17:17:45.621+0000] {local_task_job_runner.py:228} INFO - Task exited with return code 0
