[2023-11-25T03:55:00.491+0000] {taskinstance.py:1159} INFO - Dependencies all met for dep_context=non-requeueable deps ti=<TaskInstance: outcomes_dag.extract2 scheduled__2023-11-22T00:00:00+00:00 [queued]>
[2023-11-25T03:55:00.501+0000] {taskinstance.py:1159} INFO - Dependencies all met for dep_context=requeueable deps ti=<TaskInstance: outcomes_dag.extract2 scheduled__2023-11-22T00:00:00+00:00 [queued]>
[2023-11-25T03:55:00.502+0000] {taskinstance.py:1361} INFO - Starting attempt 1 of 1
[2023-11-25T03:55:00.519+0000] {taskinstance.py:1382} INFO - Executing <Task(PythonOperator): extract2> on 2023-11-22 00:00:00+00:00
[2023-11-25T03:55:00.528+0000] {standard_task_runner.py:57} INFO - Started process 97 to run task
[2023-11-25T03:55:00.537+0000] {standard_task_runner.py:84} INFO - Running: ['***', 'tasks', 'run', 'outcomes_dag', 'extract2', 'scheduled__2023-11-22T00:00:00+00:00', '--job-id', '12', '--raw', '--subdir', 'DAGS_FOLDER/outcomes_dag.py', '--cfg-path', '/tmp/tmpvbgq786c']
[2023-11-25T03:55:00.539+0000] {standard_task_runner.py:85} INFO - Job 12: Subtask extract2
[2023-11-25T03:55:00.595+0000] {task_command.py:416} INFO - Running <TaskInstance: outcomes_dag.extract2 scheduled__2023-11-22T00:00:00+00:00 [running]> on host 1ccd1734fa5f
[2023-11-25T03:55:00.661+0000] {taskinstance.py:1662} INFO - Exporting env vars: AIRFLOW_CTX_DAG_OWNER='***' AIRFLOW_CTX_DAG_ID='outcomes_dag' AIRFLOW_CTX_TASK_ID='extract2' AIRFLOW_CTX_EXECUTION_DATE='2023-11-22T00:00:00+00:00' AIRFLOW_CTX_TRY_NUMBER='1' AIRFLOW_CTX_DAG_RUN_ID='scheduled__2023-11-22T00:00:00+00:00'
[2023-11-25T03:55:20.765+0000] {taskinstance.py:1937} ERROR - Task failed with exception
Traceback (most recent call last):
  File "/home/airflow/.local/lib/python3.8/site-packages/boto3/s3/transfer.py", line 292, in upload_file
    future.result()
  File "/home/airflow/.local/lib/python3.8/site-packages/s3transfer/futures.py", line 103, in result
    return self._coordinator.result()
  File "/home/airflow/.local/lib/python3.8/site-packages/s3transfer/futures.py", line 266, in result
    raise self._exception
  File "/home/airflow/.local/lib/python3.8/site-packages/s3transfer/tasks.py", line 139, in __call__
    return self._execute_main(kwargs)
  File "/home/airflow/.local/lib/python3.8/site-packages/s3transfer/tasks.py", line 162, in _execute_main
    return_value = self._main(**kwargs)
  File "/home/airflow/.local/lib/python3.8/site-packages/s3transfer/upload.py", line 764, in _main
    client.put_object(Bucket=bucket, Key=key, Body=body, **extra_args)
  File "/home/airflow/.local/lib/python3.8/site-packages/botocore/client.py", line 535, in _api_call
    return self._make_api_call(operation_name, kwargs)
  File "/home/airflow/.local/lib/python3.8/site-packages/botocore/client.py", line 980, in _make_api_call
    raise error_class(parsed_response, operation_name)
botocore.exceptions.ClientError: An error occurred (BadDigest) when calling the PutObject operation (reached max retries: 4): The Content-MD5 you specified did not match what we received.

During handling of the above exception, another exception occurred:

Traceback (most recent call last):
  File "/home/airflow/.local/lib/python3.8/site-packages/airflow/operators/python.py", line 192, in execute
    return_value = self.execute_callable()
  File "/home/airflow/.local/lib/python3.8/site-packages/airflow/operators/python.py", line 209, in execute_callable
    return self.python_callable(*self.op_args, **self.op_kwargs)
  File "/opt/airflow/dags/etl_scripts/extract.py", line 15, in extract_data
    s3.Bucket('animalshelter').upload_file(Filename='shelter.csv',Key='shelter.csv')
  File "/home/airflow/.local/lib/python3.8/site-packages/boto3/s3/inject.py", line 233, in bucket_upload_file
    return self.meta.client.upload_file(
  File "/home/airflow/.local/lib/python3.8/site-packages/boto3/s3/inject.py", line 143, in upload_file
    return transfer.upload_file(
  File "/home/airflow/.local/lib/python3.8/site-packages/boto3/s3/transfer.py", line 298, in upload_file
    raise S3UploadFailedError(
boto3.exceptions.S3UploadFailedError: Failed to upload shelter.csv to animalshelter/shelter.csv: An error occurred (BadDigest) when calling the PutObject operation (reached max retries: 4): The Content-MD5 you specified did not match what we received.
[2023-11-25T03:55:20.815+0000] {taskinstance.py:1400} INFO - Marking task as FAILED. dag_id=outcomes_dag, task_id=extract2, execution_date=20231122T000000, start_date=20231125T035500, end_date=20231125T035520
[2023-11-25T03:55:20.849+0000] {standard_task_runner.py:104} ERROR - Failed to execute job 12 for task extract2 (Failed to upload shelter.csv to animalshelter/shelter.csv: An error occurred (BadDigest) when calling the PutObject operation (reached max retries: 4): The Content-MD5 you specified did not match what we received.; 97)
[2023-11-25T03:55:20.880+0000] {local_task_job_runner.py:228} INFO - Task exited with return code 1
