[2023-11-19T10:08:48.822+0000] {taskinstance.py:1159} INFO - Dependencies all met for dep_context=non-requeueable deps ti=<TaskInstance: outcomes_dag.transform manual__2023-11-19T10:08:43.311405+00:00 [queued]>
[2023-11-19T10:08:48.827+0000] {taskinstance.py:1159} INFO - Dependencies all met for dep_context=requeueable deps ti=<TaskInstance: outcomes_dag.transform manual__2023-11-19T10:08:43.311405+00:00 [queued]>
[2023-11-19T10:08:48.828+0000] {taskinstance.py:1361} INFO - Starting attempt 1 of 1
[2023-11-19T10:08:48.833+0000] {taskinstance.py:1382} INFO - Executing <Task(PythonOperator): transform> on 2023-11-19 10:08:43.311405+00:00
[2023-11-19T10:08:48.841+0000] {standard_task_runner.py:57} INFO - Started process 911 to run task
[2023-11-19T10:08:48.844+0000] {standard_task_runner.py:84} INFO - Running: ['***', 'tasks', 'run', 'outcomes_dag', 'transform', 'manual__2023-11-19T10:08:43.311405+00:00', '--job-id', '54', '--raw', '--subdir', 'DAGS_FOLDER/outcomes_dag.py', '--cfg-path', '/tmp/tmp7xc88gco']
[2023-11-19T10:08:48.847+0000] {standard_task_runner.py:85} INFO - Job 54: Subtask transform
[2023-11-19T10:08:48.885+0000] {task_command.py:416} INFO - Running <TaskInstance: outcomes_dag.transform manual__2023-11-19T10:08:43.311405+00:00 [running]> on host 696613a1ef55
[2023-11-19T10:08:48.976+0000] {taskinstance.py:1662} INFO - Exporting env vars: AIRFLOW_CTX_DAG_OWNER='***' AIRFLOW_CTX_DAG_ID='outcomes_dag' AIRFLOW_CTX_TASK_ID='transform' AIRFLOW_CTX_EXECUTION_DATE='2023-11-19T10:08:43.311405+00:00' AIRFLOW_CTX_TRY_NUMBER='1' AIRFLOW_CTX_DAG_RUN_ID='manual__2023-11-19T10:08:43.311405+00:00'
[2023-11-19T10:08:50.526+0000] {taskinstance.py:1937} ERROR - Task failed with exception
Traceback (most recent call last):
  File "/home/airflow/.local/lib/python3.8/site-packages/airflow/operators/python.py", line 192, in execute
    return_value = self.execute_callable()
  File "/home/airflow/.local/lib/python3.8/site-packages/airflow/operators/python.py", line 209, in execute_callable
    return self.python_callable(*self.op_args, **self.op_kwargs)
  File "/opt/airflow/dags/etl_scripts/transform.py", line 40, in transform_data
    s3.Bucket('animalshelter').upload_file(Filename='dim_dates.csv', Key='dim_dates.csv')
  File "/home/airflow/.local/lib/python3.8/site-packages/boto3/s3/inject.py", line 233, in bucket_upload_file
    return self.meta.client.upload_file(
  File "/home/airflow/.local/lib/python3.8/site-packages/boto3/s3/inject.py", line 143, in upload_file
    return transfer.upload_file(
  File "/home/airflow/.local/lib/python3.8/site-packages/boto3/s3/transfer.py", line 292, in upload_file
    future.result()
  File "/home/airflow/.local/lib/python3.8/site-packages/s3transfer/futures.py", line 103, in result
    return self._coordinator.result()
  File "/home/airflow/.local/lib/python3.8/site-packages/s3transfer/futures.py", line 266, in result
    raise self._exception
  File "/home/airflow/.local/lib/python3.8/site-packages/s3transfer/tasks.py", line 269, in _main
    self._submit(transfer_future=transfer_future, **kwargs)
  File "/home/airflow/.local/lib/python3.8/site-packages/s3transfer/upload.py", line 591, in _submit
    upload_input_manager.provide_transfer_size(transfer_future)
  File "/home/airflow/.local/lib/python3.8/site-packages/s3transfer/upload.py", line 244, in provide_transfer_size
    self._osutil.get_file_size(transfer_future.meta.call_args.fileobj)
  File "/home/airflow/.local/lib/python3.8/site-packages/s3transfer/utils.py", line 247, in get_file_size
    return os.path.getsize(filename)
  File "/usr/local/lib/python3.8/genericpath.py", line 50, in getsize
    return os.stat(filename).st_size
FileNotFoundError: [Errno 2] No such file or directory: 'dim_dates.csv'
[2023-11-19T10:08:50.536+0000] {taskinstance.py:1400} INFO - Marking task as FAILED. dag_id=outcomes_dag, task_id=transform, execution_date=20231119T100843, start_date=20231119T100848, end_date=20231119T100850
[2023-11-19T10:08:50.542+0000] {standard_task_runner.py:104} ERROR - Failed to execute job 54 for task transform ([Errno 2] No such file or directory: 'dim_dates.csv'; 911)
[2023-11-19T10:08:50.559+0000] {local_task_job_runner.py:228} INFO - Task exited with return code 1
[2023-11-19T10:08:50.575+0000] {taskinstance.py:2778} INFO - 0 downstream tasks scheduled from follow-on schedule check
