[2023-11-19T06:28:24.486+0000] {taskinstance.py:1159} INFO - Dependencies all met for dep_context=non-requeueable deps ti=<TaskInstance: outcomes_dag.load_animals_dim scheduled__2023-11-18T00:00:00+00:00 [queued]>
[2023-11-19T06:28:24.494+0000] {taskinstance.py:1159} INFO - Dependencies all met for dep_context=requeueable deps ti=<TaskInstance: outcomes_dag.load_animals_dim scheduled__2023-11-18T00:00:00+00:00 [queued]>
[2023-11-19T06:28:24.496+0000] {taskinstance.py:1361} INFO - Starting attempt 1 of 1
[2023-11-19T06:28:24.507+0000] {taskinstance.py:1382} INFO - Executing <Task(PythonOperator): load_animals_dim> on 2023-11-18 00:00:00+00:00
[2023-11-19T06:28:24.513+0000] {standard_task_runner.py:57} INFO - Started process 100 to run task
[2023-11-19T06:28:24.525+0000] {standard_task_runner.py:84} INFO - Running: ['***', 'tasks', 'run', 'outcomes_dag', 'load_animals_dim', 'scheduled__2023-11-18T00:00:00+00:00', '--job-id', '7', '--raw', '--subdir', 'DAGS_FOLDER/outcomes_dag.py', '--cfg-path', '/tmp/tmpq6uubytv']
[2023-11-19T06:28:24.537+0000] {standard_task_runner.py:85} INFO - Job 7: Subtask load_animals_dim
[2023-11-19T06:28:24.593+0000] {task_command.py:416} INFO - Running <TaskInstance: outcomes_dag.load_animals_dim scheduled__2023-11-18T00:00:00+00:00 [running]> on host 8c758415f3b2
[2023-11-19T06:28:24.861+0000] {taskinstance.py:1662} INFO - Exporting env vars: AIRFLOW_CTX_DAG_OWNER='***' AIRFLOW_CTX_DAG_ID='outcomes_dag' AIRFLOW_CTX_TASK_ID='load_animals_dim' AIRFLOW_CTX_EXECUTION_DATE='2023-11-18T00:00:00+00:00' AIRFLOW_CTX_TRY_NUMBER='1' AIRFLOW_CTX_DAG_RUN_ID='scheduled__2023-11-18T00:00:00+00:00'
[2023-11-19T06:28:39.102+0000] {logging_mixin.py:154} INFO - dim_animals loaded
[2023-11-19T06:28:39.105+0000] {python.py:194} INFO - Done. Returned value was: None
[2023-11-19T06:28:39.147+0000] {taskinstance.py:1400} INFO - Marking task as SUCCESS. dag_id=outcomes_dag, task_id=load_animals_dim, execution_date=20231118T000000, start_date=20231119T062824, end_date=20231119T062839
[2023-11-19T06:28:39.239+0000] {local_task_job_runner.py:228} INFO - Task exited with return code 0
[2023-11-19T06:28:39.299+0000] {taskinstance.py:2778} INFO - 0 downstream tasks scheduled from follow-on schedule check
[2023-11-19T07:33:05.069+0000] {taskinstance.py:1159} INFO - Dependencies all met for dep_context=non-requeueable deps ti=<TaskInstance: outcomes_dag.load_animals_dim scheduled__2023-11-18T00:00:00+00:00 [queued]>
[2023-11-19T07:33:05.079+0000] {taskinstance.py:1159} INFO - Dependencies all met for dep_context=requeueable deps ti=<TaskInstance: outcomes_dag.load_animals_dim scheduled__2023-11-18T00:00:00+00:00 [queued]>
[2023-11-19T07:33:05.079+0000] {taskinstance.py:1361} INFO - Starting attempt 1 of 1
[2023-11-19T07:33:05.088+0000] {taskinstance.py:1382} INFO - Executing <Task(PythonOperator): load_animals_dim> on 2023-11-18 00:00:00+00:00
[2023-11-19T07:33:05.091+0000] {standard_task_runner.py:57} INFO - Started process 127 to run task
[2023-11-19T07:33:05.097+0000] {standard_task_runner.py:84} INFO - Running: ['***', 'tasks', 'run', 'outcomes_dag', 'load_animals_dim', 'scheduled__2023-11-18T00:00:00+00:00', '--job-id', '13', '--raw', '--subdir', 'DAGS_FOLDER/outcomes_dag.py', '--cfg-path', '/tmp/tmp28xrt8r8']
[2023-11-19T07:33:05.102+0000] {standard_task_runner.py:85} INFO - Job 13: Subtask load_animals_dim
[2023-11-19T07:33:05.158+0000] {task_command.py:416} INFO - Running <TaskInstance: outcomes_dag.load_animals_dim scheduled__2023-11-18T00:00:00+00:00 [running]> on host 13403f191858
[2023-11-19T07:33:05.538+0000] {taskinstance.py:1662} INFO - Exporting env vars: AIRFLOW_CTX_DAG_OWNER='***' AIRFLOW_CTX_DAG_ID='outcomes_dag' AIRFLOW_CTX_TASK_ID='load_animals_dim' AIRFLOW_CTX_EXECUTION_DATE='2023-11-18T00:00:00+00:00' AIRFLOW_CTX_TRY_NUMBER='1' AIRFLOW_CTX_DAG_RUN_ID='scheduled__2023-11-18T00:00:00+00:00'
[2023-11-19T07:33:18.394+0000] {logging_mixin.py:154} INFO - dim_animals loaded
[2023-11-19T07:33:18.401+0000] {python.py:194} INFO - Done. Returned value was: None
[2023-11-19T07:33:18.436+0000] {taskinstance.py:1400} INFO - Marking task as SUCCESS. dag_id=outcomes_dag, task_id=load_animals_dim, execution_date=20231118T000000, start_date=20231119T073305, end_date=20231119T073318
[2023-11-19T07:33:18.552+0000] {local_task_job_runner.py:228} INFO - Task exited with return code 0
[2023-11-19T07:33:18.591+0000] {taskinstance.py:2778} INFO - 1 downstream tasks scheduled from follow-on schedule check
[2023-11-19T09:32:54.220+0000] {taskinstance.py:1159} INFO - Dependencies all met for dep_context=non-requeueable deps ti=<TaskInstance: outcomes_dag.load_animals_dim scheduled__2023-11-18T00:00:00+00:00 [queued]>
[2023-11-19T09:32:54.237+0000] {taskinstance.py:1159} INFO - Dependencies all met for dep_context=requeueable deps ti=<TaskInstance: outcomes_dag.load_animals_dim scheduled__2023-11-18T00:00:00+00:00 [queued]>
[2023-11-19T09:32:54.244+0000] {taskinstance.py:1361} INFO - Starting attempt 1 of 1
[2023-11-19T09:32:54.277+0000] {taskinstance.py:1382} INFO - Executing <Task(PythonOperator): load_animals_dim> on 2023-11-18 00:00:00+00:00
[2023-11-19T09:32:54.325+0000] {standard_task_runner.py:57} INFO - Started process 104 to run task
[2023-11-19T09:32:54.318+0000] {standard_task_runner.py:84} INFO - Running: ['***', 'tasks', 'run', 'outcomes_dag', 'load_animals_dim', 'scheduled__2023-11-18T00:00:00+00:00', '--job-id', '16', '--raw', '--subdir', 'DAGS_FOLDER/outcomes_dag.py', '--cfg-path', '/tmp/tmpc7nupfzq']
[2023-11-19T09:32:54.349+0000] {standard_task_runner.py:85} INFO - Job 16: Subtask load_animals_dim
[2023-11-19T09:32:54.463+0000] {task_command.py:416} INFO - Running <TaskInstance: outcomes_dag.load_animals_dim scheduled__2023-11-18T00:00:00+00:00 [running]> on host 696613a1ef55
[2023-11-19T09:32:54.585+0000] {taskinstance.py:1662} INFO - Exporting env vars: AIRFLOW_CTX_DAG_OWNER='***' AIRFLOW_CTX_DAG_ID='outcomes_dag' AIRFLOW_CTX_TASK_ID='load_animals_dim' AIRFLOW_CTX_EXECUTION_DATE='2023-11-18T00:00:00+00:00' AIRFLOW_CTX_TRY_NUMBER='1' AIRFLOW_CTX_DAG_RUN_ID='scheduled__2023-11-18T00:00:00+00:00'
[2023-11-19T09:32:54.596+0000] {taskinstance.py:1937} ERROR - Task failed with exception
Traceback (most recent call last):
  File "/home/airflow/.local/lib/python3.8/site-packages/airflow/operators/python.py", line 192, in execute
    return_value = self.execute_callable()
  File "/home/airflow/.local/lib/python3.8/site-packages/airflow/operators/python.py", line 209, in execute_callable
    return self.python_callable(*self.op_args, **self.op_kwargs)
  File "/opt/airflow/dags/etl_scripts/load.py", line 25, in load_data
    pd.read_parquet(table_file).to_sql(table_name, conn, if_exists="append", index=False, method=insert_on_conflict_nothing)
  File "/home/airflow/.local/lib/python3.8/site-packages/pandas/io/parquet.py", line 509, in read_parquet
    return impl.read(
  File "/home/airflow/.local/lib/python3.8/site-packages/pandas/io/parquet.py", line 220, in read
    path_or_handle, handles, kwargs["filesystem"] = _get_path_or_handle(
  File "/home/airflow/.local/lib/python3.8/site-packages/pandas/io/parquet.py", line 110, in _get_path_or_handle
    handles = get_handle(
  File "/home/airflow/.local/lib/python3.8/site-packages/pandas/io/common.py", line 868, in get_handle
    handle = open(handle, ioargs.mode)
FileNotFoundError: [Errno 2] No such file or directory: '/opt/airflow/data/2023-11-18/processed/dim_animals.parquet'
[2023-11-19T09:32:54.607+0000] {taskinstance.py:1400} INFO - Marking task as FAILED. dag_id=outcomes_dag, task_id=load_animals_dim, execution_date=20231118T000000, start_date=20231119T093254, end_date=20231119T093254
[2023-11-19T09:32:54.612+0000] {standard_task_runner.py:104} ERROR - Failed to execute job 16 for task load_animals_dim ([Errno 2] No such file or directory: '/opt/airflow/data/2023-11-18/processed/dim_animals.parquet'; 104)
[2023-11-19T09:32:54.620+0000] {local_task_job_runner.py:228} INFO - Task exited with return code 1
[2023-11-19T09:32:54.641+0000] {taskinstance.py:2778} INFO - 0 downstream tasks scheduled from follow-on schedule check
[2023-11-19T20:43:40.302+0000] {taskinstance.py:1159} INFO - Dependencies all met for dep_context=non-requeueable deps ti=<TaskInstance: outcomes_dag.load_animals_dim scheduled__2023-11-18T00:00:00+00:00 [queued]>
[2023-11-19T20:43:40.306+0000] {taskinstance.py:1159} INFO - Dependencies all met for dep_context=requeueable deps ti=<TaskInstance: outcomes_dag.load_animals_dim scheduled__2023-11-18T00:00:00+00:00 [queued]>
[2023-11-19T20:43:40.306+0000] {taskinstance.py:1361} INFO - Starting attempt 1 of 1
[2023-11-19T20:43:40.311+0000] {taskinstance.py:1382} INFO - Executing <Task(PythonOperator): load_animals_dim> on 2023-11-18 00:00:00+00:00
[2023-11-19T20:43:40.314+0000] {standard_task_runner.py:57} INFO - Started process 103 to run task
[2023-11-19T20:43:40.317+0000] {standard_task_runner.py:84} INFO - Running: ['***', 'tasks', 'run', 'outcomes_dag', 'load_animals_dim', 'scheduled__2023-11-18T00:00:00+00:00', '--job-id', '9', '--raw', '--subdir', 'DAGS_FOLDER/outcomes_dag.py', '--cfg-path', '/tmp/tmphddrk2z3']
[2023-11-19T20:43:40.319+0000] {standard_task_runner.py:85} INFO - Job 9: Subtask load_animals_dim
[2023-11-19T20:43:40.365+0000] {task_command.py:416} INFO - Running <TaskInstance: outcomes_dag.load_animals_dim scheduled__2023-11-18T00:00:00+00:00 [running]> on host 549ad0bd2371
[2023-11-19T20:43:40.425+0000] {taskinstance.py:1662} INFO - Exporting env vars: AIRFLOW_CTX_DAG_OWNER='***' AIRFLOW_CTX_DAG_ID='outcomes_dag' AIRFLOW_CTX_TASK_ID='load_animals_dim' AIRFLOW_CTX_EXECUTION_DATE='2023-11-18T00:00:00+00:00' AIRFLOW_CTX_TRY_NUMBER='1' AIRFLOW_CTX_DAG_RUN_ID='scheduled__2023-11-18T00:00:00+00:00'
[2023-11-19T20:43:56.606+0000] {taskinstance.py:1937} ERROR - Task failed with exception
Traceback (most recent call last):
  File "/home/airflow/.local/lib/python3.8/site-packages/sqlalchemy/engine/base.py", line 3371, in _wrap_pool_connect
    return fn()
  File "/home/airflow/.local/lib/python3.8/site-packages/sqlalchemy/pool/base.py", line 327, in connect
    return _ConnectionFairy._checkout(self)
  File "/home/airflow/.local/lib/python3.8/site-packages/sqlalchemy/pool/base.py", line 894, in _checkout
    fairy = _ConnectionRecord.checkout(pool)
  File "/home/airflow/.local/lib/python3.8/site-packages/sqlalchemy/pool/base.py", line 493, in checkout
    rec = pool._do_get()
  File "/home/airflow/.local/lib/python3.8/site-packages/sqlalchemy/pool/impl.py", line 146, in _do_get
    self._dec_overflow()
  File "/home/airflow/.local/lib/python3.8/site-packages/sqlalchemy/util/langhelpers.py", line 70, in __exit__
    compat.raise_(
  File "/home/airflow/.local/lib/python3.8/site-packages/sqlalchemy/util/compat.py", line 211, in raise_
    raise exception
  File "/home/airflow/.local/lib/python3.8/site-packages/sqlalchemy/pool/impl.py", line 143, in _do_get
    return self._create_connection()
  File "/home/airflow/.local/lib/python3.8/site-packages/sqlalchemy/pool/base.py", line 273, in _create_connection
    return _ConnectionRecord(self)
  File "/home/airflow/.local/lib/python3.8/site-packages/sqlalchemy/pool/base.py", line 388, in __init__
    self.__connect()
  File "/home/airflow/.local/lib/python3.8/site-packages/sqlalchemy/pool/base.py", line 691, in __connect
    pool.logger.debug("Error on connect(): %s", e)
  File "/home/airflow/.local/lib/python3.8/site-packages/sqlalchemy/util/langhelpers.py", line 70, in __exit__
    compat.raise_(
  File "/home/airflow/.local/lib/python3.8/site-packages/sqlalchemy/util/compat.py", line 211, in raise_
    raise exception
  File "/home/airflow/.local/lib/python3.8/site-packages/sqlalchemy/pool/base.py", line 686, in __connect
    self.dbapi_connection = connection = pool._invoke_creator(self)
  File "/home/airflow/.local/lib/python3.8/site-packages/sqlalchemy/engine/create.py", line 574, in connect
    return dialect.connect(*cargs, **cparams)
  File "/home/airflow/.local/lib/python3.8/site-packages/sqlalchemy/engine/default.py", line 598, in connect
    return self.dbapi.connect(*cargs, **cparams)
  File "/home/airflow/.local/lib/python3.8/site-packages/psycopg2/__init__.py", line 122, in connect
    conn = _connect(dsn, connection_factory=connection_factory, **kwasync)
psycopg2.OperationalError: connection to server at "database-1.cvwmlpdligxr.us-east-2.rds.amazonaws.com" (13.58.230.201), port 5432 failed: server closed the connection unexpectedly
	This probably means the server terminated abnormally
	before or while processing the request.


The above exception was the direct cause of the following exception:

Traceback (most recent call last):
  File "/home/airflow/.local/lib/python3.8/site-packages/airflow/operators/python.py", line 192, in execute
    return_value = self.execute_callable()
  File "/home/airflow/.local/lib/python3.8/site-packages/airflow/operators/python.py", line 209, in execute_callable
    return self.python_callable(*self.op_args, **self.op_kwargs)
  File "/opt/airflow/dags/etl_scripts/load.py", line 26, in load_data
    pd.read_csv(obj['Body'], index_col=0).to_sql(table_name, conn, if_exists="append", index=False, method=insert_on_conflict_nothing)
  File "/home/airflow/.local/lib/python3.8/site-packages/pandas/core/generic.py", line 2878, in to_sql
    return sql.to_sql(
  File "/home/airflow/.local/lib/python3.8/site-packages/pandas/io/sql.py", line 768, in to_sql
    with pandasSQL_builder(con, schema=schema, need_transaction=True) as pandas_sql:
  File "/home/airflow/.local/lib/python3.8/site-packages/pandas/io/sql.py", line 832, in pandasSQL_builder
    return SQLDatabase(con, schema, need_transaction)
  File "/home/airflow/.local/lib/python3.8/site-packages/pandas/io/sql.py", line 1539, in __init__
    con = self.exit_stack.enter_context(con.connect())
  File "/home/airflow/.local/lib/python3.8/site-packages/sqlalchemy/engine/base.py", line 3325, in connect
    return self._connection_cls(self, close_with_result=close_with_result)
  File "/home/airflow/.local/lib/python3.8/site-packages/sqlalchemy/engine/base.py", line 96, in __init__
    else engine.raw_connection()
  File "/home/airflow/.local/lib/python3.8/site-packages/sqlalchemy/engine/base.py", line 3404, in raw_connection
    return self._wrap_pool_connect(self.pool.connect, _connection)
  File "/home/airflow/.local/lib/python3.8/site-packages/sqlalchemy/engine/base.py", line 3374, in _wrap_pool_connect
    Connection._handle_dbapi_exception_noconnection(
  File "/home/airflow/.local/lib/python3.8/site-packages/sqlalchemy/engine/base.py", line 2208, in _handle_dbapi_exception_noconnection
    util.raise_(
  File "/home/airflow/.local/lib/python3.8/site-packages/sqlalchemy/util/compat.py", line 211, in raise_
    raise exception
  File "/home/airflow/.local/lib/python3.8/site-packages/sqlalchemy/engine/base.py", line 3371, in _wrap_pool_connect
    return fn()
  File "/home/airflow/.local/lib/python3.8/site-packages/sqlalchemy/pool/base.py", line 327, in connect
    return _ConnectionFairy._checkout(self)
  File "/home/airflow/.local/lib/python3.8/site-packages/sqlalchemy/pool/base.py", line 894, in _checkout
    fairy = _ConnectionRecord.checkout(pool)
  File "/home/airflow/.local/lib/python3.8/site-packages/sqlalchemy/pool/base.py", line 493, in checkout
    rec = pool._do_get()
  File "/home/airflow/.local/lib/python3.8/site-packages/sqlalchemy/pool/impl.py", line 146, in _do_get
    self._dec_overflow()
  File "/home/airflow/.local/lib/python3.8/site-packages/sqlalchemy/util/langhelpers.py", line 70, in __exit__
    compat.raise_(
  File "/home/airflow/.local/lib/python3.8/site-packages/sqlalchemy/util/compat.py", line 211, in raise_
    raise exception
  File "/home/airflow/.local/lib/python3.8/site-packages/sqlalchemy/pool/impl.py", line 143, in _do_get
    return self._create_connection()
  File "/home/airflow/.local/lib/python3.8/site-packages/sqlalchemy/pool/base.py", line 273, in _create_connection
    return _ConnectionRecord(self)
  File "/home/airflow/.local/lib/python3.8/site-packages/sqlalchemy/pool/base.py", line 388, in __init__
    self.__connect()
  File "/home/airflow/.local/lib/python3.8/site-packages/sqlalchemy/pool/base.py", line 691, in __connect
    pool.logger.debug("Error on connect(): %s", e)
  File "/home/airflow/.local/lib/python3.8/site-packages/sqlalchemy/util/langhelpers.py", line 70, in __exit__
    compat.raise_(
  File "/home/airflow/.local/lib/python3.8/site-packages/sqlalchemy/util/compat.py", line 211, in raise_
    raise exception
  File "/home/airflow/.local/lib/python3.8/site-packages/sqlalchemy/pool/base.py", line 686, in __connect
    self.dbapi_connection = connection = pool._invoke_creator(self)
  File "/home/airflow/.local/lib/python3.8/site-packages/sqlalchemy/engine/create.py", line 574, in connect
    return dialect.connect(*cargs, **cparams)
  File "/home/airflow/.local/lib/python3.8/site-packages/sqlalchemy/engine/default.py", line 598, in connect
    return self.dbapi.connect(*cargs, **cparams)
  File "/home/airflow/.local/lib/python3.8/site-packages/psycopg2/__init__.py", line 122, in connect
    conn = _connect(dsn, connection_factory=connection_factory, **kwasync)
sqlalchemy.exc.OperationalError: (psycopg2.OperationalError) connection to server at "database-1.cvwmlpdligxr.us-east-2.rds.amazonaws.com" (13.58.230.201), port 5432 failed: server closed the connection unexpectedly
	This probably means the server terminated abnormally
	before or while processing the request.

(Background on this error at: https://sqlalche.me/e/14/e3q8)
[2023-11-19T20:43:56.617+0000] {taskinstance.py:1400} INFO - Marking task as FAILED. dag_id=outcomes_dag, task_id=load_animals_dim, execution_date=20231118T000000, start_date=20231119T204340, end_date=20231119T204356
[2023-11-19T20:43:56.624+0000] {standard_task_runner.py:104} ERROR - Failed to execute job 9 for task load_animals_dim ((psycopg2.OperationalError) connection to server at "database-1.cvwmlpdligxr.us-east-2.rds.amazonaws.com" (13.58.230.201), port 5432 failed: server closed the connection unexpectedly
	This probably means the server terminated abnormally
	before or while processing the request.

(Background on this error at: https://sqlalche.me/e/14/e3q8); 103)
[2023-11-19T20:43:56.669+0000] {local_task_job_runner.py:228} INFO - Task exited with return code 1
[2023-11-19T20:47:20.226+0000] {taskinstance.py:1159} INFO - Dependencies all met for dep_context=non-requeueable deps ti=<TaskInstance: outcomes_dag.load_animals_dim scheduled__2023-11-18T00:00:00+00:00 [queued]>
[2023-11-19T20:47:20.232+0000] {taskinstance.py:1159} INFO - Dependencies all met for dep_context=requeueable deps ti=<TaskInstance: outcomes_dag.load_animals_dim scheduled__2023-11-18T00:00:00+00:00 [queued]>
[2023-11-19T20:47:20.233+0000] {taskinstance.py:1361} INFO - Starting attempt 1 of 1
[2023-11-19T20:47:20.240+0000] {taskinstance.py:1382} INFO - Executing <Task(PythonOperator): load_animals_dim> on 2023-11-18 00:00:00+00:00
[2023-11-19T20:47:20.247+0000] {standard_task_runner.py:57} INFO - Started process 107 to run task
[2023-11-19T20:47:20.256+0000] {standard_task_runner.py:84} INFO - Running: ['***', 'tasks', 'run', 'outcomes_dag', 'load_animals_dim', 'scheduled__2023-11-18T00:00:00+00:00', '--job-id', '9', '--raw', '--subdir', 'DAGS_FOLDER/outcomes_dag.py', '--cfg-path', '/tmp/tmpxn_pzbd6']
[2023-11-19T20:47:20.262+0000] {standard_task_runner.py:85} INFO - Job 9: Subtask load_animals_dim
[2023-11-19T20:47:20.336+0000] {task_command.py:416} INFO - Running <TaskInstance: outcomes_dag.load_animals_dim scheduled__2023-11-18T00:00:00+00:00 [running]> on host 9cdfa5fb3a71
[2023-11-19T20:47:20.389+0000] {taskinstance.py:1662} INFO - Exporting env vars: AIRFLOW_CTX_DAG_OWNER='***' AIRFLOW_CTX_DAG_ID='outcomes_dag' AIRFLOW_CTX_TASK_ID='load_animals_dim' AIRFLOW_CTX_EXECUTION_DATE='2023-11-18T00:00:00+00:00' AIRFLOW_CTX_TRY_NUMBER='1' AIRFLOW_CTX_DAG_RUN_ID='scheduled__2023-11-18T00:00:00+00:00'
[2023-11-19T20:47:36.518+0000] {taskinstance.py:1937} ERROR - Task failed with exception
Traceback (most recent call last):
  File "/home/airflow/.local/lib/python3.8/site-packages/sqlalchemy/engine/base.py", line 3371, in _wrap_pool_connect
    return fn()
  File "/home/airflow/.local/lib/python3.8/site-packages/sqlalchemy/pool/base.py", line 327, in connect
    return _ConnectionFairy._checkout(self)
  File "/home/airflow/.local/lib/python3.8/site-packages/sqlalchemy/pool/base.py", line 894, in _checkout
    fairy = _ConnectionRecord.checkout(pool)
  File "/home/airflow/.local/lib/python3.8/site-packages/sqlalchemy/pool/base.py", line 493, in checkout
    rec = pool._do_get()
  File "/home/airflow/.local/lib/python3.8/site-packages/sqlalchemy/pool/impl.py", line 146, in _do_get
    self._dec_overflow()
  File "/home/airflow/.local/lib/python3.8/site-packages/sqlalchemy/util/langhelpers.py", line 70, in __exit__
    compat.raise_(
  File "/home/airflow/.local/lib/python3.8/site-packages/sqlalchemy/util/compat.py", line 211, in raise_
    raise exception
  File "/home/airflow/.local/lib/python3.8/site-packages/sqlalchemy/pool/impl.py", line 143, in _do_get
    return self._create_connection()
  File "/home/airflow/.local/lib/python3.8/site-packages/sqlalchemy/pool/base.py", line 273, in _create_connection
    return _ConnectionRecord(self)
  File "/home/airflow/.local/lib/python3.8/site-packages/sqlalchemy/pool/base.py", line 388, in __init__
    self.__connect()
  File "/home/airflow/.local/lib/python3.8/site-packages/sqlalchemy/pool/base.py", line 691, in __connect
    pool.logger.debug("Error on connect(): %s", e)
  File "/home/airflow/.local/lib/python3.8/site-packages/sqlalchemy/util/langhelpers.py", line 70, in __exit__
    compat.raise_(
  File "/home/airflow/.local/lib/python3.8/site-packages/sqlalchemy/util/compat.py", line 211, in raise_
    raise exception
  File "/home/airflow/.local/lib/python3.8/site-packages/sqlalchemy/pool/base.py", line 686, in __connect
    self.dbapi_connection = connection = pool._invoke_creator(self)
  File "/home/airflow/.local/lib/python3.8/site-packages/sqlalchemy/engine/create.py", line 574, in connect
    return dialect.connect(*cargs, **cparams)
  File "/home/airflow/.local/lib/python3.8/site-packages/sqlalchemy/engine/default.py", line 598, in connect
    return self.dbapi.connect(*cargs, **cparams)
  File "/home/airflow/.local/lib/python3.8/site-packages/psycopg2/__init__.py", line 122, in connect
    conn = _connect(dsn, connection_factory=connection_factory, **kwasync)
psycopg2.OperationalError: connection to server at "database-1.cvwmlpdligxr.us-east-2.rds.amazonaws.com" (13.58.230.201), port 5432 failed: server closed the connection unexpectedly
	This probably means the server terminated abnormally
	before or while processing the request.


The above exception was the direct cause of the following exception:

Traceback (most recent call last):
  File "/home/airflow/.local/lib/python3.8/site-packages/airflow/operators/python.py", line 192, in execute
    return_value = self.execute_callable()
  File "/home/airflow/.local/lib/python3.8/site-packages/airflow/operators/python.py", line 209, in execute_callable
    return self.python_callable(*self.op_args, **self.op_kwargs)
  File "/opt/airflow/dags/etl_scripts/load.py", line 26, in load_data
    pd.read_csv(obj['Body'], index_col=0).to_sql(table_name, conn, if_exists="append", index=False, method=insert_on_conflict_nothing)
  File "/home/airflow/.local/lib/python3.8/site-packages/pandas/core/generic.py", line 2878, in to_sql
    return sql.to_sql(
  File "/home/airflow/.local/lib/python3.8/site-packages/pandas/io/sql.py", line 768, in to_sql
    with pandasSQL_builder(con, schema=schema, need_transaction=True) as pandas_sql:
  File "/home/airflow/.local/lib/python3.8/site-packages/pandas/io/sql.py", line 832, in pandasSQL_builder
    return SQLDatabase(con, schema, need_transaction)
  File "/home/airflow/.local/lib/python3.8/site-packages/pandas/io/sql.py", line 1539, in __init__
    con = self.exit_stack.enter_context(con.connect())
  File "/home/airflow/.local/lib/python3.8/site-packages/sqlalchemy/engine/base.py", line 3325, in connect
    return self._connection_cls(self, close_with_result=close_with_result)
  File "/home/airflow/.local/lib/python3.8/site-packages/sqlalchemy/engine/base.py", line 96, in __init__
    else engine.raw_connection()
  File "/home/airflow/.local/lib/python3.8/site-packages/sqlalchemy/engine/base.py", line 3404, in raw_connection
    return self._wrap_pool_connect(self.pool.connect, _connection)
  File "/home/airflow/.local/lib/python3.8/site-packages/sqlalchemy/engine/base.py", line 3374, in _wrap_pool_connect
    Connection._handle_dbapi_exception_noconnection(
  File "/home/airflow/.local/lib/python3.8/site-packages/sqlalchemy/engine/base.py", line 2208, in _handle_dbapi_exception_noconnection
    util.raise_(
  File "/home/airflow/.local/lib/python3.8/site-packages/sqlalchemy/util/compat.py", line 211, in raise_
    raise exception
  File "/home/airflow/.local/lib/python3.8/site-packages/sqlalchemy/engine/base.py", line 3371, in _wrap_pool_connect
    return fn()
  File "/home/airflow/.local/lib/python3.8/site-packages/sqlalchemy/pool/base.py", line 327, in connect
    return _ConnectionFairy._checkout(self)
  File "/home/airflow/.local/lib/python3.8/site-packages/sqlalchemy/pool/base.py", line 894, in _checkout
    fairy = _ConnectionRecord.checkout(pool)
  File "/home/airflow/.local/lib/python3.8/site-packages/sqlalchemy/pool/base.py", line 493, in checkout
    rec = pool._do_get()
  File "/home/airflow/.local/lib/python3.8/site-packages/sqlalchemy/pool/impl.py", line 146, in _do_get
    self._dec_overflow()
  File "/home/airflow/.local/lib/python3.8/site-packages/sqlalchemy/util/langhelpers.py", line 70, in __exit__
    compat.raise_(
  File "/home/airflow/.local/lib/python3.8/site-packages/sqlalchemy/util/compat.py", line 211, in raise_
    raise exception
  File "/home/airflow/.local/lib/python3.8/site-packages/sqlalchemy/pool/impl.py", line 143, in _do_get
    return self._create_connection()
  File "/home/airflow/.local/lib/python3.8/site-packages/sqlalchemy/pool/base.py", line 273, in _create_connection
    return _ConnectionRecord(self)
  File "/home/airflow/.local/lib/python3.8/site-packages/sqlalchemy/pool/base.py", line 388, in __init__
    self.__connect()
  File "/home/airflow/.local/lib/python3.8/site-packages/sqlalchemy/pool/base.py", line 691, in __connect
    pool.logger.debug("Error on connect(): %s", e)
  File "/home/airflow/.local/lib/python3.8/site-packages/sqlalchemy/util/langhelpers.py", line 70, in __exit__
    compat.raise_(
  File "/home/airflow/.local/lib/python3.8/site-packages/sqlalchemy/util/compat.py", line 211, in raise_
    raise exception
  File "/home/airflow/.local/lib/python3.8/site-packages/sqlalchemy/pool/base.py", line 686, in __connect
    self.dbapi_connection = connection = pool._invoke_creator(self)
  File "/home/airflow/.local/lib/python3.8/site-packages/sqlalchemy/engine/create.py", line 574, in connect
    return dialect.connect(*cargs, **cparams)
  File "/home/airflow/.local/lib/python3.8/site-packages/sqlalchemy/engine/default.py", line 598, in connect
    return self.dbapi.connect(*cargs, **cparams)
  File "/home/airflow/.local/lib/python3.8/site-packages/psycopg2/__init__.py", line 122, in connect
    conn = _connect(dsn, connection_factory=connection_factory, **kwasync)
sqlalchemy.exc.OperationalError: (psycopg2.OperationalError) connection to server at "database-1.cvwmlpdligxr.us-east-2.rds.amazonaws.com" (13.58.230.201), port 5432 failed: server closed the connection unexpectedly
	This probably means the server terminated abnormally
	before or while processing the request.

(Background on this error at: https://sqlalche.me/e/14/e3q8)
[2023-11-19T20:47:36.553+0000] {taskinstance.py:1400} INFO - Marking task as FAILED. dag_id=outcomes_dag, task_id=load_animals_dim, execution_date=20231118T000000, start_date=20231119T204720, end_date=20231119T204736
[2023-11-19T20:47:36.575+0000] {standard_task_runner.py:104} ERROR - Failed to execute job 9 for task load_animals_dim ((psycopg2.OperationalError) connection to server at "database-1.cvwmlpdligxr.us-east-2.rds.amazonaws.com" (13.58.230.201), port 5432 failed: server closed the connection unexpectedly
	This probably means the server terminated abnormally
	before or while processing the request.

(Background on this error at: https://sqlalche.me/e/14/e3q8); 107)
[2023-11-19T20:47:36.584+0000] {local_task_job_runner.py:228} INFO - Task exited with return code 1
[2023-11-19T21:07:56.041+0000] {taskinstance.py:1159} INFO - Dependencies all met for dep_context=non-requeueable deps ti=<TaskInstance: outcomes_dag.load_animals_dim scheduled__2023-11-18T00:00:00+00:00 [queued]>
[2023-11-19T21:07:56.046+0000] {taskinstance.py:1159} INFO - Dependencies all met for dep_context=requeueable deps ti=<TaskInstance: outcomes_dag.load_animals_dim scheduled__2023-11-18T00:00:00+00:00 [queued]>
[2023-11-19T21:07:56.046+0000] {taskinstance.py:1361} INFO - Starting attempt 1 of 1
[2023-11-19T21:07:56.054+0000] {taskinstance.py:1382} INFO - Executing <Task(PythonOperator): load_animals_dim> on 2023-11-18 00:00:00+00:00
[2023-11-19T21:07:56.058+0000] {standard_task_runner.py:57} INFO - Started process 99 to run task
[2023-11-19T21:07:56.062+0000] {standard_task_runner.py:84} INFO - Running: ['***', 'tasks', 'run', 'outcomes_dag', 'load_animals_dim', 'scheduled__2023-11-18T00:00:00+00:00', '--job-id', '11', '--raw', '--subdir', 'DAGS_FOLDER/outcomes_dag.py', '--cfg-path', '/tmp/tmprc199o8q']
[2023-11-19T21:07:56.065+0000] {standard_task_runner.py:85} INFO - Job 11: Subtask load_animals_dim
[2023-11-19T21:07:56.117+0000] {task_command.py:416} INFO - Running <TaskInstance: outcomes_dag.load_animals_dim scheduled__2023-11-18T00:00:00+00:00 [running]> on host 39e21f8b1ec3
[2023-11-19T21:07:56.172+0000] {taskinstance.py:1662} INFO - Exporting env vars: AIRFLOW_CTX_DAG_OWNER='***' AIRFLOW_CTX_DAG_ID='outcomes_dag' AIRFLOW_CTX_TASK_ID='load_animals_dim' AIRFLOW_CTX_EXECUTION_DATE='2023-11-18T00:00:00+00:00' AIRFLOW_CTX_TRY_NUMBER='1' AIRFLOW_CTX_DAG_RUN_ID='scheduled__2023-11-18T00:00:00+00:00'
[2023-11-19T21:07:56.790+0000] {logging_mixin.py:154} INFO - dim_animals loaded
[2023-11-19T21:07:56.790+0000] {python.py:194} INFO - Done. Returned value was: None
[2023-11-19T21:07:56.798+0000] {taskinstance.py:1400} INFO - Marking task as SUCCESS. dag_id=outcomes_dag, task_id=load_animals_dim, execution_date=20231118T000000, start_date=20231119T210756, end_date=20231119T210756
[2023-11-19T21:07:56.842+0000] {local_task_job_runner.py:228} INFO - Task exited with return code 0
[2023-11-19T21:11:48.250+0000] {taskinstance.py:1159} INFO - Dependencies all met for dep_context=non-requeueable deps ti=<TaskInstance: outcomes_dag.load_animals_dim scheduled__2023-11-18T00:00:00+00:00 [queued]>
[2023-11-19T21:11:48.258+0000] {taskinstance.py:1159} INFO - Dependencies all met for dep_context=requeueable deps ti=<TaskInstance: outcomes_dag.load_animals_dim scheduled__2023-11-18T00:00:00+00:00 [queued]>
[2023-11-19T21:11:48.259+0000] {taskinstance.py:1361} INFO - Starting attempt 1 of 1
[2023-11-19T21:11:48.287+0000] {taskinstance.py:1382} INFO - Executing <Task(PythonOperator): load_animals_dim> on 2023-11-18 00:00:00+00:00
[2023-11-19T21:11:48.305+0000] {standard_task_runner.py:57} INFO - Started process 121 to run task
[2023-11-19T21:11:48.326+0000] {standard_task_runner.py:84} INFO - Running: ['***', 'tasks', 'run', 'outcomes_dag', 'load_animals_dim', 'scheduled__2023-11-18T00:00:00+00:00', '--job-id', '10', '--raw', '--subdir', 'DAGS_FOLDER/outcomes_dag.py', '--cfg-path', '/tmp/tmpr0w_ukey']
[2023-11-19T21:11:48.336+0000] {standard_task_runner.py:85} INFO - Job 10: Subtask load_animals_dim
[2023-11-19T21:11:48.416+0000] {task_command.py:416} INFO - Running <TaskInstance: outcomes_dag.load_animals_dim scheduled__2023-11-18T00:00:00+00:00 [running]> on host 0aa87954f8d2
[2023-11-19T21:11:48.506+0000] {taskinstance.py:1662} INFO - Exporting env vars: AIRFLOW_CTX_DAG_OWNER='***' AIRFLOW_CTX_DAG_ID='outcomes_dag' AIRFLOW_CTX_TASK_ID='load_animals_dim' AIRFLOW_CTX_EXECUTION_DATE='2023-11-18T00:00:00+00:00' AIRFLOW_CTX_TRY_NUMBER='1' AIRFLOW_CTX_DAG_RUN_ID='scheduled__2023-11-18T00:00:00+00:00'
[2023-11-19T21:11:49.157+0000] {logging_mixin.py:154} INFO - dim_animals loaded
[2023-11-19T21:11:49.157+0000] {python.py:194} INFO - Done. Returned value was: None
[2023-11-19T21:11:49.165+0000] {taskinstance.py:1400} INFO - Marking task as SUCCESS. dag_id=outcomes_dag, task_id=load_animals_dim, execution_date=20231118T000000, start_date=20231119T211148, end_date=20231119T211149
[2023-11-19T21:11:49.189+0000] {local_task_job_runner.py:228} INFO - Task exited with return code 0
[2023-11-19T21:15:30.332+0000] {taskinstance.py:1159} INFO - Dependencies all met for dep_context=non-requeueable deps ti=<TaskInstance: outcomes_dag.load_animals_dim scheduled__2023-11-18T00:00:00+00:00 [queued]>
[2023-11-19T21:15:30.337+0000] {taskinstance.py:1159} INFO - Dependencies all met for dep_context=requeueable deps ti=<TaskInstance: outcomes_dag.load_animals_dim scheduled__2023-11-18T00:00:00+00:00 [queued]>
[2023-11-19T21:15:30.337+0000] {taskinstance.py:1361} INFO - Starting attempt 1 of 1
[2023-11-19T21:15:30.347+0000] {taskinstance.py:1382} INFO - Executing <Task(PythonOperator): load_animals_dim> on 2023-11-18 00:00:00+00:00
[2023-11-19T21:15:30.352+0000] {standard_task_runner.py:57} INFO - Started process 112 to run task
[2023-11-19T21:15:30.376+0000] {standard_task_runner.py:84} INFO - Running: ['***', 'tasks', 'run', 'outcomes_dag', 'load_animals_dim', 'scheduled__2023-11-18T00:00:00+00:00', '--job-id', '9', '--raw', '--subdir', 'DAGS_FOLDER/outcomes_dag.py', '--cfg-path', '/tmp/tmp0uaav4v3']
[2023-11-19T21:15:30.384+0000] {standard_task_runner.py:85} INFO - Job 9: Subtask load_animals_dim
[2023-11-19T21:15:30.480+0000] {task_command.py:416} INFO - Running <TaskInstance: outcomes_dag.load_animals_dim scheduled__2023-11-18T00:00:00+00:00 [running]> on host 5d17f892a68d
[2023-11-19T21:15:30.588+0000] {taskinstance.py:1662} INFO - Exporting env vars: AIRFLOW_CTX_DAG_OWNER='***' AIRFLOW_CTX_DAG_ID='outcomes_dag' AIRFLOW_CTX_TASK_ID='load_animals_dim' AIRFLOW_CTX_EXECUTION_DATE='2023-11-18T00:00:00+00:00' AIRFLOW_CTX_TRY_NUMBER='1' AIRFLOW_CTX_DAG_RUN_ID='scheduled__2023-11-18T00:00:00+00:00'
[2023-11-19T21:15:31.183+0000] {logging_mixin.py:154} INFO - dim_animals loaded
[2023-11-19T21:15:31.183+0000] {python.py:194} INFO - Done. Returned value was: None
[2023-11-19T21:15:31.190+0000] {taskinstance.py:1400} INFO - Marking task as SUCCESS. dag_id=outcomes_dag, task_id=load_animals_dim, execution_date=20231118T000000, start_date=20231119T211530, end_date=20231119T211531
[2023-11-19T21:15:31.233+0000] {local_task_job_runner.py:228} INFO - Task exited with return code 0
[2023-11-19T21:20:53.995+0000] {taskinstance.py:1159} INFO - Dependencies all met for dep_context=non-requeueable deps ti=<TaskInstance: outcomes_dag.load_animals_dim scheduled__2023-11-18T00:00:00+00:00 [queued]>
[2023-11-19T21:20:53.999+0000] {taskinstance.py:1159} INFO - Dependencies all met for dep_context=requeueable deps ti=<TaskInstance: outcomes_dag.load_animals_dim scheduled__2023-11-18T00:00:00+00:00 [queued]>
[2023-11-19T21:20:53.999+0000] {taskinstance.py:1361} INFO - Starting attempt 1 of 1
[2023-11-19T21:20:54.005+0000] {taskinstance.py:1382} INFO - Executing <Task(PythonOperator): load_animals_dim> on 2023-11-18 00:00:00+00:00
[2023-11-19T21:20:54.011+0000] {standard_task_runner.py:57} INFO - Started process 115 to run task
[2023-11-19T21:20:54.014+0000] {standard_task_runner.py:84} INFO - Running: ['***', 'tasks', 'run', 'outcomes_dag', 'load_animals_dim', 'scheduled__2023-11-18T00:00:00+00:00', '--job-id', '13', '--raw', '--subdir', 'DAGS_FOLDER/outcomes_dag.py', '--cfg-path', '/tmp/tmp4yfl9qt3']
[2023-11-19T21:20:54.016+0000] {standard_task_runner.py:85} INFO - Job 13: Subtask load_animals_dim
[2023-11-19T21:20:54.054+0000] {task_command.py:416} INFO - Running <TaskInstance: outcomes_dag.load_animals_dim scheduled__2023-11-18T00:00:00+00:00 [running]> on host 33e2059faeb6
[2023-11-19T21:20:54.105+0000] {taskinstance.py:1662} INFO - Exporting env vars: AIRFLOW_CTX_DAG_OWNER='***' AIRFLOW_CTX_DAG_ID='outcomes_dag' AIRFLOW_CTX_TASK_ID='load_animals_dim' AIRFLOW_CTX_EXECUTION_DATE='2023-11-18T00:00:00+00:00' AIRFLOW_CTX_TRY_NUMBER='1' AIRFLOW_CTX_DAG_RUN_ID='scheduled__2023-11-18T00:00:00+00:00'
[2023-11-19T21:20:54.740+0000] {logging_mixin.py:154} INFO - dim_animals loaded
[2023-11-19T21:20:54.744+0000] {python.py:194} INFO - Done. Returned value was: None
[2023-11-19T21:20:54.750+0000] {taskinstance.py:1400} INFO - Marking task as SUCCESS. dag_id=outcomes_dag, task_id=load_animals_dim, execution_date=20231118T000000, start_date=20231119T212053, end_date=20231119T212054
[2023-11-19T21:20:54.802+0000] {local_task_job_runner.py:228} INFO - Task exited with return code 0
[2023-11-19T21:31:18.512+0000] {taskinstance.py:1159} INFO - Dependencies all met for dep_context=non-requeueable deps ti=<TaskInstance: outcomes_dag.load_animals_dim scheduled__2023-11-18T00:00:00+00:00 [queued]>
[2023-11-19T21:31:18.531+0000] {taskinstance.py:1159} INFO - Dependencies all met for dep_context=requeueable deps ti=<TaskInstance: outcomes_dag.load_animals_dim scheduled__2023-11-18T00:00:00+00:00 [queued]>
[2023-11-19T21:31:18.532+0000] {taskinstance.py:1361} INFO - Starting attempt 1 of 1
[2023-11-19T21:31:18.552+0000] {taskinstance.py:1382} INFO - Executing <Task(PythonOperator): load_animals_dim> on 2023-11-18 00:00:00+00:00
[2023-11-19T21:31:18.557+0000] {standard_task_runner.py:57} INFO - Started process 111 to run task
[2023-11-19T21:31:18.564+0000] {standard_task_runner.py:84} INFO - Running: ['***', 'tasks', 'run', 'outcomes_dag', 'load_animals_dim', 'scheduled__2023-11-18T00:00:00+00:00', '--job-id', '9', '--raw', '--subdir', 'DAGS_FOLDER/outcomes_dag.py', '--cfg-path', '/tmp/tmpl5xum7z8']
[2023-11-19T21:31:18.567+0000] {standard_task_runner.py:85} INFO - Job 9: Subtask load_animals_dim
[2023-11-19T21:31:18.650+0000] {task_command.py:416} INFO - Running <TaskInstance: outcomes_dag.load_animals_dim scheduled__2023-11-18T00:00:00+00:00 [running]> on host bceb2bfddd0e
[2023-11-19T21:31:18.745+0000] {taskinstance.py:1662} INFO - Exporting env vars: AIRFLOW_CTX_DAG_OWNER='***' AIRFLOW_CTX_DAG_ID='outcomes_dag' AIRFLOW_CTX_TASK_ID='load_animals_dim' AIRFLOW_CTX_EXECUTION_DATE='2023-11-18T00:00:00+00:00' AIRFLOW_CTX_TRY_NUMBER='1' AIRFLOW_CTX_DAG_RUN_ID='scheduled__2023-11-18T00:00:00+00:00'
[2023-11-19T21:31:19.423+0000] {logging_mixin.py:154} INFO - dim_animals loaded
[2023-11-19T21:31:19.424+0000] {python.py:194} INFO - Done. Returned value was: None
[2023-11-19T21:31:19.436+0000] {taskinstance.py:1400} INFO - Marking task as SUCCESS. dag_id=outcomes_dag, task_id=load_animals_dim, execution_date=20231118T000000, start_date=20231119T213118, end_date=20231119T213119
[2023-11-19T21:31:19.468+0000] {local_task_job_runner.py:228} INFO - Task exited with return code 0
[2023-11-20T17:17:50.438+0000] {taskinstance.py:1159} INFO - Dependencies all met for dep_context=non-requeueable deps ti=<TaskInstance: outcomes_dag.load_animals_dim scheduled__2023-11-18T00:00:00+00:00 [queued]>
[2023-11-20T17:17:50.454+0000] {taskinstance.py:1159} INFO - Dependencies all met for dep_context=requeueable deps ti=<TaskInstance: outcomes_dag.load_animals_dim scheduled__2023-11-18T00:00:00+00:00 [queued]>
[2023-11-20T17:17:50.456+0000] {taskinstance.py:1361} INFO - Starting attempt 1 of 1
[2023-11-20T17:17:50.508+0000] {taskinstance.py:1382} INFO - Executing <Task(PythonOperator): load_animals_dim> on 2023-11-18 00:00:00+00:00
[2023-11-20T17:17:50.536+0000] {standard_task_runner.py:57} INFO - Started process 152 to run task
[2023-11-20T17:17:50.638+0000] {standard_task_runner.py:84} INFO - Running: ['***', 'tasks', 'run', 'outcomes_dag', 'load_animals_dim', 'scheduled__2023-11-18T00:00:00+00:00', '--job-id', '13', '--raw', '--subdir', 'DAGS_FOLDER/outcomes_dag.py', '--cfg-path', '/tmp/tmpn6umnnyp']
[2023-11-20T17:17:50.664+0000] {standard_task_runner.py:85} INFO - Job 13: Subtask load_animals_dim
[2023-11-20T17:17:50.838+0000] {task_command.py:416} INFO - Running <TaskInstance: outcomes_dag.load_animals_dim scheduled__2023-11-18T00:00:00+00:00 [running]> on host c82b86fb091d
[2023-11-20T17:17:51.021+0000] {taskinstance.py:1662} INFO - Exporting env vars: AIRFLOW_CTX_DAG_OWNER='***' AIRFLOW_CTX_DAG_ID='outcomes_dag' AIRFLOW_CTX_TASK_ID='load_animals_dim' AIRFLOW_CTX_EXECUTION_DATE='2023-11-18T00:00:00+00:00' AIRFLOW_CTX_TRY_NUMBER='1' AIRFLOW_CTX_DAG_RUN_ID='scheduled__2023-11-18T00:00:00+00:00'
[2023-11-20T17:18:07.179+0000] {taskinstance.py:1937} ERROR - Task failed with exception
Traceback (most recent call last):
  File "/home/airflow/.local/lib/python3.8/site-packages/sqlalchemy/engine/base.py", line 3371, in _wrap_pool_connect
    return fn()
  File "/home/airflow/.local/lib/python3.8/site-packages/sqlalchemy/pool/base.py", line 327, in connect
    return _ConnectionFairy._checkout(self)
  File "/home/airflow/.local/lib/python3.8/site-packages/sqlalchemy/pool/base.py", line 894, in _checkout
    fairy = _ConnectionRecord.checkout(pool)
  File "/home/airflow/.local/lib/python3.8/site-packages/sqlalchemy/pool/base.py", line 493, in checkout
    rec = pool._do_get()
  File "/home/airflow/.local/lib/python3.8/site-packages/sqlalchemy/pool/impl.py", line 146, in _do_get
    self._dec_overflow()
  File "/home/airflow/.local/lib/python3.8/site-packages/sqlalchemy/util/langhelpers.py", line 70, in __exit__
    compat.raise_(
  File "/home/airflow/.local/lib/python3.8/site-packages/sqlalchemy/util/compat.py", line 211, in raise_
    raise exception
  File "/home/airflow/.local/lib/python3.8/site-packages/sqlalchemy/pool/impl.py", line 143, in _do_get
    return self._create_connection()
  File "/home/airflow/.local/lib/python3.8/site-packages/sqlalchemy/pool/base.py", line 273, in _create_connection
    return _ConnectionRecord(self)
  File "/home/airflow/.local/lib/python3.8/site-packages/sqlalchemy/pool/base.py", line 388, in __init__
    self.__connect()
  File "/home/airflow/.local/lib/python3.8/site-packages/sqlalchemy/pool/base.py", line 691, in __connect
    pool.logger.debug("Error on connect(): %s", e)
  File "/home/airflow/.local/lib/python3.8/site-packages/sqlalchemy/util/langhelpers.py", line 70, in __exit__
    compat.raise_(
  File "/home/airflow/.local/lib/python3.8/site-packages/sqlalchemy/util/compat.py", line 211, in raise_
    raise exception
  File "/home/airflow/.local/lib/python3.8/site-packages/sqlalchemy/pool/base.py", line 686, in __connect
    self.dbapi_connection = connection = pool._invoke_creator(self)
  File "/home/airflow/.local/lib/python3.8/site-packages/sqlalchemy/engine/create.py", line 574, in connect
    return dialect.connect(*cargs, **cparams)
  File "/home/airflow/.local/lib/python3.8/site-packages/sqlalchemy/engine/default.py", line 598, in connect
    return self.dbapi.connect(*cargs, **cparams)
  File "/home/airflow/.local/lib/python3.8/site-packages/psycopg2/__init__.py", line 122, in connect
    conn = _connect(dsn, connection_factory=connection_factory, **kwasync)
psycopg2.OperationalError: connection to server at "dpg-cldp6jef27hc73fbu0rg-a.oregon-postgres.render.com" (35.227.164.209), port 5432 failed: server closed the connection unexpectedly
	This probably means the server terminated abnormally
	before or while processing the request.


The above exception was the direct cause of the following exception:

Traceback (most recent call last):
  File "/home/airflow/.local/lib/python3.8/site-packages/airflow/operators/python.py", line 192, in execute
    return_value = self.execute_callable()
  File "/home/airflow/.local/lib/python3.8/site-packages/airflow/operators/python.py", line 209, in execute_callable
    return self.python_callable(*self.op_args, **self.op_kwargs)
  File "/opt/airflow/dags/etl_scripts/load.py", line 23, in load_data
    pd.read_csv(obj['Body'], index_col=0).to_sql(table_name, conn, if_exists="append", index=False, method=insert_on_conflict_nothing)
  File "/home/airflow/.local/lib/python3.8/site-packages/pandas/core/generic.py", line 2878, in to_sql
    return sql.to_sql(
  File "/home/airflow/.local/lib/python3.8/site-packages/pandas/io/sql.py", line 768, in to_sql
    with pandasSQL_builder(con, schema=schema, need_transaction=True) as pandas_sql:
  File "/home/airflow/.local/lib/python3.8/site-packages/pandas/io/sql.py", line 832, in pandasSQL_builder
    return SQLDatabase(con, schema, need_transaction)
  File "/home/airflow/.local/lib/python3.8/site-packages/pandas/io/sql.py", line 1539, in __init__
    con = self.exit_stack.enter_context(con.connect())
  File "/home/airflow/.local/lib/python3.8/site-packages/sqlalchemy/engine/base.py", line 3325, in connect
    return self._connection_cls(self, close_with_result=close_with_result)
  File "/home/airflow/.local/lib/python3.8/site-packages/sqlalchemy/engine/base.py", line 96, in __init__
    else engine.raw_connection()
  File "/home/airflow/.local/lib/python3.8/site-packages/sqlalchemy/engine/base.py", line 3404, in raw_connection
    return self._wrap_pool_connect(self.pool.connect, _connection)
  File "/home/airflow/.local/lib/python3.8/site-packages/sqlalchemy/engine/base.py", line 3374, in _wrap_pool_connect
    Connection._handle_dbapi_exception_noconnection(
  File "/home/airflow/.local/lib/python3.8/site-packages/sqlalchemy/engine/base.py", line 2208, in _handle_dbapi_exception_noconnection
    util.raise_(
  File "/home/airflow/.local/lib/python3.8/site-packages/sqlalchemy/util/compat.py", line 211, in raise_
    raise exception
  File "/home/airflow/.local/lib/python3.8/site-packages/sqlalchemy/engine/base.py", line 3371, in _wrap_pool_connect
    return fn()
  File "/home/airflow/.local/lib/python3.8/site-packages/sqlalchemy/pool/base.py", line 327, in connect
    return _ConnectionFairy._checkout(self)
  File "/home/airflow/.local/lib/python3.8/site-packages/sqlalchemy/pool/base.py", line 894, in _checkout
    fairy = _ConnectionRecord.checkout(pool)
  File "/home/airflow/.local/lib/python3.8/site-packages/sqlalchemy/pool/base.py", line 493, in checkout
    rec = pool._do_get()
  File "/home/airflow/.local/lib/python3.8/site-packages/sqlalchemy/pool/impl.py", line 146, in _do_get
    self._dec_overflow()
  File "/home/airflow/.local/lib/python3.8/site-packages/sqlalchemy/util/langhelpers.py", line 70, in __exit__
    compat.raise_(
  File "/home/airflow/.local/lib/python3.8/site-packages/sqlalchemy/util/compat.py", line 211, in raise_
    raise exception
  File "/home/airflow/.local/lib/python3.8/site-packages/sqlalchemy/pool/impl.py", line 143, in _do_get
    return self._create_connection()
  File "/home/airflow/.local/lib/python3.8/site-packages/sqlalchemy/pool/base.py", line 273, in _create_connection
    return _ConnectionRecord(self)
  File "/home/airflow/.local/lib/python3.8/site-packages/sqlalchemy/pool/base.py", line 388, in __init__
    self.__connect()
  File "/home/airflow/.local/lib/python3.8/site-packages/sqlalchemy/pool/base.py", line 691, in __connect
    pool.logger.debug("Error on connect(): %s", e)
  File "/home/airflow/.local/lib/python3.8/site-packages/sqlalchemy/util/langhelpers.py", line 70, in __exit__
    compat.raise_(
  File "/home/airflow/.local/lib/python3.8/site-packages/sqlalchemy/util/compat.py", line 211, in raise_
    raise exception
  File "/home/airflow/.local/lib/python3.8/site-packages/sqlalchemy/pool/base.py", line 686, in __connect
    self.dbapi_connection = connection = pool._invoke_creator(self)
  File "/home/airflow/.local/lib/python3.8/site-packages/sqlalchemy/engine/create.py", line 574, in connect
    return dialect.connect(*cargs, **cparams)
  File "/home/airflow/.local/lib/python3.8/site-packages/sqlalchemy/engine/default.py", line 598, in connect
    return self.dbapi.connect(*cargs, **cparams)
  File "/home/airflow/.local/lib/python3.8/site-packages/psycopg2/__init__.py", line 122, in connect
    conn = _connect(dsn, connection_factory=connection_factory, **kwasync)
sqlalchemy.exc.OperationalError: (psycopg2.OperationalError) connection to server at "dpg-cldp6jef27hc73fbu0rg-a.oregon-postgres.render.com" (35.227.164.209), port 5432 failed: server closed the connection unexpectedly
	This probably means the server terminated abnormally
	before or while processing the request.

(Background on this error at: https://sqlalche.me/e/14/e3q8)
[2023-11-20T17:18:07.220+0000] {taskinstance.py:1400} INFO - Marking task as FAILED. dag_id=outcomes_dag, task_id=load_animals_dim, execution_date=20231118T000000, start_date=20231120T171750, end_date=20231120T171807
[2023-11-20T17:18:07.247+0000] {standard_task_runner.py:104} ERROR - Failed to execute job 13 for task load_animals_dim ((psycopg2.OperationalError) connection to server at "dpg-cldp6jef27hc73fbu0rg-a.oregon-postgres.render.com" (35.227.164.209), port 5432 failed: server closed the connection unexpectedly
	This probably means the server terminated abnormally
	before or while processing the request.

(Background on this error at: https://sqlalche.me/e/14/e3q8); 152)
[2023-11-20T17:18:07.291+0000] {local_task_job_runner.py:228} INFO - Task exited with return code 1
